Workbook

Sheet Roster 9A
A1: Maria Rubbato Catholic School 2015 E.C Roster Grade 9A Student's
A3: Home Room Teacher Grade 9A
A5: No | B5: Student Name | C5: Age | D5: Sex | E5: Semester | F5: Amharic | G5: English | H5: Maths | I5: physics | J5: chemistry | K5: Biology | L5: Geography | M5: History | N5: Civics | O5: ICT | P5: H.P.E | Q5: Total | R5: Average | S5: Rank | T5: Condc. | U5: Abse.
A6: 1 | C6: 14 | D6: F | E6: Semister 1 | F6: ='9A Sem 1'!E4 -> 71 | G6: ='9A Sem 1'!F4 -> 50 | H6: ='9A Sem 1'!G4 -> 50 | I6: ='9A Sem 1'!H4 -> 70 | J6: ='9A Sem 1'!I4 -> 54 | K6: ='9A Sem 1'!J4 -> 53 | L6: ='9A Sem 1'!K4 -> 68 | M6: ='9A Sem 1'!L4 -> 65 | ... U6: ='9A Sem 1'!T4 -> 0
C7: 14 | D7: F | E7: Semister 2 | F7: ='9A Sem 2'!E4 -> 80 | G7: ='9A Sem 2'!F4 -> 54 | H7: ='9A Sem 2'!G4 -> 70 | I7: ='9A Sem 2'!H4 -> 65 | J7: ='9A Sem 2'!I4 -> 51 | K7: ='9A Sem 2'!J4 -> 51 | L7: ='9A Sem 2'!K4 -> 61 | M7: ='9A Sem 2'!L4 -> 64 | ... U7: ='9A Sem 2'!T4 -> 0
C8: 14 | D8: F | E8: Average | F8: =AVERAGE(F6:F7) -> 75.5 | G8: =AVERAGE(G6:G7) -> 52 | H8: =AVERAGE(H6:H7) -> 60 | I8: =AVERAGE(I6:I7) -> 67.5 | J8: =AVERAGE(J6:J7) -> 52.5 | K8: =AVERAGE(K6:K7) -> 52 | L8: =AVERAGE(L6:L7) -> 64.5 | M8: =AVERAGE(M6:M7) -> 64.5 | ... R8: =AVERAGE(R6:R7) -> 63.045455 | S8: ='9A Sem avr'!$H$4 -> 37 | T8: =AVERAGE(T6:T7) -> 0 | U8: =AVERAGE(U6:U7) -> 0
A9: 2 | C9: 16 | D9: M | E9: Semister 1 | F9: ='9A Sem 1'!E5 -> 92 | G9: ='9A Sem 1'!F5 -> 93 | H9: ='9A Sem 1'!G5 -> 95 | I9: ='9A Sem 1'!H5 -> 100 | J9: ='9A Sem 1'!I5 -> 96 | K9: ='9A Sem 1'!J5 -> 98 | L9: ='9A Sem 1'!K5 -> 95 | M9: ='9A Sem 1'!L5 -> 98 | ... U9: ='9A Sem 1'!T5 -> 0
C10: 16 | D10: M | E10: Semister 2 | F10: ='9A Sem 2'!E5 -> 96 | G10: ='9A Sem 2'!F5 -> 94 | H10: ='9A Sem 2'!G5 -> 96 | I10: ='9A Sem 2'!H5 -> 100 | J10: ='9A Sem 2'!I5 -> 96 | K10: ='9A Sem 2'!J5 -> 98 | L10: ='9A Sem 2'!K5 -> 96 | M10: ='9A Sem 2'!L5 -> 95 | ... U10: ='9A Sem 2'!T5 -> 0
C11: 16 | D11: M | E11: Average | F11: =AVERAGE(F9:F10) -> 94 | G11: =AVERAGE(G9:G10) -> 93.5 | H11: =AVERAGE(H9:H10) -> 95.5 | I11: =AVERAGE(I9:I10) -> 100 | J11: =AVERAGE(J9:J10) -> 96 | K11: =AVERAGE(K9:K10) -> 98 | L11: =AVERAGE(L9:L10) -> 95.5 | M11: =AVERAGE(M9:M10) -> 96.5 | ... R11: =AVERAGE(R9:R10) -> 96.818182 | S11: ='9A Sem avr'!$H$5 -> 1 | T11: =AVERAGE(T9:T10) -> 0 | U11: =AVERAGE(U9:U10) -> 0
A12: 3 | C12: 14 | D12: F | E12: Semister 1 | F12: ='9A Sem 1'!E6 -> 83 | G12: ='9A Sem 1'!F6 -> 46 | H12: ='9A Sem 1'!G6 -> 54 | I12: ='9A Sem 1'!H6 -> 53 | J12: ='9A Sem 1'!I6 -> 57 | K12: ='9A Sem 1'!J6 -> 40 | L12: ='9A Sem 1'!K6 -> 38 | M12: ='9A Sem 1'!L6 -> 63 | ... U12: ='9A Sem 1'!T6 -> 0
C13: 14 | D13: F | E13: Semister 2 | F13: ='9A Sem 2'!E6 -> 79 | G13: ='9A Sem 2'!F6 -> 50 | H13: ='9A Sem 2'!G6 -> 54 | I13: ='9A Sem 2'!H6 -> 50 | J13: ='9A Sem 2'!I6 -> 43 | K13: ='9A Sem 2'!J6 -> 46 | L13: ='9A Sem 2'!K6 -> 51 | M13: ='9A Sem 2'!L6 -> 41 | ... U13: ='9A Sem 2'!T6 -> 0
C14: 14 | D14: F | E14: Average | F14: =AVERAGE(F12:F13) -> 81 | G14: =AVERAGE(G12:G13) -> 48 | H14: =AVERAGE(H12:H13) -> 54 | I14: =AVERAGE(I12:I13) -> 51.5 | J14: =AVERAGE(J12:J13) -> 50 | K14: =AVERAGE(K12:K13) -> 43 | L14: =AVERAGE(L12:L13) -> 44.5 | M14: =AVERAGE(M12:M13) -> 52 | ... U14: =AVERAGE(U12:U13) -> 0
A15: 4 | C15: 14 | D15: M | E15: Semister 1 | F15: ='9A Sem 1'!E7 -> 89 | G15: ='9A Sem 1'!F7 -> 70 | H15: ='9A Sem 1'!G7 -> 55 | I15: ='9A Sem 1'!H7 -> 69 | J15: ='9A Sem 1'!I7 -> 59 | K15: ='9A Sem 1'!J7 -> 72 | L15: ='9A Sem 1'!K7 -> 76 | M15: ='9A Sem 1'!L7 -> 91 | ... U15: ='9A Sem 1'!T7 -> 0
C16: 14 | D16: M | E16: Semister 2 | F16: ='9A Sem 2'!E7 -> 82 | G16: ='9A Sem 2'!F7 -> 73 | H16: ='9A Sem 2'!G7 -> 71 | I16: ='9A Sem 2'!H7 -> 69 | J16: ='9A Sem 2'!I7 -> 66 | K16: ='9A Sem 2'!J7 -> 80 | L16: ='9A Sem 2'!K7 -> 82 | M16: ='9A Sem 2'!L7 -> 91 | ... U16: ='9A Sem 2'!T7 -> 0
C17: 14 | D17: M | E17: Average | F17: =AVERAGE(F15:F16) -> 85.5 | G17: =AVERAGE(G15:G16) -> 71.5 | H17: =AVERAGE(H15:H16) -> 63 | I17: =AVERAGE(I15:I16) -> 69 | J17: =AVERAGE(J15:J16) -> 62.5 | K17: =AVERAGE(K15:K16) -> 76 | L17: =AVERAGE(L15:L16) -> 79 | M17: =AVERAGE(M15:M16) -> 91 | ... R17: =AVERAGE(R15:R16) -> 77.863636 | S17: ='9A Sem avr'!$H$7 -> 20 | T17: =AVERAGE(T15:T16) -> 0 | U17: =AVERAGE(U15:U16) -> 0
A18: 5 | C18: 14 | D18: F | E18: Semister 1 | F18: ='9A Sem 1'!E8 -> 92 | G18: ='9A Sem 1'!F8 -> 87 | H18: ='9A Sem 1'!G8 -> 90 | I18: ='9A Sem 1'!H8 -> 88 | J18: ='9A Sem 1'!I8 -> 91 | K18: ='9A Sem 1'!J8 -> 92 | L18: ='9A Sem 1'!K8 -> 92 | M18: ='9A Sem 1'!L8 -> 93 | ... U18: ='9A Sem 1'!T8 -> 0
C19: 14 | D19: F | E19: Semister 2 | F19: ='9A Sem 2'!E8 -> 91 | G19: ='9A Sem 2'!F8 -> 96 | H19: ='9A Sem 2'!G8 -> 93 | I19: ='9A Sem 2'!H8 -> 90 | J19: ='9A Sem 2'!I8 -> 83 | K19: ='9A Sem 2'!J8 -> 96 | L19: ='9A Sem 2'!K8 -> 86 | M19: ='9A Sem 2'!L8 -> 86 | ... U19: ='9A Sem 2'!T8 -> 0
C20: 14 | D20: F | E20: Average | F20: =AVERAGE(F18:F19) -> 91.5 | G20: =AVERAGE(G18:G19) -> 91.5 | H20: =AVERAGE(H18:H19) -> 91.5 | I20: =AVERAGE(I18:I19) -> 89 | J20: =AVERAGE(J18:J19) -> 87 | K20: =AVERAGE(K18:K19) -> 94 | L20: =AVERAGE(L18:L19) -> 89 | M20: =AVERAGE(M18:M19) -> 89.5 | ... R20: =AVERAGE(R18:R19) -> 91.545455 | S20: ='9A Sem avr'!$H$8 -> 3 | T20: =AVERAGE(T18:T19) -> 0 | U20: =AVERAGE(U18:U19) -> 0
A21: 6 | C21: 16 | D21: F | E21: Semister 1 | F21: ='9A Sem 1'!E9 -> 55 | G21: ='9A Sem 1'!F9 -> 38 | H21: ='9A Sem 1'!G9 -> 51 | I21: ='9A Sem 1'!H9 -> 39 | J21: ='9A Sem 1'!I9 -> 51 | K21: ='9A Sem 1'!J9 -> 36 | L21: ='9A Sem 1'!K9 -> 41 | M21: ='9A Sem 1'!L9 -> 40 | ... U21: ='9A Sem 1'!T9 -> 0
C22: 16 | D22: F | E22: Semister 2 | F22: ='9A Sem 2'!E9 -> 69 | G22: ='9A Sem 2'!F9 -> 44 | H22: ='9A Sem 2'!G9 -> 42 | I22: ='9A Sem 2'!H9 -> 44 | J22: ='9A Sem 2'!I9 -> 41 | K22: ='9A Sem 2'!J9 -> 38 | L22: ='9A Sem 2'!K9 -> 45 | M22: ='9A Sem 2'!L9 -> 44 | ... U22: ='9A Sem 2'!T9 -> 0
C23: 16 | D23: F | E23: Average | F23: =AVERAGE(F21:F22) -> 62 | G23: =AVERAGE(G21:G22) -> 41 | H23: =AVERAGE(H21:H22) -> 46.5 | I23: =AVERAGE(I21:I22) -> 41.5 | J23: =AVERAGE(J21:J22) -> 46 | K23: =AVERAGE(K21:K22) -> 37 | L23: =AVERAGE(L21:L22) -> 43 | M23: =AVERAGE(M21:M22) -> 42 | ... R23: =AVERAGE(R21:R22) -> 48.909091 | S23: ='9A Sem avr'!$H$9 -> 48 | T23: =AVERAGE(T21:T22) -> 0 | U23: =AVERAGE(U21:U22) -> 0
A24: 7 | C24: 14 | D24: F | E24: Semister 1 | F24: ='9A Sem 1'!E10 -> 90 | G24: ='9A Sem 1'!F10 -> 82 | H24: ='9A Sem 1'!G10 -> 63 | I24: ='9A Sem 1'!H10 -> 66 | J24: ='9A Sem 1'!I10 -> 69 | K24: ='9A Sem 1'!J10 -> 77 | L24: ='9A Sem 1'!K10 -> 80 | M24: ='9A Sem 1'!L10 -> 83 | ... U24: ='9A Sem 1'!T10 -> 0
C25: 14 | D25: F | E25: Semister 2 | F25: ='9A Sem 2'!E10 -> 85 | G25: ='9A Sem 2'!F10 -> 83 | H25: ='9A Sem 2'!G10 -> 60 | I25: ='9A Sem 2'!H10 -> 69 | J25: ='9A Sem 2'!I10 -> 64 | K25: ='9A Sem 2'!J10 -> 81 | L25: ='9A Sem 2'!K10 -> 82 | M25: ='9A Sem 2'!L10 -> 81 | ... U25: ='9A Sem 2'!T10 -> 0
C26: 14 | D26: F | E26: Average | F26: =AVERAGE(F24:F25) -> 87.5 | G26: =AVERAGE(G24:G25) -> 82.5 | H26: =AVERAGE(H24:H25) -> 61.5 | I26: =AVERAGE(I24:I25) -> 67.5 | J26: =AVERAGE(J24:J25) -> 66.5 | K26: =AVERAGE(K24:K25) -> 79 | L26: =AVERAGE(L24:L25) -> 81 | M26: =AVERAGE(M24:M25) -> 82 | ... R26: =AVERAGE(R24:R25) -> 79.5 | S26: ='9A Sem avr'!$H$10 -> 16 | T26: =AVERAGE(T24:T25) -> 0 | U26: =AVERAGE(U24:U25) -> 0
A27: 8 | C27: 14 | D27: M | E27: Semister 1 | F27: ='9A Sem 1'!E11 -> 88 | G27: ='9A Sem 1'!F11 -> 73 | H27: ='9A Sem 1'!G11 -> 61 | I27: ='9A Sem 1'!H11 -> 67 | J27: ='9A Sem 1'!I11 -> 68 | K27: ='9A Sem 1'!J11 -> 70 | L27: ='9A Sem 1'!K11 -> 66 | M27: ='9A Sem 1'!L11 -> 85 | ... U27: ='9A Sem 1'!T11 -> 0
C28: 14 | D28: M | E28: Semister 2 | F28: ='9A Sem 2'!E11 -> 87 | G28: ='9A Sem 2'!F11 -> 74 | H28: ='9A Sem 2'!G11 -> 54 | I28: ='9A Sem 2'!H11 -> 52 | J28: ='9A Sem 2'!I11 -> 53 | K28: ='9A Sem 2'!J11 -> 59 | L28: ='9A Sem 2'!K11 -> 67 | M28: ='9A Sem 2'!L11 -> 76 | ... U28: ='9A Sem 2'!T11 -> 0
C29: 14 | D29: M | E29: Average | F29: =AVERAGE(F27:F28) -> 87.5 | G29: =AVERAGE(G27:G28) -> 73.5 | H29: =AVERAGE(H27:H28) -> 57.5 | I29: =AVERAGE(I27:I28) -> 59.5 | J29: =AVERAGE(J27:J28) -> 60.5 | K29: =AVERAGE(K27:K28) -> 64.5 | L29: =AVERAGE(L27:L28) -> 66.5 | M29: =AVERAGE(M27:M28) -> 80.5 | ... R29: =AVERAGE(R27:R28) -> 73.409091 | S29: ='9A Sem avr'!$H$11 -> 26 | T29: =AVERAGE(T27:T28) -> 0 | U29: =AVERAGE(U27:U28) -> 0
A30: 9 | C30: 15 | D30: M | E30: Semister 1 | F30: ='9A Sem 1'!E12 -> 77 | G30: ='9A Sem 1'!F12 -> 52 | H30: ='9A Sem 1'!G12 -> 33 | I30: ='9A Sem 1'!H12 -> 40 | J30: ='9A Sem 1'!I12 -> 40 | K30: ='9A Sem 1'!J12 -> 44 | L30: ='9A Sem 1'!K12 -> 50 | M30: ='9A Sem 1'!L12 -> 57 | ... U30: ='9A Sem 1'!T12 -> 0
C31: 15 | D31: M | E31: Semister 2 | F31: ='9A Sem 2'!E12 -> 57 | G31: ='9A Sem 2'!F12 -> 46 | H31: ='9A Sem 2'!G12 -> 35 | I31: ='9A Sem 2'!H12 -> 42 | J31: ='9A Sem 2'!I12 -> 56 | K31: ='9A Sem 2'!J12 -> 34 | L31: ='9A Sem 2'!K12 -> 51 | M31: ='9A Sem 2'!L12 -> 40 | ... U31: ='9A Sem 2'!T12 -> 0
C32: 15 | D32: M | E32: Average | F32: =AVERAGE(F30:F31) -> 67 | G32: =AVERAGE(G30:G31) -> 49 | H32: =AVERAGE(H30:H31) -> 34 | I32: =AVERAGE(I30:I31) -> 41 | J32: =AVERAGE(J30:J31) -> 48 | K32: =AVERAGE(K30:K31) -> 39 | L32: =AVERAGE(L30:L31) -> 50.5 | M32: =AVERAGE(M30:M31) -> 48.5 | ... R32: =AVERAGE(R30:R31) -> 51.272727 | S32: ='9A Sem avr'!$H$12 -> 47 | T32: =AVERAGE(T30:T31) -> 0 | U32: =AVERAGE(U30:U31) -> 0
A33: 10 | C33: 15 | D33: M | E33: Semister 1 | F33: ='9A Sem 1'!E13 -> 89 | G33: ='9A Sem 1'!F13 -> 64 | H33: ='9A Sem 1'!G13 -> 56 | I33: ='9A Sem 1'!H13 -> 66 | J33: ='9A Sem 1'!I13 -> 58 | K33: ='9A Sem 1'!J13 -> 72 | L33: ='9A Sem 1'!K13 -> 82 | M33: ='9A Sem 1'!L13 -> 90 | ... U33: ='9A Sem 1'!T13 -> 0
C34: 15 | D34: M | E34: Semister 2 | F34: ='9A Sem 2'!E13 -> 92 | G34: ='9A Sem 2'!F13 -> 64 | H34: ='9A Sem 2'!G13 -> 52 | I34: ='9A Sem 2'!H13 -> 58 | J34: ='9A Sem 2'!I13 -> 58 | K34: ='9A Sem 2'!J13 -> 75 | L34: ='9A Sem 2'!K13 -> 79 | M34: ='9A Sem 2'!L13 -> 73 | ... U34: ='9A Sem 2'!T13 -> 0
C35: 15 | D35: M | E35: Average | F35: =AVERAGE(F33:F34) -> 90.5 | G35: =AVERAGE(G33:G34) -> 64 | H35: =AVERAGE(H33:H34) -> 54 | I35: =AVERAGE(I33:I34) -> 62 | J35: =AVERAGE(J33:J34) -> 58 | K35: =AVERAGE(K33:K34) -> 73.5 | L35: =AVERAGE(L33:L34) -> 80.5 | M35: =AVERAGE(M33:M34) -> 81.5 | ... R35: =AVERAGE(R33:R34) -> 75.181818 | S35: ='9A Sem avr'!$H$13 -> 24 | T35: =AVERAGE(T33:T34) -> 0 | U35: =AVERAGE(U33:U34) -> 0
A36: 11 | C36: 14 | D36: F | E36: Semister 1 | F36: ='9A Sem 1'!E14 -> 84 | G36: ='9A Sem 1'!F14 -> 82 | H36: ='9A Sem 1'!G14 -> 84 | I36: ='9A Sem 1'!H14 -> 78 | J36: ='9A Sem 1'!I14 -> 68 | K36: ='9A Sem 1'!J14 -> 68 | L36: ='9A Sem 1'!K14 -> 82 | M36: ='9A Sem 1'!L14 -> 81 | ... U36: ='9A Sem 1'!T14 -> 0
C37: 14 | D37: F | E37: Semister 2 | F37: ='9A Sem 2'!E14 -> 87 | G37: ='9A Sem 2'!F14 -> 85 | H37: ='9A Sem 2'!G14 -> 81 | I37: ='9A Sem 2'!H14 -> 78 | J37: ='9A Sem 2'!I14 -> 68 | K37: ='9A Sem 2'!J14 -> 73 | L37: ='9A Sem 2'!K14 -> 78 | M37: ='9A Sem 2'!L14 -> 77 | ... U37: ='9A Sem 2'!T14 -> 0
C38: 14 | D38: F | E38: Average | F38: =AVERAGE(F36:F37) -> 85.5 | G38: =AVERAGE(G36:G37) -> 83.5 | H38: =AVERAGE(H36:H37) -> 82.5 | I38: =AVERAGE(I36:I37) -> 78 | J38: =AVERAGE(J36:J37) -> 68 | K38: =AVERAGE(K36:K37) -> 70.5 | L38: =AVERAGE(L36:L37) -> 80 | M38: =AVERAGE(M36:M37) -> 79 | ... R38: =AVERAGE(R36:R37) -> 82.227273 | S38: ='9A Sem avr'!$H$14 -> 11 | T38: =AVERAGE(T36:T37) -> 0 | U38: =AVERAGE(U36:U37) -> 0
A39: 12 | C39: 15 | D39: F | E39: Semister 1 | F39: ='9A Sem 1'!E15 -> 71 | G39: ='9A Sem 1'!F15 -> 66 | H39: ='9A Sem 1'!G15 -> 55 | I39: ='9A Sem 1'!H15 -> 45 | J39: ='9A Sem 1'!I15 -> 54 | K39: ='9A Sem 1'!J15 -> 41 | L39: ='9A Sem 1'!K15 -> 51 | M39: ='9A Sem 1'!L15 -> 56 | ... U39: ='9A Sem 1'!T15 -> 0
C40: 15 | D40: F | E40: Semister 2 | F40: ='9A Sem 2'!E15 -> 84 | G40: ='9A Sem 2'!F15 -> 50 | H40: ='9A Sem 2'!G15 -> 57 | I40: ='9A Sem 2'!H15 -> 53 | J40: ='9A Sem 2'!I15 -> 54 | K40: ='9A Sem 2'!J15 -> 50 | L40: ='9A Sem 2'!K15 -> 55 | M40: ='9A Sem 2'!L15 -> 50 | ... U40: ='9A Sem 2'!T15 -> 0
C41: 15 | D41: F | E41: Average | F41: =AVERAGE(F39:F40) -> 77.5 | G41: =AVERAGE(G39:G40) -> 58 | H41: =AVERAGE(H39:H40) -> 56 | I41: =AVERAGE(I39:I40) -> 49 | J41: =AVERAGE(J39:J40) -> 54 | K41: =AVERAGE(K39:K40) -> 45.5 | L41: =AVERAGE(L39:L40) -> 53 | M41: =AVERAGE(M39:M40) -> 53 | ... R41: =AVERAGE(R39:R40) -> 61.181818 | S41: ='9A Sem avr'!$H$15 -> 42 | T41: =AVERAGE(T39:T40) -> 0 | U41: =AVERAGE(U39:U40) -> 0
A42: 13 | C42: 14 | D42: F | E42: Semister 1 | F42: ='9A Sem 1'!E16 -> 87 | G42: ='9A Sem 1'!F16 -> 70 | H42: ='9A Sem 1'!G16 -> 56 | I42: ='9A Sem 1'!H16 -> 64 | J42: ='9A Sem 1'!I16 -> 56 | K42: ='9A Sem 1'!J16 -> 57 | L42: ='9A Sem 1'!K16 -> 68 | M42: ='9A Sem 1'!L16 -> 73 | ... U42: ='9A Sem 1'!T16 -> 0
...

Sheet 9A Sem 1
A1: Maria Rubbato Catholic School 2015 E.C Roster Grade 9A Student's
A2: Home Room Teacher Grade 9A
A3: No | B3: Student Name | C3: Age | D3: Sex | E3: Amharic | F3: English | G3: Maths | H3: physics | I3: chemistry | J3: Biology | K3: Geography | L3: History | M3: Civics | N3: ICT | O3: H.P.E | P3: Total | Q3: Average | R3: Rank | S3: Condc. | T3: Abse.
A4: 1 | C4: 14 | D4: F | E4: 71 | F4: 50 | G4: 50 | H4: 70 | I4: 54 | J4: 53 | K4: 68 | L4: 65 | M4: 52 | N4: 74 | O4: 70 | P4: =SUM(E4:O4) -> 677 | Q4: =AVERAGE(E4:O4) -> 61.545455 | R4: =RANK(Q4,$Q$4:$Q$55) -> 38
A5: 2 | C5: 16 | D5: M | E5: 92 | F5: 93 | G5: 95 | H5: 100 | I5: 96 | J5: 98 | K5: 95 | L5: 98 | M5: 93 | N5: 100 | O5: 100 | P5: =SUM(E5:O5) -> 1060 | Q5: =AVERAGE(E5:O5) -> 96.363636 | R5: =RANK(Q5,$Q$4:$Q$55) -> 1
A6: 3 | C6: 14 | D6: F | E6: 83 | F6: 46 | G6: 54 | H6: 53 | I6: 57 | J6: 40 | K6: 38 | L6: 63 | M6: 52 | N6: 67 | O6: 80 | P6: =SUM(E6:O6) -> 633 | Q6: =AVERAGE(E6:O6) -> 57.545455 | R6: =RANK(Q6,$Q$4:$Q$55) -> 44
A7: 4 | C7: 14 | D7: M | E7: 89 | F7: 70 | G7: 55 | H7: 69 | I7: 59 | J7: 72 | K7: 76 | L7: 91 | M7: 82 | N7: 77 | O7: 88 | P7: =SUM(E7:O7) -> 828 | Q7: =AVERAGE(E7:O7) -> 75.272727 | R7: =RANK(Q7,$Q$4:$Q$55) -> 22
A8: 5 | C8: 14 | D8: F | E8: 92 | F8: 87 | G8: 90 | H8: 88 | I8: 91 | J8: 92 | K8: 92 | L8: 93 | M8: 92 | N8: 96 | O8: 91 | P8: =SUM(E8:O8) -> 1004 | Q8: =AVERAGE(E8:O8) -> 91.272727 | R8: =RANK(Q8,$Q$4:$Q$55) -> 2
A9: 6 | C9: 16 | D9: F | E9: 55 | F9: 38 | G9: 51 | H9: 39 | I9: 51 | J9: 36 | K9: 41 | L9: 40 | M9: 50 | N9: 52 | O9: 79 | P9: =SUM(E9:O9) -> 532 | Q9: =AVERAGE(E9:O9) -> 48.363636 | R9: =RANK(Q9,$Q$4:$Q$55) -> 49
A10: 7 | C10: 14 | D10: F | E10: 90 | F10: 82 | G10: 63 | H10: 66 | I10: 69 | J10: 77 | K10: 80 | L10: 83 | M10: 88 | N10: 88 | O10: 90 | P10: =SUM(E10:O10) -> 876 | Q10: =AVERAGE(E10:O10) -> 79.636364 | R10: =RANK(Q10,$Q$4:$Q$55) -> 14
A11: 8 | C11: 14 | D11: M | E11: 88 | F11: 73 | G11: 61 | H11: 67 | I11: 68 | J11: 70 | K11: 66 | L11: 85 | M11: 79 | N11: 93 | O11: 78 | P11: =SUM(E11:O11) -> 828 | Q11: =AVERAGE(E11:O11) -> 75.272727 | R11: =RANK(Q11,$Q$4:$Q$55) -> 22
A12: 9 | C12: 15 | D12: M | E12: 77 | F12: 52 | G12: 33 | H12: 40 | I12: 40 | J12: 44 | K12: 50 | L12: 57 | M12: 51 | N12: 55 | O12: 78 | P12: =SUM(E12:O12) -> 577 | Q12: =AVERAGE(E12:O12) -> 52.454545 | R12: =RANK(Q12,$Q$4:$Q$55) -> 47
A13: 10 | C13: 15 | D13: M | E13: 89 | F13: 64 | G13: 56 | H13: 66 | I13: 58 | J13: 72 | K13: 82 | L13: 90 | M13: 77 | N13: 90 | O13: 100 | P13: =SUM(E13:O13) -> 844 | Q13: =AVERAGE(E13:O13) -> 76.727273 | R13: =RANK(Q13,$Q$4:$Q$55) -> 19
A14: 11 | C14: 14 | D14: F | E14: 84 | F14: 82 | G14: 84 | H14: 78 | I14: 68 | J14: 68 | K14: 82 | L14: 81 | M14: 81 | N14: 99 | O14: 94 | P14: =SUM(E14:O14) -> 901 | Q14: =AVERAGE(E14:O14) -> 81.909091 | R14: =RANK(Q14,$Q$4:$Q$55) -> 11
A15: 12 | C15: 15 | D15: F | E15: 71 | F15: 66 | G15: 55 | H15: 45 | I15: 54 | J15: 41 | K15: 51 | L15: 56 | M15: 60 | N15: 77 | O15: 85 | P15: =SUM(E15:O15) -> 661 | Q15: =AVERAGE(E15:O15) -> 60.090909 | R15: =RANK(Q15,$Q$4:$Q$55) -> 39
... A34: 31 | C34: 14 | D34: M | E34: 79 | F34: 48 | G34: 52 | H34: 51 | I34: 44 | J34: 54 | K34: 48 | L34: 64 | M34: 60 | N34: 73 | O34: 88 | P34: =SUM(E34:O34) -> 661 | Q34: =AVERAGE(E34:O34) -> 60.090909 | R34: =RANK(Q34,$Q$4:$Q$55) -> 39
A35: 32 | C35: 16 | D35: F | P35: =SUM(E35:O35) -> 0
A36: 33 | C36: 14 | D36: F | E36: 86 | F36: 81 | G36: 77 | H36: 71 | I36: 72 | J36: 75 | K36: 76 | L36: 80 | M36: 81 | N36: 91 | O36: 96 | P36: =SUM(E36:O36) -> 886 | Q36: =AVERAGE(E36:O36) -> 80.545455 | R36: =RANK(Q36,$Q$4:$Q$55) -> 12
A37: 34 | C37: 14 | D37: M | E37: 80 | F37: 62 | G37: 85 | H37: 76 | I37: 79 | J37: 77 | K37: 76 | L37: 77 | M37: 64 | N37: 95 | O37: 84 | P37: =SUM(E37:O37) -> 855 | Q37: =AVERAGE(E37:O37) -> 77.727273 | R37: =RANK(Q37,$Q$4:$Q$55) -> 16
A38: 35 | C38: 15 | D38: M | E38: 81 | F38: 67 | G38: 52 | H38: 68 | I38: 62 | J38: 84 | K38: 80 | L38: 89 | M38: 88 | N38: 89 | O38: 77 | P38: =SUM(E38:O38) -> 837 | Q38: =AVERAGE(E38:O38) -> 76.090909 | R38: =RANK(Q38,$Q$4:$Q$55) -> 21
A39: 36 | C39: 14 | D39: F | E39: 79 | F39: 63 | G39: 70 | H39: 61 | I39: 57 | J39: 65 | K39: 58 | L39: 74 | M39: 62 | N39: 79 | O39: 84 | P39: =SUM(E39:O39) -> 752 | Q39: =AVERAGE(E39:O39) -> 68.363636 | R39: =RANK(Q39,$Q$4:$Q$55) -> 31
A40: 37 | C40: 15 | D40: M | E40: 66 | F40: 66 | G40: 48 | H40: 63 | I40: 45 | J40: 57 | K40: 62 | L40: 73 | M40: 54 | N40: 47 | O40: 79 | P40: =SUM(E40:O40) -> 660 | Q40: =AVERAGE(E40:O40) -> 60 | R40: =RANK(Q40,$Q$4:$Q$55) -> 41
A41: 38 | C41: 15 | D41: F | E41: 84 | F41: 72 | G41: 74 | H41: 73 | I41: 61 | J41: 66 | K41: 71 | L41: 75 | M41: 78 | N41: 85 | O41: 82 | P41: =SUM(E41:O41) -> 821 | Q41: =AVERAGE(E41:O41) -> 74.636364 | R41: =RANK(Q41,$Q$4:$Q$55) -> 26
A42: 39 | C42: 14 | D42: M | E42: 84 | F42: 57 | G42: 57 | H42: 60 | I42: 45 | J42: 50 | K42: 50 | L42: 65 | M42: 57 | N42: 75 | O42: 79 | P42: =SUM(E42:O42) -> 679 | Q42: =AVERAGE(E42:O42) -> 61.727273 | R42: =RANK(Q42,$Q$4:$Q$55) -> 37
A43: 40 | C43: 15 | D43: F | P43: =SUM(E43:O43) -> 0
A44: 41 | C44: 16 | D44: M | E44: 58 | F44: 56 | G44: 56 | H44: 58 | I44: 57 | J44: 56 | K44: 66 | L44: 68 | M44: 53 | N44: 84 | O44: 85 | P44: =SUM(E44:O44) -> 697 | Q44: =AVERAGE(E44:O44) -> 63.363636 | R44: =RANK(Q44,$Q$4:$Q$55) -> 35
A45: 42 | C45: 16 | D45: F | E45: 67 | F45: 41 | G45: 31 | H45: 44 | I45: 51 | J45: 35 | K45: 43 | L45: 32 | M45: 48 | N45: 61 | O45: 66 | P45: =SUM(E45:O45) -> 519 | Q45: =AVERAGE(E45:O45) -> 47.181818 | R45: =RANK(Q45,$Q$4:$Q$55) -> 50
A46: 43 | C46: 14 | D46: M | E46: 83 | F46: 64 | G46: 62 | H46: 67 | I46: 58 | J46: 75 | K46: 69 | L46: 78 | M46: 60 | N46: 89 | O46: 78 | P46: =SUM(E46:O46) -> 783 | Q46: =AVERAGE(E46:O46) -> 71.181818 | R46: =RANK(Q46,$Q$4:$Q$55) -> 28
A47: 44 | C47: 15 | D47: F | E47: 63 | F47: 48 | G47: 37 | H47: 38 | I47: 39 | J47: 48 | K47: 46 | L47: 42 | M47: 53 | N47: 54 | O47: 78 | P47: =SUM(E47:O47) -> 546 | Q47: =AVERAGE(E47:O47) -> 49.636364 | R47: =RANK(Q47,$Q$4:$Q$55) -> 48
A48: 45 | C48: 14 | D48: M | E48: 81 | F48: 67 | G48: 61 | H48: 67 | I48: 61 | J48: 77 | K48: 81 | L48: 79 | M48: 80 | N48: 93 | O48: 100 | P48: =SUM(E48:O48) -> 847 | Q48: =AVERAGE(E48:O48) -> 77 | R48: =RANK(Q48,$Q$4:$Q$55) -> 18
A49: 46 | C49: 14 | D49: F | E49: 61 | F49: 47 | G49: 45 | H49: 52 | I49: 52 | J49: 45 | K49: 52 | L49: 51 | M49: 45 | N49: 85 | O49: 87 | P49: =SUM(E49:O49) -> 622 | Q49: =AVERAGE(E49:O49) -> 56.545455 | R49: =RANK(Q49,$Q$4:$Q$55) -> 46
A50: 47 | C50: 14 | D50: F | E50: 76 | F50: 74 | G50: 43 | H50: 55 | I50: 41 | J50: 52 | K50: 57 | L50: 67 | M50: 67 | N50: 72 | O50: 85 | P50: =SUM(E50:O50) -> 689 | Q50: =AVERAGE(E50:O50) -> 62.636364 | R50: =RANK(Q50,$Q$4:$Q$55) -> 36
A51: 48 | C51: 14 | D51: F | E51: 81 | F51: 63 | G51: 52 | H51: 60 | I51: 53 | J51: 54 | K51: 58 | L51: 72 | M51: 76 | N51: 69 | O51: 90 | P51: =SUM(E51:O51) -> 728 | Q51: =AVERAGE(E51:O51) -> 66.181818 | R51: =RANK(Q51,$Q$4:$Q$55) -> 33
A52: 49 | C52: 14 | D52: M | E52: 74 | F52: 76 | G52: 61 | H52: 68 | I52: 50 | J52: 56 | K52: 62 | L52: 61 | M52: 76 | N52: 82 | O52: 83 | P52: =SUM(E52:O52) -> 749 | Q52: =AVERAGE(E52:O52) -> 68.090909 | R52: =RANK(Q52,$Q$4:$Q$55) -> 32
A53: 50 | C53: 15 | D53: F | E53: 85 | F53: 58 | G53: 68 | H53: 71 | I53: 62 | J53: 60 | K53: 83 | L53: 85 | M53: 66 | N53: 94 | O53: 95 | P53: =SUM(E53:O53) -> 827 | Q53: =AVERAGE(E53:O53) -> 75.181818 | R53: =RANK(Q53,$Q$4:$Q$55) -> 24
A54: 51 | C54: 16 | D54: F | E54: 87 | F54: 72 | G54: 74 | H54: 71 | I54: 80 | J54: 72 | K54: 72 | L54: 82 | M54: 85 | N54: 89 | O54: 99 | P54: =SUM(E54:O54) -> 883 | Q54: =AVERAGE(E54:O54) -> 80.272727 | R54: =RANK(Q54,$Q$4:$Q$55) -> 13
A55: 52 | C55: 15 | D55: M | E55: 72 | F55: 51 | G55: 50 | H55: 51 | I55: 53 | J55: 56 | K55: 47 | L55: 55 | M55: 63 | N55: 78 | O55: 80 | P55: =SUM(E55:O55) -> 656 | Q55: =AVERAGE(E55:O55) -> 59.636364 | R55: =RANK(Q55,$Q$4:$Q$55) -> 42
A56: 53
A57: 54
A58: 55

Sheet 9A Sem 2
A1: Maria Rubbato Catholic School 2015 E.C Roster Grade 9A Student's
A2: Home Room Teacher Grade 9A
A3: No | B3: Student Name | C3: Age | D3: Sex | E3: Amharic | F3: English | G3: Maths | H3: physics | I3: chemistry | J3: Biology | K3: Geography | L3: History | M3: Civics | N3: ICT | O3: H.P.E | P3: Total | Q3: Average | R3: Rank | S3: Condc. | T3: Abse.
A4: 1 | C4: 14 | D4: F | E4: 80 | F4: 54 | G4: 70 | H4: 65 | I4: 51 | J4: 51 | K4: 61 | L4: 64 | M4: 58 | N4: 72 | O4: 84 | P4: =SUM(E4:O4) -> 710 | Q4: =AVERAGE(E4:O4) -> 64.545455 | R4: =RANK(Q4,$Q$4:$Q$55) -> 40
A5: 2 | C5: 16 | D5: M | E5: 96 | F5: 94 | G5: 96 | H5: 100 | I5: 96 | J5: 98 | K5: 96 | L5: 95 | M5: 100 | N5: 99 | O5: 100 | P5: =SUM(E5:O5) -> 1070 | Q5: =AVERAGE(E5:O5) -> 97.272727 | R5: =RANK(Q5,$Q$4:$Q$55) -> 1
A6: 3 | C6: 14 | D6: F | E6: 79 | F6: 50 | G6: 54 | H6: 50 | I6: 43 | J6: 46 | K6: 51 | L6: 41 | M6: 55 | N6: 77 | O6: 92 | P6: =SUM(E6:O6) -> 638 | Q6: =AVERAGE(E6:O6) -> 58 | R6: =RANK(Q6,$Q$4:$Q$55) -> 45
A7: 4 | C7: 14 | D7: M | E7: 82 | F7: 73 | G7: 71 | H7: 69 | I7: 66 | J7: 80 | K7: 82 | L7: 91 | M7: 88 | N7: 92 | O7: 91 | P7: =SUM(E7:O7) -> 885 | Q7: =AVERAGE(E7:O7) -> 80.454545 | R7: =RANK(Q7,$Q$4:$Q$55) -> 16
A8: 5 | C8: 14 | D8: F | E8: 91 | F8: 96 | G8: 93 | H8: 90 | I8: 83 | J8: 96 | K8: 86 | L8: 86 | M8: 96 | N8: 99 | O8: 94 | P8: =SUM(E8:O8) -> 1010 | Q8: =AVERAGE(E8:O8) -> 91.818182 | R8: =RANK(Q8,$Q$4:$Q$55) -> 3
A9: 6 | C9: 16 | D9: F | E9: 69 | F9: 44 | G9: 42 | H9: 44 | I9: 41 | J9: 38 | K9: 45 | L9: 44 | M9: 48 | N9: 65 | O9: 64 | P9: =SUM(E9:O9) -> 544 | Q9: =AVERAGE(E9:O9) -> 49.454545 | R9: =RANK(Q9,$Q$4:$Q$55) -> 48
A10: 7 | C10: 14 | D10: F | E10: 85 | F10: 83 | G10: 60 | H10: 69 | I10: 64 | J10: 81 | K10: 82 | L10: 81 | M10: 94 | N10: 87 | O10: 87 | P10: =SUM(E10:O10) -> 873 | Q10: =AVERAGE(E10:O10) -> 79.363636 | R10: =RANK(Q10,$Q$4:$Q$55) -> 19
A11: 8 | C11: 14 | D11: M | E11: 87 | F11: 74 | G11: 54 | H11: 52 | I11: 53 | J11: 59 | K11: 67 | L11: 76 | M11: 93 | N11: 83 | O11: 89 | P11: =SUM(E11:O11) -> 787 | Q11: =AVERAGE(E11:O11) -> 71.545455 | R11: =RANK(Q11,$Q$4:$Q$55) -> 28
A12: 9 | C12: 15 | D12: M | E12: 57 | F12: 46 | G12: 35 | H12: 42 | I12: 56 | J12: 34 | K12: 51 | L12: 40 | M12: 53 | N12: 54 | O12: 83 | P12: =SUM(E12:O12) -> 551 | Q12: =AVERAGE(E12:O12) -> 50.090909 | R12: =RANK(Q12,$Q$4:$Q$55) -> 47
A13: 10 | C13: 15 | D13: M | E13: 92 | F13: 64 | G13: 52 | H13: 58 | I13: 58 | J13: 75 | K13: 79 | L13: 73 | M13: 82 | N13: 85 | O13: 92 | P13: =SUM(E13:O13) -> 810 | Q13: =AVERAGE(E13:O13) -> 73.636364 | R13: =RANK(Q13,$Q$4:$Q$55) -> 25
A14: 11 | C14: 14 | D14: F | E14: 87 | F14: 85 | G14: 81 | H14: 78 | I14: 68 | J14: 73 | K14: 78 | L14: 77 | M14: 90 | N14: 99 | O14: 92 | P14: =SUM(E14:O14) -> 908 | Q14: =AVERAGE(E14:O14) -> 82.545455 | R14: =RANK(Q14,$Q$4:$Q$55) -> 14
A15: 12 | C15: 15 | D15: F | E15: 84 | F15: 50 | G15: 57 | H15: 53 | I15: 54 | J15: 50 | K15: 55 | L15: 50 | M15: 63 | N15: 76 | O15: 93 | P15: =SUM(E15:O15) -> 685 | Q15: =AVERAGE(E15:O15) -> 62.272727 | R15: =RANK(Q15,$Q$4:$Q$55) -> 42
... A34: 31 | C34: 14 | D34: M | E34: 78 | F34: 56 | G34: 57 | H34: 44 | I34: 54 | J34: 57 | K34: 70 | L34: 80 | M34: 58 | N34: 78 | O34: 81 | P34: =SUM(E34:O34) -> 713 | Q34: =AVERAGE(E34:O34) -> 64.818182 | R34: =RANK(Q34,$Q$4:$Q$55) -> 39
A35: 32 | C35: 16 | D35: F | P35: =SUM(E35:O35) -> 0
A36: 33 | C36: 14 | D36: F | E36: 85 | F36: 82 | G36: 63 | H36: 72 | I36: 78 | J36: 81 | K36: 75 | L36: 73 | M36: 93 | N36: 93 | O36: 88 | P36: =SUM(E36:O36) -> 883 | Q36: =AVERAGE(E36:O36) -> 80.272727 | R36: =RANK(Q36,$Q$4:$Q$55) -> 17
A37: 34 | C37: 14 | D37: M | E37: 82 | F37: 68 | G37: 87 | H37: 80 | I37: 73 | J37: 76 | K37: 73 | L37: 64 | M37: 71 | N37: 91 | O37: 91 | P37: =SUM(E37:O37) -> 856 | Q37: =AVERAGE(E37:O37) -> 77.818182 | R37: =RANK(Q37,$Q$4:$Q$55) -> 22
A38: 35 | C38: 15 | D38: M | P38: =SUM(E38:O38) -> 0
A39: 36 | C39: 14 | D39: F | E39: 80 | F39: 69 | G39: 58 | H39: 57 | I39: 56 | J39: 71 | K39: 65 | L39: 71 | M39: 69 | N39: 86 | O39: 93 | P39: =SUM(E39:O39) -> 775 | Q39: =AVERAGE(E39:O39) -> 70.454545 | R39: =RANK(Q39,$Q$4:$Q$55) -> 30
A40: 37 | C40: 15 | D40: M | E40: 70 | F40: 76 | G40: 43 | H40: 51 | I40: 48 | J40: 58 | K40: 64 | L40: 64 | M40: 80 | N40: 61 | O40: 74 | P40: =SUM(E40:O40) -> 689 | Q40: =AVERAGE(E40:O40) -> 62.636364 | R40: =RANK(Q40,$Q$4:$Q$55) -> 41
A41: 38 | C41: 15 | D41: F | E41: 84 | F41: 78 | G41: 70 | H41: 66 | I41: 64 | J41: 58 | K41: 69 | L41: 64 | M41: 87 | N41: 82 | O41: 92 | P41: =SUM(E41:O41) -> 814 | Q41: =AVERAGE(E41:O41) -> 74 | R41: =RANK(Q41,$Q$4:$Q$55) -> 24
A42: 39 | C42: 14 | D42: M | E42: 81 | F42: 67 | G42: 58 | H42: 59 | I42: 53 | J42: 59 | K42: 67 | L42: 55 | M42: 63 | N42: 89 | O42: 90 | P42: =SUM(E42:O42) -> 741 | Q42: =AVERAGE(E42:O42) -> 67.363636 | R42: =RANK(Q42,$Q$4:$Q$55) -> 33
A43: 40 | C43: 15 | D43: F | P43: =SUM(E43:O43) -> 0
A44: 41 | C44: 16 | D44: M | E44: 64 | F44: 56 | G44: 61 | H44: 60 | I44: 53 | J44: 56 | K44: 70 | L44: 70 | M44: 66 | N44: 88 | O44: 92 | P44: =SUM(E44:O44) -> 736 | Q44: =AVERAGE(E44:O44) -> 66.909091 | R44: =RANK(Q44,$Q$4:$Q$55) -> 35
A45: 42 | C45: 16 | D45: F | P45: =SUM(E45:O45) -> 0
A46: 43 | C46: 14 | D46: M | E46: 77 | F46: 69 | G46: 62 | H46: 61 | I46: 59 | J46: 82 | K46: 74 | L46: 57 | M46: 81 | N46: 90 | O46: 88 | P46: =SUM(E46:O46) -> 800 | Q46: =AVERAGE(E46:O46) -> 72.727273 | R46: =RANK(Q46,$Q$4:$Q$55) -> 26
A47: 44 | C47: 15 | D47: F | E47: 77 | F47: 55 | G47: 36 | H47: 33 | I47: 44 | J47: 45 | K47: 46 | L47: 44 | M47: 66 | N47: 72 | O47: 70 | P47: =SUM(E47:O47) -> 588 | Q47: =AVERAGE(E47:O47) -> 53.454545 | R47: =RANK(Q47,$Q$4:$Q$55) -> 46
A48: 45 | C48: 14 | D48: M | E48: 85 | F48: 69 | G48: 81 | H48: 72 | I48: 75 | J48: 81 | K48: 84 | L48: 80 | M48: 87 | N48: 95 | O48: 100 | P48: =SUM(E48:O48) -> 909 | Q48: =AVERAGE(E48:O48) -> 82.636364 | R48: =RANK(Q48,$Q$4:$Q$55) -> 13
A49: 46 | C49: 14 | D49: F | E49: 68 | F49: 56 | G49: 41 | H49: 54 | I49: 40 | J49: 46 | K49: 60 | L49: 58 | M49: 52 | N49: 82 | O49: 88 | P49: =SUM(E49:O49) -> 645 | Q49: =AVERAGE(E49:O49) -> 58.636364 | R49: =RANK(Q49,$Q$4:$Q$55) -> 44
A50: 47 | C50: 14 | D50: F | E50: 80 | F50: 68 | G50: 41 | H50: 43 | I50: 46 | J50: 58 | K50: 66 | L50: 71 | M50: 80 | N50: 81 | O50: 85 | P50: =SUM(E50:O50) -> 719 | Q50: =AVERAGE(E50:O50) -> 65.363636 | R50: =RANK(Q50,$Q$4:$Q$55) -> 37
A51: 48 | C51: 14 | D51: F | E51: 82 | F51: 71 | G51: 53 | H51: 63 | I51: 43 | J51: 60 | K51: 63 | L51: 59 | M51: 64 | N51: 84 | O51: 94 | P51: =SUM(E51:O51) -> 736 | Q51: =AVERAGE(E51:O51) -> 66.909091 | R51: =RANK(Q51,$Q$4:$Q$55) -> 35
A52: 49 | C52: 14 | D52: M | E52: 67 | F52: 86 | G52: 55 | H52: 59 | I52: 64 | J52: 51 | K52: 61 | L52: 69 | M52: 78 | N52: 93 | O52: 84 | P52: =SUM(E52:O52) -> 767 | Q52: =AVERAGE(E52:O52) -> 69.727273 | R52: =RANK(Q52,$Q$4:$Q$55) -> 31
A53: 50 | C53: 15 | D53: F | E53: 83 | F53: 64 | G53: 67 | H53: 67 | I53: 58 | J53: 74 | K53: 82 | L53: 86 | M53: 75 | N53: 88 | O53: 94 | P53: =SUM(E53:O53) -> 838 | Q53: =AVERAGE(E53:O53) -> 76.181818 | R53: =RANK(Q53,$Q$4:$Q$55) -> 23
A54: 51 | C54: 16 | D54: F | E54: 84 | F54: 78 | G54: 75 | H54: 68 | I54: 64 | J54: 72 | K54: 69 | L54: 71 | M54: 87 | N54: 100 | O54: 92 | P54: =SUM(E54:O54) -> 860 | Q54: =AVERAGE(E54:O54) -> 78.181818 | R54: =RANK(Q54,$Q$4:$Q$55) -> 21
A55: 52 | C55: 15 | D55: M | E55: 75 | F55: 61 | G55: 53 | H55: 52 | I55: 55 | J55: 57 | K55: 59 | L55: 63 | M55: 65 | N55: 86 | O55: 93 | P55: =SUM(E55:O55) -> 719 | Q55: =AVERAGE(E55:O55) -> 65.363636 | R55: =RANK(Q55,$Q$4:$Q$55) -> 37
A56: 53
A57: 54
A58: 55

Sheet 9A Sem avr
A1: Maria Rubbato Catholic School 2015E.C Roster Grade 9A Student's
A2: Home Room Teacher Grade 9A
A3: No | B3: Student Name | C3: Age | D3: Sex | E3: Semster 1 Average | F3: Semster 2 Average | G3: Average | H3: Rank
A4: 1 | C4: 14 | D4: F | E4: ='9A Sem 1'!Q4 -> 61.545455 | F4: ='9A Sem 2'!Q4 -> 64.545455 | G4: =AVERAGE(E4:F4) -> 63.045455 | H4: =RANK(G4,$G$4:$G$55) -> 37
A5: 2 | C5: 16 | D5: M | E5: ='9A Sem 1'!Q5 -> 96.363636 | F5: ='9A Sem 2'!Q5 -> 97.272727 | G5: =AVERAGE(E5:F5) -> 96.818182 | H5: =RANK(G5,$G$4:$G$55) -> 1
A6: 3 | C6: 14 | D6: F | E6: ='9A Sem 1'!Q6 -> 57.545455 | F6: ='9A Sem 2'!Q6 -> 58 | G6: =AVERAGE(E6:F6) -> 57.772727 | H6: =RANK(G6,$G$4:$G$55) -> 44
A7: 4 | C7: 14 | D7: M | E7: ='9A Sem 1'!Q7 -> 75.272727 | F7: ='9A Sem 2'!Q7 -> 80.454545 | G7: =AVERAGE(E7:F7) -> 77.863636 | H7: =RANK(G7,$G$4:$G$55) -> 20
A8: 5 | C8: 14 | D8: F | E8: ='9A Sem 1'!Q8 -> 91.272727 | F8: ='9A Sem 2'!Q8 -> 91.818182 | G8: =AVERAGE(E8:F8) -> 91.545455 | H8: =RANK(G8,$G$4:$G$55) -> 3
A9: 6 | C9: 16 | D9: F | E9: ='9A Sem 1'!Q9 -> 48.363636 | F9: ='9A Sem 2'!Q9 -> 49.454545 | G9: =AVERAGE(E9:F9) -> 48.909091 | H9: =RANK(G9,$G$4:$G$55) -> 48
A10: 7 | C10: 14 | D10: F | E10: ='9A Sem 1'!Q10 -> 79.636364 | F10: ='9A Sem 2'!Q10 -> 79.363636 | G10: =AVERAGE(E10:F10) -> 79.5 | H10: =RANK(G10,$G$4:$G$55) -> 16
A11: 8 | C11: 14 | D11: M | E11: ='9A Sem 1'!Q11 -> 75.272727 | F11: ='9A Sem 2'!Q11 -> 71.545455 | G11: =AVERAGE(E11:F11) -> 73.409091 | H11: =RANK(G11,$G$4:$G$55) -> 26
A12: 9 | C12: 15 | D12: M | E12: ='9A Sem 1'!Q12 -> 52.454545 | F12: ='9A Sem 2'!Q12 -> 50.090909 | G12: =AVERAGE(E12:F12) -> 51.272727 | H12: =RANK(G12,$G$4:$G$55) -> 47
A13: 10 | C13: 15 | D13: M | E13: ='9A Sem 1'!Q13 -> 76.727273 | F13: ='9A Sem 2'!Q13 -> 73.636364 | G13: =AVERAGE(E13:F13) -> 75.181818 | H13: =RANK(G13,$G$4:$G$55) -> 24
A14: 11 | C14: 14 | D14: F | E14: ='9A Sem 1'!Q14 -> 81.909091 | F14: ='9A Sem 2'!Q14 -> 82.545455 | G14: =AVERAGE(E14:F14) -> 82.227273 | H14: =RANK(G14,$G$4:$G$55) -> 11
A15: 12 | C15: 15 | D15: F | E15: ='9A Sem 1'!Q15 -> 60.090909 | F15: ='9A Sem 2'!Q15 -> 62.272727 | G15: =AVERAGE(E15:F15) -> 61.181818 | H15: =RANK(G15,$G$4:$G$55) -> 42
... A55: 52 | C55: 15 | D55: M | E55: ='9A Sem 1'!Q55 -> 59.636364 | F55: ='9A Sem 2'!Q55 -> 65.363636 | G55: =AVERAGE(E55:F55) -> 62.5 | H55: =RANK(G55,$G$4:$G$55) -> 39
A56: 53 | E56: ='9A Sem 1'!Q56 -> 0 | F56: ='9A Sem 2'!Q56 -> 0 | G56: =AVERAGE(E56:F56) -> 0
A57: 54 | E57: ='9A Sem 1'!Q57 -> 0 | F57: ='9A Sem 2'!Q57 -> 0 | G57: =AVERAGE(E57:F57) -> 0
A58: 55 | E58: ='9A Sem 1'!Q58 -> 0 | F58: ='9A Sem 2'!Q58 -> 0 | G58: =AVERAGE(E58:F58) -> 0

Sheet Roster 9B
A1: Maria Rubbato Catholic School 2015 E.C Roster Grade 9B Student's
A3: Home Room Teacher Grade 9B
A5: No | B5: Student Name | C5: Age | D5: Sex | E5: Semester | F5: Amharic | G5: English | H5: Maths | I5: physics | J5: chemistry | K5: Biology | L5: Geography | M5: History | N5: Civics | O5: ICT | P5: H.P.E | Q5: Total | R5: Average | S5: Rank | T5: Condc. | U5: Abse.
A6: 1 | C6: 15 | D6: M | E6: Semister 1 | F6: ='9B Sem 1'!E4 -> 87 | G6: ='9B Sem 1'!F4 -> 51 | H6: ='9B Sem 1'!G4 -> 69 | I6: ='9B Sem 1'!H4 -> 47 | J6: ='9B Sem 1'!I4 -> 61 | K6: ='9B Sem 1'!J4 -> 55 | L6: ='9B Sem 1'!K4 -> 51 | M6: ='9B Sem 1'!L4 -> 64 | ... U6: ='9B Sem 1'!T4 -> 0
C7: 15 | D7: M | E7: Semister 2 | F7: ='9B Sem 2'!E4 -> 82 | G7: ='9B Sem 2'!F4 -> 62 | H7: ='9B Sem 2'!G4 -> 73 | I7: ='9B Sem 2'!H4 -> 55 | J7: ='9B Sem 2'!I4 -> 61 | K7: ='9B Sem 2'!J4 -> 58 | L7: ='9B Sem 2'!K4 -> 57 | M7: ='9B Sem 2'!L4 -> 62 | ... U7: ='9B Sem 2'!T4 -> 0
C8: 15 | D8: M | E8: Average | F8: =AVERAGE(F6:F7) -> 84.5 | G8: =AVERAGE(G6:G7) -> 56.5 | H8: =AVERAGE(H6:H7) -> 71 | I8: =AVERAGE(I6:I7) -> 51 | J8: =AVERAGE(J6:J7) -> 61 | K8: =AVERAGE(K6:K7) -> 56.5 | L8: =AVERAGE(L6:L7) -> 54 | M8: =AVERAGE(M6:M7) -> 63 | ... R8: =AVERAGE(R6:R7) -> 65.227273 | T8: =AVERAGE(T6:T7) -> 0 | U8: =AVERAGE(U6:U7) -> 0
A9: 2 | C9: 15 | D9: F | E9: Semister 1 | F9: ='9B Sem 1'!E5 -> 87 | G9: ='9B Sem 1'!F5 -> 66 | H9: ='9B Sem 1'!G5 -> 63 | I9: ='9B Sem 1'!H5 -> 72 | J9: ='9B Sem 1'!I5 -> 58 | K9: ='9B Sem 1'!J5 -> 65 | L9: ='9B Sem 1'!K5 -> 69 | M9: ='9B Sem 1'!L5 -> 81 | ... U9: ='9B Sem 1'!T5 -> 0
C10: 15 | D10: F | E10: Semister 2 | F10: ='9B Sem 2'!E5 -> 91 | G10: ='9B Sem 2'!F5 -> 68 | H10: ='9B Sem 2'!G5 -> 64 | I10: ='9B Sem 2'!H5 -> 66 | J10: ='9B Sem 2'!I5 -> 59 | K10: ='9B Sem 2'!J5 -> 62 | L10: ='9B Sem 2'!K5 -> 65 | M10: ='9B Sem 2'!L5 -> 73 | ... U10: ='9B Sem 2'!T5 -> 0
C11: 15 | D11: F | E11: Average | F11: =AVERAGE(F9:F10) -> 89 | G11: =AVERAGE(G9:G10) -> 67 | H11: =AVERAGE(H9:H10) -> 63.5 | I11: =AVERAGE(I9:I10) -> 69 | J11: =AVERAGE(J9:J10) -> 58.5 | K11: =AVERAGE(K9:K10) -> 63.5 | L11: =AVERAGE(L9:L10) -> 67 | M11: =AVERAGE(M9:M10) -> 77 | ... R11: =AVERAGE(R9:R10) -> 72.636364 | T11: =AVERAGE(T9:T10) -> 0 | U11: =AVERAGE(U9:U10) -> 0
A12: 3 | C12: 14 | D12: M | E12: Semister 1 | F12: ='9B Sem 1'!E6 -> 88 | G12: ='9B Sem 1'!F6 -> 70 | H12: ='9B Sem 1'!G6 -> 62 | I12: ='9B Sem 1'!H6 -> 57 | J12: ='9B Sem 1'!I6 -> 50 | K12: ='9B Sem 1'!J6 -> 51 | L12: ='9B Sem 1'!K6 -> 59 | M12: ='9B Sem 1'!L6 -> 68 | ... U12: ='9B Sem 1'!T6 -> 0
C13: 14 | D13: M | E13: Semister 2 | F13: ='9B Sem 2'!E6 -> 92 | G13: ='9B Sem 2'!F6 -> 77 | H13: ='9B Sem 2'!G6 -> 55 | I13: ='9B Sem 2'!H6 -> 55 | J13: ='9B Sem 2'!I6 -> 54 | K13: ='9B Sem 2'!J6 -> 58 | L13: ='9B Sem 2'!K6 -> 59 | M13: ='9B Sem 2'!L6 -> 61 | ... U13: ='9B Sem 2'!T6 -> 0
C14: 14 | D14: M | E14: Average | F14: =AVERAGE(F12:F13) -> 90 | G14: =AVERAGE(G12:G13) -> 73.5 | H14: =AVERAGE(H12:H13) -> 58.5 | I14: =AVERAGE(I12:I13) -> 56 | J14: =AVERAGE(J12:J13) -> 52 | K14: =AVERAGE(K12:K13) -> 54.5 | L14: =AVERAGE(L12:L13) -> 59 | M14: =AVERAGE(M12:M13) -> 64.5 | ... R14: =AVERAGE(R12:R13) -> 68.227273 | T14: =AVERAGE(T12:T13) -> 0 | U14: =AVERAGE(U12:U13) -> 0
A15: 4 | C15: 14 | D15: M | E15: Semister 1 | F15: ='9B Sem 1'!E7 -> 84 | G15: ='9B Sem 1'!F7 -> 77 | H15: ='9B Sem 1'!G7 -> 91 | I15: ='9B Sem 1'!H7 -> 71 | J15: ='9B Sem 1'!I7 -> 89 | K15: ='9B Sem 1'!J7 -> 86 | L15: ='9B Sem 1'!K7 -> 79 | M15: ='9B Sem 1'!L7 -> 84 | ... U15: ='9B Sem 1'!T7 -> 0
C16: 14 | D16: M | E16: Semister 2 | F16: ='9B Sem 2'!E7 -> 88 | G16: ='9B Sem 2'!F7 -> 72 | H16: ='9B Sem 2'!G7 -> 86 | I16: ='9B Sem 2'!H7 -> 78 | J16: ='9B Sem 2'!I7 -> 85 | K16: ='9B Sem 2'!J7 -> 91 | L16: ='9B Sem 2'!K7 -> 74 | M16: ='9B Sem 2'!L7 -> 71 | ... U16: ='9B Sem 2'!T7 -> 0
C17: 14 | D17: M | E17: Average | F17: =AVERAGE(F15:F16) -> 86 | G17: =AVERAGE(G15:G16) -> 74.5 | H17: =AVERAGE(H15:H16) -> 88.5 | I17: =AVERAGE(I15:I16) -> 74.5 | J17: =AVERAGE(J15:J16) -> 87 | K17: =AVERAGE(K15:K16) -> 88.5 | L17: =AVERAGE(L15:L16) -> 76.5 | M17: =AVERAGE(M15:M16) -> 77.5 | ... R17: =AVERAGE(R15:R16) -> 82.954545 | T17: =AVERAGE(T15:T16) -> 0 | U17: =AVERAGE(U15:U16) -> 0
A18: 5 | C18: 14 | D18: M | E18: Semister 1 | F18: ='9B Sem 1'!E8 -> 67 | G18: ='9B Sem 1'!F8 -> 54 | H18: ='9B Sem 1'!G8 -> 42 | I18: ='9B Sem 1'!H8 -> 56 | J18: ='9B Sem 1'!I8 -> 57 | K18: ='9B Sem 1'!J8 -> 55 | L18: ='9B Sem 1'!K8 -> 58 | M18: ='9B Sem 1'!L8 -> 62 | ... U18: ='9B Sem 1'!T8 -> 0
C19: 14 | D19: M | E19: Semister 2 | F19: ='9B Sem 2'!E8 -> 73 | G19: ='9B Sem 2'!F8 -> 55 | H19: ='9B Sem 2'!G8 -> 55 | I19: ='9B Sem 2'!H8 -> 52 | J19: ='9B Sem 2'!I8 -> 53 | K19: ='9B Sem 2'!J8 -> 52 | L19: ='9B Sem 2'!K8 -> 52 | M19: ='9B Sem 2'!L8 -> 60 | ... U19: ='9B Sem 2'!T8 -> 0
C20: 14 | D20: M | E20: Average | F20: =AVERAGE(F18:F19) -> 70 | G20: =AVERAGE(G18:G19) -> 54.5 | H20: =AVERAGE(H18:H19) -> 48.5 | I20: =AVERAGE(I18:I19) -> 54 | J20: =AVERAGE(J18:J19) -> 55 | K20: =AVERAGE(K18:K19) -> 53.5 | L20: =AVERAGE(L18:L19) -> 55 | M20: =AVERAGE(M18:M19) -> 61 | ... R20: =AVERAGE(R18:R19) -> 60.681818 | T20: =AVERAGE(T18:T19) -> 0 | U20: =AVERAGE(U18:U19) -> 0
A21: 6 | C21: 15 | D21: M | E21: Semister 1 | F21: ='9B Sem 1'!E9 -> 73 | G21: ='9B Sem 1'!F9 -> 66 | H21: ='9B Sem 1'!G9 -> 72 | I21: ='9B Sem 1'!H9 -> 64 | J21: ='9B Sem 1'!I9 -> 68 | K21: ='9B Sem 1'!J9 -> 86 | L21: ='9B Sem 1'!K9 -> 78 | M21: ='9B Sem 1'!L9 -> 81 | ... U21: ='9B Sem 1'!T9 -> 0
C22: 15 | D22: F | E22: Semister 2 | F22: ='9B Sem 2'!E9 -> 77 | G22: ='9B Sem 2'!F9 -> 69 | H22: ='9B Sem 2'!G9 -> 87 | I22: ='9B Sem 2'!H9 -> 58 | J22: ='9B Sem 2'!I9 -> 68 | K22: ='9B Sem 2'!J9 -> 82 | L22: ='9B Sem 2'!K9 -> 72 | M22: ='9B Sem 2'!L9 -> 74 | ... U22: ='9B Sem 2'!T9 -> 0
C23: 15 | D23: F | E23: Average | F23: =AVERAGE(F21:F22) -> 75 | G23: =AVERAGE(G21:G22) -> 67.5 | H23: =AVERAGE(H21:H22) -> 79.5 | I23: =AVERAGE(I21:I22) -> 61 | J23: =AVERAGE(J21:J22) -> 68 | K23: =AVERAGE(K21:K22) -> 84 | L23: =AVERAGE(L21:L22) -> 75 | M23: =AVERAGE(M21:M22) -> 77.5 | ... R23: =AVERAGE(R21:R22) -> 76.136364 | T23: =AVERAGE(T21:T22) -> 0 | U23: =AVERAGE(U21:U22) -> 0
A24: 7 | C24: 14 | D24: F | E24: Semister 1 | F24: ='9B Sem 1'!E10 -> 78 | G24: ='9B Sem 1'!F10 -> 67 | H24: ='9B Sem 1'!G10 -> 73 | I24: ='9B Sem 1'!H10 -> 61 | J24: ='9B Sem 1'!I10 -> 58 | K24: ='9B Sem 1'!J10 -> 69 | L24: ='9B Sem 1'!K10 -> 69 | M24: ='9B Sem 1'!L10 -> 67 | ... U24: ='9B Sem 1'!T10 -> 0
C25: 14 | D25: F | E25: Semister 2 | F25: ='9B Sem 2'!E10 -> 87 | G25: ='9B Sem 2'!F10 -> 81 | H25: ='9B Sem 2'!G10 -> 59 | I25: ='9B Sem 2'!H10 -> 61 | J25: ='9B Sem 2'!I10 -> 52 | K25: ='9B Sem 2'!J10 -> 70 | L25: ='9B Sem 2'!K10 -> 72 | M25: ='9B Sem 2'!L10 -> 66 | ... U25: ='9B Sem 2'!T10 -> 0
C26: 14 | D26: F | E26: Average | F26: =AVERAGE(F24:F25) -> 82.5 | G26: =AVERAGE(G24:G25) -> 74 | H26: =AVERAGE(H24:H25) -> 66 | I26: =AVERAGE(I24:I25) -> 61 | J26: =AVERAGE(J24:J25) -> 55 | K26: =AVERAGE(K24:K25) -> 69.5 | L26: =AVERAGE(L24:L25) -> 70.5 | M26: =AVERAGE(M24:M25) -> 66.5 | ... R26: =AVERAGE(R24:R25) -> 71.272727 | T26: =AVERAGE(T24:T25) -> 0 | U26: =AVERAGE(U24:U25) -> 0
A27: 8 | C27: 15 | D27: M | E27: Semister 1 | F27: ='9B Sem 1'!E11 -> 79 | G27: ='9B Sem 1'!F11 -> 62 | H27: ='9B Sem 1'!G11 -> 58 | I27: ='9B Sem 1'!H11 -> 68 | J27: ='9B Sem 1'!I11 -> 60 | K27: ='9B Sem 1'!J11 -> 55 | L27: ='9B Sem 1'!K11 -> 57 | M27: ='9B Sem 1'!L11 -> 68 | ... U27: ='9B Sem 1'!T11 -> 0
C28: 15 | D28: M | E28: Semister 2 | F28: ='9B Sem 2'!E11 -> 79 | G28: ='9B Sem 2'!F11 -> 64 | H28: ='9B Sem 2'!G11 -> 65 | I28: ='9B Sem 2'!H11 -> 59 | J28: ='9B Sem 2'!I11 -> 56 | K28: ='9B Sem 2'!J11 -> 52 | L28: ='9B Sem 2'!K11 -> 55 | M28: ='9B Sem 2'!L11 -> 50 | ... U28: ='9B Sem 2'!T11 -> 0
C29: 15 | D29: M | E29: Average | F29: =AVERAGE(F27:F28) -> 79 | G29: =AVERAGE(G27:G28) -> 63 | H29: =AVERAGE(H27:H28) -> 61.5 | I29: =AVERAGE(I27:I28) -> 63.5 | J29: =AVERAGE(J27:J28) -> 58 | K29: =AVERAGE(K27:K28) -> 53.5 | L29: =AVERAGE(L27:L28) -> 56 | M29: =AVERAGE(M27:M28) -> 59 | ... R29: =AVERAGE(R27:R28) -> 65.954545 | T29: =AVERAGE(T27:T28) -> 0 | U29: =AVERAGE(U27:U28) -> 0
A30: 9 | C30: 15 | D30: M | E30: Semister 1 | F30: ='9B Sem 1'!E12 -> 83 | G30: ='9B Sem 1'!F12 -> 51 | H30: ='9B Sem 1'!G12 -> 46 | I30: ='9B Sem 1'!H12 -> 51 | J30: ='9B Sem 1'!I12 -> 74 | K30: ='9B Sem 1'!J12 -> 78 | L30: ='9B Sem 1'!K12 -> 77 | M30: ='9B Sem 1'!L12 -> 91 | ... U30: ='9B Sem 1'!T12 -> 0
C31: 15 | D31: M | E31: Semister 2 | F31: ='9B Sem 2'!E12 -> 87 | G31: ='9B Sem 2'!F12 -> 64 | H31: ='9B Sem 2'!G12 -> 47 | I31: ='9B Sem 2'!H12 -> 57 | J31: ='9B Sem 2'!I12 -> 61 | K31: ='9B Sem 2'!J12 -> 70 | L31: ='9B Sem 2'!K12 -> 80 | M31: ='9B Sem 2'!L12 -> 77 | ... U31: ='9B Sem 2'!T12 -> 0
C32: 15 | D32: M | E32: Average | F32: =AVERAGE(F30:F31) -> 85 | G32: =AVERAGE(G30:G31) -> 57.5 | H32: =AVERAGE(H30:H31) -> 46.5 | I32: =AVERAGE(I30:I31) -> 54 | J32: =AVERAGE(J30:J31) -> 67.5 | K32: =AVERAGE(K30:K31) -> 74 | L32: =AVERAGE(L30:L31) -> 78.5 | M32: =AVERAGE(M30:M31) -> 84 | ... R32: =AVERAGE(R30:R31) -> 70.545455 | T32: =AVERAGE(T30:T31) -> 0 | U32: =AVERAGE(U30:U31) -> 0
A33: 10 | C33: 14 | D33: F | E33: Semister 1 | F33: ='9B Sem 1'!E13 -> 91 | G33: ='9B Sem 1'!F13 -> 67 | H33: ='9B Sem 1'!G13 -> 82 | I33: ='9B Sem 1'!H13 -> 64 | J33: ='9B Sem 1'!I13 -> 72 | K33: ='9B Sem 1'!J13 -> 68 | L33: ='9B Sem 1'!K13 -> 64 | M33: ='9B Sem 1'!L13 -> 81 | ... U33: ='9B Sem 1'!T13 -> 0
C34: 14 | D34: F | E34: Semister 2 | F34: ='9B Sem 2'!E13 -> 91 | G34: ='9B Sem 2'!F13 -> 84 | H34: ='9B Sem 2'!G13 -> 78 | I34: ='9B Sem 2'!H13 -> 71 | J34: ='9B Sem 2'!I13 -> 77 | K34: ='9B Sem 2'!J13 -> 82 | L34: ='9B Sem 2'!K13 -> 84 | M34: ='9B Sem 2'!L13 -> 75 | ... U34: ='9B Sem 2'!T13 -> 0
C35: 14 | D35: F | E35: Average | F35: =AVERAGE(F33:F34) -> 91 | G35: =AVERAGE(G33:G34) -> 75.5 | H35: =AVERAGE(H33:H34) -> 80 | I35: =AVERAGE(I33:I34) -> 67.5 | J35: =AVERAGE(J33:J34) -> 74.5 | K35: =AVERAGE(K33:K34) -> 75 | L35: =AVERAGE(L33:L34) -> 74 | M35: =AVERAGE(M33:M34) -> 78 | ... R35: =AVERAGE(R33:R34) -> 79.681818 | T35: =AVERAGE(T33:T34) -> 0 | U35: =AVERAGE(U33:U34) -> 0
A36: 11 | C36: 14 | D36: F | E36: Semister 1 | F36: ='9B Sem 1'!E14 -> 87 | G36: ='9B Sem 1'!F14 -> 74 | H36: ='9B Sem 1'!G14 -> 84 | I36: ='9B Sem 1'!H14 -> 76 | J36: ='9B Sem 1'!I14 -> 81 | K36: ='9B Sem 1'!J14 -> 94 | L36: ='9B Sem 1'!K14 -> 80 | M36: ='9B Sem 1'!L14 -> 83 | ... U36: ='9B Sem 1'!T14 -> 0
C37: 14 | D37: F | E37: Semister 2 | F37: ='9B Sem 2'!E14 -> 93 | G37: ='9B Sem 2'!F14 -> 76 | H37: ='9B Sem 2'!G14 -> 84 | I37: ='9B Sem 2'!H14 -> 78 | J37: ='9B Sem 2'!I14 -> 82 | K37: ='9B Sem 2'!J14 -> 84 | L37: ='9B Sem 2'!K14 -> 76 | M37: ='9B Sem 2'!L14 -> 81 | ... U37: ='9B Sem 2'!T14 -> 0
C38: 14 | D38: F | E38: Average | F38: =AVERAGE(F36:F37) -> 90 | G38: =AVERAGE(G36:G37) -> 75 | H38: =AVERAGE(H36:H37) -> 84 | I38: =AVERAGE(I36:I37) -> 77 | J38: =AVERAGE(J36:J37) -> 81.5 | K38: =AVERAGE(K36:K37) -> 89 | L38: =AVERAGE(L36:L37) -> 78 | M38: =AVERAGE(M36:M37) -> 82 | ... R38: =AVERAGE(R36:R37) -> 83.227273 | T38: =AVERAGE(T36:T37) -> 0 | U38: =AVERAGE(U36:U37) -> 0
A39: 12 | C39: 14 | D39: F | E39: Semister 1 | F39: ='9B Sem 1'!E15 -> 83 | G39: ='9B Sem 1'!F15 -> 70 | H39: ='9B Sem 1'!G15 -> 67 | I39: ='9B Sem 1'!H15 -> 68 | J39: ='9B Sem 1'!I15 -> 54 | K39: ='9B Sem 1'!J15 -> 65 | L39: ='9B Sem 1'!K15 -> 65 | M39: ='9B Sem 1'!L15 -> 84 | ... U39: ='9B Sem 1'!T15 -> 0
C40: 14 | D40: F | E40: Semister 2 | F40: ='9B Sem 2'!E15 -> 85 | G40: ='9B Sem 2'!F15 -> 73 | H40: ='9B Sem 2'!G15 -> 80 | I40: ='9B Sem 2'!H15 -> 71 | J40: ='9B Sem 2'!I15 -> 72 | K40: ='9B Sem 2'!J15 -> 79 | L40: ='9B Sem 2'!K15 -> 66 | M40: ='9B Sem 2'!L15 -> 78 | ... U40: ='9B Sem 2'!T15 -> 0
C41: 14 | D41: F | E41: Average | F41: =AVERAGE(F39:F40) -> 84 | G41: =AVERAGE(G39:G40) -> 71.5 | H41: =AVERAGE(H39:H40) -> 73.5 | I41: =AVERAGE(I39:I40) -> 69.5 | J41: =AVERAGE(J39:J40) -> 63 | K41: =AVERAGE(K39:K40) -> 72 | L41: =AVERAGE(L39:L40) -> 65.5 | M41: =AVERAGE(M39:M40) -> 81 | ... R41: =AVERAGE(R39:R40) -> 75.954545 | T41: =AVERAGE(T39:T40) -> 0 | U41: =AVERAGE(U39:U40) -> 0
A42: 13 | C42: 15 | D42: M | E42: Semister 1 | F42: ='9B Sem 1'!E16 -> 84 | G42: ='9B Sem 1'!F16 -> 73 | H42: ='9B Sem 1'!G16 -> 52 | I42: ='9B Sem 1'!H16 -> 63 | J42: ='9B Sem 1'!I16 -> 56 | K42: ='9B Sem 1'!J16 -> 56 | L42: ='9B Sem 1'!K16 -> 57 | M42: ='9B Sem 1'!L16 -> 65 | ... U42: ='9B Sem 1'!T16 -> 0
...

Sheet 9B Sem 1
A1: Maria Rubbato Catholic School 2015 E.C Roster Grade 9B Student's
A2: Home Room Teacher Grade 9B
A3: No | B3: Student Name | C3: Age | D3: Sex | E3: Amharic | F3: English | G3: Maths | H3: physics | I3: chemistry | J3: Biology | K3: Geography | L3: History | M3: Civics | N3: ICT | O3: H.P.E | P3: Total | Q3: Average | R3: Rank | S3: Condc. | T3: Abse.
A4: 1 | C4: 15 | D4: M | E4: 87 | F4: 51 | G4: 69 | H4: 47 | I4: 61 | J4: 55 | K4: 51 | L4: 64 | M4: 67 | N4: 64 | O4: 81 | P4: =SUM(E4:O4) -> 697 | Q4: =AVERAGE(E4:O4) -> 63.363636 | R4: =RANK(Q4,$Q$4:$Q$55) -> 45
A5: 2 | C5: 15 | D5: F | E5: 87 | F5: 66 | G5: 63 | H5: 72 | I5: 58 | J5: 65 | K5: 69 | L5: 81 | M5: 77 | N5: 75 | O5: 88 | P5: =SUM(E5:O5) -> 801 | Q5: =AVERAGE(E5:O5) -> 72.818182 | R5: =RANK(Q5,$Q$4:$Q$55) -> 33
A6: 3 | C6: 14 | D6: M | E6: 88 | F6: 70 | G6: 62 | H6: 57 | I6: 50 | J6: 51 | K6: 59 | L6: 68 | M6: 62 | N6: 85 | O6: 84 | P6: =SUM(E6:O6) -> 736 | Q6: =AVERAGE(E6:O6) -> 66.909091 | R6: =RANK(Q6,$Q$4:$Q$55) -> 42
A7: 4 | C7: 14 | D7: M | E7: 84 | F7: 77 | G7: 91 | H7: 71 | I7: 89 | J7: 86 | K7: 79 | L7: 84 | M7: 83 | N7: 100 | O7: 75 | P7: =SUM(E7:O7) -> 919 | Q7: =AVERAGE(E7:O7) -> 83.545455 | R7: =RANK(Q7,$Q$4:$Q$55) -> 12
A8: 5 | C8: 14 | D8: M | E8: 67 | F8: 54 | G8: 42 | H8: 56 | I8: 57 | J8: 55 | K8: 58 | L8: 62 | M8: 51 | N8: 79 | O8: 74 | P8: =SUM(E8:O8) -> 655 | Q8: =AVERAGE(E8:O8) -> 59.545455 | R8: =RANK(Q8,$Q$4:$Q$55) -> 47
A9: 6 | C9: 15 | D9: M | E9: 73 | F9: 66 | G9: 72 | H9: 64 | I9: 68 | J9: 86 | K9: 78 | L9: 81 | M9: 63 | N9: 99 | O9: 80 | P9: =SUM(E9:O9) -> 830 | Q9: =AVERAGE(E9:O9) -> 75.454545 | R9: =RANK(Q9,$Q$4:$Q$55) -> 28
A10: 7 | C10: 14 | D10: F | E10: 78 | F10: 67 | G10: 73 | H10: 61 | I10: 58 | J10: 69 | K10: 69 | L10: 67 | M10: 74 | N10: 83 | O10: 78 | P10: =SUM(E10:O10) -> 777 | Q10: =AVERAGE(E10:O10) -> 70.636364 | R10: =RANK(Q10,$Q$4:$Q$55) -> 34
A11: 8 | C11: 15 | D11: M | E11: 79 | F11: 62 | G11: 58 | H11: 68 | I11: 60 | J11: 55 | K11: 57 | L11: 68 | M11: 65 | N11: 82 | O11: 86 | P11: =SUM(E11:O11) -> 740 | Q11: =AVERAGE(E11:O11) -> 67.272727 | R11: =RANK(Q11,$Q$4:$Q$55) -> 41
A12: 9 | C12: 15 | D12: M | E12: 83 | F12: 51 | G12: 46 | H12: 51 | I12: 74 | J12: 78 | K12: 77 | L12: 91 | M12: 68 | N12: 77 | O12: 75 | P12: =SUM(E12:O12) -> 771 | Q12: =AVERAGE(E12:O12) -> 70.090909 | R12: =RANK(Q12,$Q$4:$Q$55) -> 37
A13: 10 | C13: 14 | D13: F | E13: 91 | F13: 67 | G13: 82 | H13: 64 | I13: 72 | J13: 68 | K13: 64 | L13: 81 | M13: 78 | N13: 87 | O13: 91 | P13: =SUM(E13:O13) -> 845 | Q13: =AVERAGE(E13:O13) -> 76.818182 | R13: =RANK(Q13,$Q$4:$Q$55) -> 23
A14: 11 | C14: 14 | D14: F | E14: 87 | F14: 74 | G14: 84 | H14: 76 | I14: 81 | J14: 94 | K14: 80 | L14: 83 | M14: 77 | N14: 90 | O14: 84 | P14: =SUM(E14:O14) -> 910 | Q14: =AVERAGE(E14:O14) -> 82.727273 | R14: =RANK(Q14,$Q$4:$Q$55) -> 14
A15: 12 | C15: 14 | D15: F | E15: 83 | F15: 70 | G15: 67 | H15: 68 | I15: 54 | J15: 65 | K15: 65 | L15: 84 | M15: 76 | N15: 87 | O15: 91 | P15: =SUM(E15:O15) -> 810 | Q15: =AVERAGE(E15:O15) -> 73.636364 | R15: =RANK(Q15,$Q$4:$Q$55) -> 32
... A30: 27 | C30: 14 | D30: F | E30: 91 | F30: 72 | G30: 77 | H30: 74 | I30: 70 | J30: 80 | K30: 69 | L30: 81 | M30: 87 | N30: 89 | O30: 92 | P30: =SUM(E30:O30) -> 882 | Q30: =AVERAGE(E30:O30) -> 80.181818 | R30: =RANK(Q30,$Q$4:$Q$55) -> 18
A31: 28 | C31: 14 | D31: F | P31: =SUM(E31:O31) -> 0
A32: 29 | C32: 14 | D32: F | E32: 88 | F32: 93 | G32: 89 | H32: 92 | I32: 92 | J32: 99 | K32: 95 | L32: 99 | M32: 94 | N32: 96 | O32: 100 | P32: =SUM(E32:O32) -> 1037 | Q32: =AVERAGE(E32:O32) -> 94.272727 | R32: =RANK(Q32,$Q$4:$Q$55) -> 3
A33: 30 | C33: 14 | D33: M | E33: 81 | F33: 83 | G33: 71 | H33: 70 | I33: 63 | J33: 87 | K33: 63 | L33: 71 | M33: 78 | N33: 88 | O33: 81 | P33: =SUM(E33:O33) -> 836 | Q33: =AVERAGE(E33:O33) -> 76 | R33: =RANK(Q33,$Q$4:$Q$55) -> 27
A34: 31 | C34: 15 | D34: F | E34: 90 | F34: 52 | G34: 68 | H34: 71 | I34: 77 | J34: 78 | K34: 65 | L34: 89 | M34: 69 | N34: 97 | O34: 88 | P34: =SUM(E34:O34) -> 844 | Q34: =AVERAGE(E34:O34) -> 76.727273 | R34: =RANK(Q34,$Q$4:$Q$55) -> 25
A35: 32 | C35: 15 | D35: F | E35: 88 | F35: 79 | G35: 71 | H35: 65 | I35: 61 | J35: 72 | K35: 73 | L35: 94 | M35: 83 | N35: 84 | O35: 85 | P35: =SUM(E35:O35) -> 855 | Q35: =AVERAGE(E35:O35) -> 77.727273 | R35: =RANK(Q35,$Q$4:$Q$55) -> 21
A36: 33 | C36: 15 | D36: M | E36: 78 | F36: 76 | G36: 64 | H36: 61 | I36: 54 | J36: 69 | K36: 58 | L36: 65 | M36: 62 | N36: 79 | O36: 85 | P36: =SUM(E36:O36) -> 751 | Q36: =AVERAGE(E36:O36) -> 68.272727 | R36: =RANK(Q36,$Q$4:$Q$55) -> 39
A37: 34 | C37: 15 | D37: M | E37: 82 | F37: 66 | G37: 77 | H37: 78 | I37: 81 | J37: 87 | K37: 84 | L37: 83 | M37: 85 | N37: 97 | O37: 100 | P37: =SUM(E37:O37) -> 920 | Q37: =AVERAGE(E37:O37) -> 83.636364 | R37: =RANK(Q37,$Q$4:$Q$55) -> 11
A38: 35 | C38: 14 | D38: M | E38: 78 | F38: 80 | G38: 82 | H38: 83 | I38: 83 | J38: 88 | K38: 83 | L38: 89 | M38: 84 | N38: 91 | O38: 92 | P38: =SUM(E38:O38) -> 933 | Q38: =AVERAGE(E38:O38) -> 84.818182 | R38: =RANK(Q38,$Q$4:$Q$55) -> 10
A39: 36 | C39: 14 | D39: M | E39: 80 | F39: 64 | G39: 82 | H39: 71 | I39: 88 | J39: 78 | K39: 73 | L39: 77 | M39: 68 | N39: 87 | O39: 76 | P39: =SUM(E39:O39) -> 844 | Q39: =AVERAGE(E39:O39) -> 76.727273 | R39: =RANK(Q39,$Q$4:$Q$55) -> 25
A40: 37 | C40: 15 | D40: F | E40: 90 | F40: 82 | G40: 90 | H40: 91 | I40: 87 | J40: 96 | K40: 96 | L40: 100 | M40: 90 | N40: 100 | O40: 100 | P40: =SUM(E40:O40) -> 1022 | Q40: =AVERAGE(E40:O40) -> 92.909091 | R40: =RANK(Q40,$Q$4:$Q$55) -> 4
A41: 38 | C41: 14 | D41: M | E41: 89 | F41: 57 | G41: 85 | H41: 74 | I41: 83 | J41: 81 | K41: 77 | L41: 90 | M41: 79 | N41: 100 | O41: 89 | P41: =SUM(E41:O41) -> 904 | Q41: =AVERAGE(E41:O41) -> 82.181818 | R41: =RANK(Q41,$Q$4:$Q$55) -> 15
A42: 39 | C42: 14 | D42: F | E42: 85 | F42: 82 | G42: 90 | H42: 89 | I42: 87 | J42: 89 | K42: 90 | L42: 89 | M42: 88 | N42: 100 | O42: 100 | P42: =SUM(E42:O42) -> 989 | Q42: =AVERAGE(E42:O42) -> 89.909091 | R42: =RANK(Q42,$Q$4:$Q$55) -> 5
A43: 40 | C43: 15 | D43: F | E43: 77 | F43: 77 | G43: 51 | H43: 49 | I43: 44 | J43: 46 | K43: 47 | L43: 62 | M43: 66 | N43: 71 | O43: 81 | P43: =SUM(E43:O43) -> 671 | Q43: =AVERAGE(E43:O43) -> 61 | R43: =RANK(Q43,$Q$4:$Q$55) -> 46
... A55: 52 | C55: 14 | D55: M | E55: 66 | F55: 72 | G55: 77 | H55: 72 | I55: 74 | J55: 71 | K55: 69 | L55: 75 | M55: 74 | N55: 82 | O55: 80 | P55: =SUM(E55:O55) -> 812 | Q55: =AVERAGE(E55:O55) -> 73.818182 | R55: =RANK(Q55,$Q$4:$Q$55) -> 31
A56: 53
A57: 54
A58: 55

Sheet 9B Sem 2
A1: Maria Rubbato Catholic School 2015 E.C Roster Grade 9B Student's
A2: Home Room Teacher Grade 9B
A3: No | B3: Student Name | C3: Age | D3: Sex | E3: Amharic | F3: English | G3: Maths | H3: physics | I3: chemistry | J3: Biology | K3: Geography | L3: History | M3: Civics | N3: ICT | O3: H.P.E | P3: Total | Q3: Average | R3: Rank | S3: Condc. | T3: Abse.
A4: 1 | C4: 15 | D4: M | E4: 82 | F4: 62 | G4: 73 | H4: 55 | I4: 61 | J4: 58 | K4: 57 | L4: 62 | M4: 69 | N4: 79 | O4: 80 | P4: =SUM(E4:O4) -> 738 | Q4: =AVERAGE(E4:O4) -> 67.090909 | R4: =RANK(Q4,$Q$4:$Q$55) -> 43
A5: 2 | C5: 15 | D5: F | E5: 91 | F5: 68 | G5: 64 | H5: 66 | I5: 59 | J5: 62 | K5: 65 | L5: 73 | M5: 75 | N5: 85 | O5: 89 | P5: =SUM(E5:O5) -> 797 | Q5: =AVERAGE(E5:O5) -> 72.454545 | R5: =RANK(Q5,$Q$4:$Q$55) -> 35
A6: 3 | C6: 14 | D6: M | E6: 92 | F6: 77 | G6: 55 | H6: 55 | I6: 54 | J6: 58 | K6: 59 | L6: 61 | M6: 75 | N6: 88 | O6: 91 | P6: =SUM(E6:O6) -> 765 | Q6: =AVERAGE(E6:O6) -> 69.545455 | R6: =RANK(Q6,$Q$4:$Q$55) -> 42
A7: 4 | C7: 14 | D7: M | E7: 88 | F7: 72 | G7: 86 | H7: 78 | I7: 85 | J7: 91 | K7: 74 | L7: 71 | M7: 78 | N7: 96 | O7: 87 | P7: =SUM(E7:O7) -> 906 | Q7: =AVERAGE(E7:O7) -> 82.363636 | R7: =RANK(Q7,$Q$4:$Q$55) -> 16
A8: 5 | C8: 14 | D8: M | E8: 73 | F8: 55 | G8: 55 | H8: 52 | I8: 53 | J8: 52 | K8: 52 | L8: 60 | M8: 55 | N8: 80 | O8: 93 | P8: =SUM(E8:O8) -> 680 | Q8: =AVERAGE(E8:O8) -> 61.818182 | R8: =RANK(Q8,$Q$4:$Q$55) -> 48
A9: 6 | C9: 15 | D9: M | E9: 77 | F9: 69 | G9: 87 | H9: 58 | I9: 68 | J9: 82 | K9: 72 | L9: 74 | M9: 68 | N9: 95 | O9: 95 | P9: =SUM(E9:O9) -> 845 | Q9: =AVERAGE(E9:O9) -> 76.818182 | R9: =RANK(Q9,$Q$4:$Q$55) -> 29
A10: 7 | C10: 14 | D10: F | E10: 87 | F10: 81 | G10: 59 | H10: 61 | I10: 52 | J10: 70 | K10: 72 | L10: 66 | M10: 76 | N10: 87 | O10: 80 | P10: =SUM(E10:O10) -> 791 | Q10: =AVERAGE(E10:O10) -> 71.909091 | R10: =RANK(Q10,$Q$4:$Q$55) -> 36
A11: 8 | C11: 15 | D11: M | E11: 79 | F11: 64 | G11: 65 | H11: 59 | I11: 56 | J11: 52 | K11: 55 | L11: 50 | M11: 61 | N11: 76 | O11: 94 | P11: =SUM(E11:O11) -> 711 | Q11: =AVERAGE(E11:O11) -> 64.636364 | R11: =RANK(Q11,$Q$4:$Q$55) -> 45
A12: 9 | C12: 15 | D12: M | E12: 87 | F12: 64 | G12: 47 | H12: 57 | I12: 61 | J12: 70 | K12: 80 | L12: 77 | M12: 75 | N12: 75 | O12: 88 | P12: =SUM(E12:O12) -> 781 | Q12: =AVERAGE(E12:O12) -> 71 | R12: =RANK(Q12,$Q$4:$Q$55) -> 37
A13: 10 | C13: 14 | D13: F | E13: 91 | F13: 84 | G13: 78 | H13: 71 | I13: 77 | J13: 82 | K13: 84 | L13: 75 | M13: 89 | N13: 87 | O13: 90 | P13: =SUM(E13:O13) -> 908 | Q13: =AVERAGE(E13:O13) -> 82.545455 | R13: =RANK(Q13,$Q$4:$Q$55) -> 15
A14: 11 | C14: 14 | D14: F | E14: 93 | F14: 76 | G14: 84 | H14: 78 | I14: 82 | J14: 84 | K14: 76 | L14: 81 | M14: 87 | N14: 87 | O14: 93 | P14: =SUM(E14:O14) -> 921 | Q14: =AVERAGE(E14:O14) -> 83.727273 | R14: =RANK(Q14,$Q$4:$Q$55) -> 14
A15: 12 | C15: 14 | D15: F | E15: 85 | F15: 73 | G15: 80 | H15: 71 | I15: 72 | J15: 79 | K15: 66 | L15: 78 | M15: 81 | N15: 83 | O15: 93 | P15: =SUM(E15:O15) -> 861 | Q15: =AVERAGE(E15:O15) -> 78.272727 | R15: =RANK(Q15,$Q$4:$Q$55) -> 26
... A30: 27 | C30: 14 | D30: F | E30: 93 | F30: 70 | G30: 70 | H30: 60 | I30: 69 | J30: 85 | K30: 72 | L30: 80 | M30: 90 | N30: 87 | O30: 97 | P30: =SUM(E30:O30) -> 873 | Q30: =AVERAGE(E30:O30) -> 79.363636 | R30: =RANK(Q30,$Q$4:$Q$55) -> 24
A31: 28 | C31: 14 | D31: F | P31: =SUM(E31:O31) -> 0
A32: 29 | C32: 14 | D32: F | E32: 95 | F32: 89 | G32: 94 | H32: 88 | I32: 88 | J32: 98 | K32: 93 | L32: 95 | M32: 97 | N32: 95 | O32: 98 | P32: =SUM(E32:O32) -> 1030 | Q32: =AVERAGE(E32:O32) -> 93.636364 | R32: =RANK(Q32,$Q$4:$Q$55) -> 3
A33: 30 | C33: 14 | D33: M | E33: 83 | F33: 89 | G33: 72 | H33: 59 | I33: 66 | J33: 77 | K33: 74 | L33: 70 | M33: 82 | N33: 94 | O33: 85 | P33: =SUM(E33:O33) -> 851 | Q33: =AVERAGE(E33:O33) -> 77.363636 | R33: =RANK(Q33,$Q$4:$Q$55) -> 27
A34: 31 | C34: 15 | D34: F | E34: 87 | F34: 58 | G34: 72 | H34: 71 | I34: 69 | J34: 75 | K34: 73 | L34: 86 | M34: 73 | N34: 88 | O34: 93 | P34: =SUM(E34:O34) -> 845 | Q34: =AVERAGE(E34:O34) -> 76.818182 | R34: =RANK(Q34,$Q$4:$Q$55) -> 29
A35: 32 | C35: 15 | D35: F | E35: 85 | F35: 80 | G35: 68 | H35: 51 | I35: 61 | J35: 61 | K35: 87 | L35: 90 | M35: 93 | N35: 95 | O35: 92 | P35: =SUM(E35:O35) -> 863 | Q35: =AVERAGE(E35:O35) -> 78.454545 | R35: =RANK(Q35,$Q$4:$Q$55) -> 25
A36: 33 | C36: 15 | D36: M | E36: 80 | F36: 75 | G36: 64 | H36: 65 | I36: 53 | J36: 73 | K36: 65 | L36: 61 | M36: 80 | N36: 77 | O36: 82 | P36: =SUM(E36:O36) -> 775 | Q36: =AVERAGE(E36:O36) -> 70.454545 | R36: =RANK(Q36,$Q$4:$Q$55) -> 40
A37: 34 | C37: 15 | D37: M | E37: 83 | F37: 83 | G37: 84 | H37: 81 | I37: 85 | J37: 90 | K37: 85 | L37: 78 | M37: 95 | N37: 87 | O37: 96 | P37: =SUM(E37:O37) -> 947 | Q37: =AVERAGE(E37:O37) -> 86.090909 | R37: =RANK(Q37,$Q$4:$Q$55) -> 10
A38: 35 | C38: 14 | D38: M | E38: 76 | F38: 84 | G38: 88 | H38: 83 | I38: 80 | J38: 91 | K38: 83 | L38: 81 | M38: 90 | N38: 85 | O38: 93 | P38: =SUM(E38:O38) -> 934 | Q38: =AVERAGE(E38:O38) -> 84.909091 | R38: =RANK(Q38,$Q$4:$Q$55) -> 11
A39: 36 | C39: 14 | D39: M | E39: 80 | F39: 71 | G39: 92 | H39: 76 | I39: 79 | J39: 95 | K39: 81 | L39: 78 | M39: 75 | N39: 84 | O39: 85 | P39: =SUM(E39:O39) -> 896 | Q39: =AVERAGE(E39:O39) -> 81.454545 | R39: =RANK(Q39,$Q$4:$Q$55) -> 19
A40: 37 | C40: 15 | D40: F | E40: 90 | F40: 86 | G40: 96 | H40: 92 | I40: 83 | J40: 98 | K40: 88 | L40: 89 | M40: 97 | N40: 93 | O40: 98 | P40: =SUM(E40:O40) -> 1010 | Q40: =AVERAGE(E40:O40) -> 91.818182 | R40: =RANK(Q40,$Q$4:$Q$55) -> 6
A41: 38 | C41: 14 | D41: M | E41: 93 | F41: 77 | G41: 83 | H41: 70 | I41: 76 | J41: 75 | K41: 74 | L41: 79 | M41: 81 | N41: 97 | O41: 100 | P41: =SUM(E41:O41) -> 905 | Q41: =AVERAGE(E41:O41) -> 82.272727 | R41: =RANK(Q41,$Q$4:$Q$55) -> 17
A42: 39 | C42: 14 | D42: F | E42: 94 | F42: 82 | G42: 91 | H42: 93 | I42: 87 | J42: 96 | K42: 90 | L42: 97 | M42: 94 | N42: 95 | O42: 98 | P42: =SUM(E42:O42) -> 1017 | Q42: =AVERAGE(E42:O42) -> 92.454545 | R42: =RANK(Q42,$Q$4:$Q$55) -> 5
A43: 40 | C43: 15 | D43: F | E43: 77 | F43: 78 | G43: 50 | H43: 51 | I43: 50 | J43: 47 | K43: 57 | L43: 57 | M43: 80 | N43: 71 | O43: 80 | P43: =SUM(E43:O43) -> 698 | Q43: =AVERAGE(E43:O43) -> 63.454545 | R43: =RANK(Q43,$Q$4:$Q$55) -> 47
... A55: 52 | C55: 14 | D55: M | E55: 74 | F55: 76 | G55: 77 | H55: 66 | I55: 73 | J55: 78 | K55: 58 | L55: 61 | M55: 79 | N55: 84 | O55: 88 | P55: =SUM(E55:O55) -> 814 | Q55: =AVERAGE(E55:O55) -> 74 | R55: =RANK(Q55,$Q$4:$Q$55) -> 33
A56: 53
A57: 54
A58: 55

Sheet 9B Sem avr
A1: Maria Rubbato Catholic School 2015 E.C Roster Grade 9A Student's
A2: Home Room Teacher Grade 9B
A3: No | B3: Student Name | C3: Age | D3: Sex | E3: Semster 1 Average | F3: Semster 2 Average | G3: Average | H3: Rank
A4: 1 | C4: 15 | D4: M | E4: ='9B Sem 1'!Q4 -> 63.363636 | F4: ='9B Sem 2'!Q4 -> 67.090909 | G4: =AVERAGE(E4:F4) -> 65.227273 | H4: =RANK(G4,$G$4:$G$55) -> 45
A5: 2 | C5: 15 | D5: F | E5: ='9B Sem 1'!Q5 -> 72.818182 | F5: ='9B Sem 2'!Q5 -> 72.454545 | G5: =AVERAGE(E5:F5) -> 72.636364 | H5: =RANK(G5,$G$4:$G$55) -> 34
A6: 3 | C6: 14 | D6: M | E6: ='9B Sem 1'!Q6 -> 66.909091 | F6: ='9B Sem 2'!Q6 -> 69.545455 | G6: =AVERAGE(E6:F6) -> 68.227273 | H6: =RANK(G6,$G$4:$G$55) -> 42
A7: 4 | C7: 14 | D7: M | E7: ='9B Sem 1'!Q7 -> 83.545455 | F7: ='9B Sem 2'!Q7 -> 82.363636 | G7: =AVERAGE(E7:F7) -> 82.954545 | H7: =RANK(G7,$G$4:$G$55) -> 14
A8: 5 | C8: 14 | D8: M | E8: ='9B Sem 1'!Q8 -> 59.545455 | F8: ='9B Sem 2'!Q8 -> 61.818182 | G8: =AVERAGE(E8:F8) -> 60.681818 | H8: =RANK(G8,$G$4:$G$55) -> 48
A9: 6 | C9: 15 | D9: M | E9: ='9B Sem 1'!Q9 -> 75.454545 | F9: ='9B Sem 2'!Q9 -> 76.818182 | G9: =AVERAGE(E9:F9) -> 76.136364 | H9: =RANK(G9,$G$4:$G$55) -> 28
A10: 7 | C10: 14 | D10: F | E10: ='9B Sem 1'!Q10 -> 70.636364 | F10: ='9B Sem 2'!Q10 -> 71.909091 | G10: =AVERAGE(E10:F10) -> 71.272727 | H10: =RANK(G10,$G$4:$G$55) -> 35
A11: 8 | C11: 15 | D11: M | E11: ='9B Sem 1'!Q11 -> 67.272727 | F11: ='9B Sem 2'!Q11 -> 64.636364 | G11: =AVERAGE(E11:F11) -> 65.954545 | H11: =RANK(G11,$G$4:$G$55) -> 44
A12: 9 | C12: 15 | D12: M | E12: ='9B Sem 1'!Q12 -> 70.090909 | F12: ='9B Sem 2'!Q12 -> 71 | G12: =AVERAGE(E12:F12) -> 70.545455 | H12: =RANK(G12,$G$4:$G$55) -> 37
A13: 10 | C13: 14 | D13: F | E13: ='9B Sem 1'!Q13 -> 76.818182 | F13: ='9B Sem 2'!Q13 -> 82.545455 | G13: =AVERAGE(E13:F13) -> 79.681818 | H13: =RANK(G13,$G$4:$G$55) -> 20
A14: 11 | C14: 14 | D14: F | E14: ='9B Sem 1'!Q14 -> 82.727273 | F14: ='9B Sem 2'!Q14 -> 83.727273 | G14: =AVERAGE(E14:F14) -> 83.227273 | H14: =RANK(G14,$G$4:$G$55) -> 13
A15: 12 | C15: 14 | D15: F | E15: ='9B Sem 1'!Q15 -> 73.636364 | F15: ='9B Sem 2'!Q15 -> 78.272727 | G15: =AVERAGE(E15:F15) -> 75.954545 | H15: =RANK(G15,$G$4:$G$55) -> 29
... A55: 52 | C55: 14 | D55: M | E55: ='9B Sem 1'!Q55 -> 73.818182 | F55: ='9B Sem 2'!Q55 -> 74 | G55: =AVERAGE(E55:F55) -> 73.909091 | H55: =RANK(G55,$G$4:$G$55) -> 33

Sheet Roster 10A
A1: Maria Rubbato Catholic School 2015 E.C Roster Grade 10A Student's
A3: Home Room Teacher Grade 10A
A5: No | B5: Student Name | C5: Age | D5: Sex | E5: Semester | F5: Amharic | G5: English | H5: Maths | I5: physics | J5: chemistry | K5: Biology | L5: Geography | M5: History | N5: Civics | O5: ICT | P5: H.P.E | Q5: Total | R5: Average | S5: Rank | T5: Condc. | U5: Abse.
A6: 1 | C6: 15 | D6: M | E6: Semister 1 | F6: ='10A Sem 1'!E4 -> 74 | G6: ='10A Sem 1'!F4 -> 50 | H6: ='10A Sem 1'!G4 -> 51 | I6: ='10A Sem 1'!H4 -> 58 | J6: ='10A Sem 1'!I4 -> 44 | K6: ='10A Sem 1'!J4 -> 45 | L6: ='10A Sem 1'!K4 -> 53 | M6: ='10A Sem 1'!L4 -> 58 | ... U6: ='10A Sem 1'!T4 -> 0
C7: 15 | D7: M | E7: Semister 2 | F7: ='10A Sem 2'!E4 -> 77 | G7: ='10A Sem 2'!F4 -> 56 | H7: ='10A Sem 2'!G4 -> 44 | I7: ='10A Sem 2'!H4 -> 50 | J7: ='10A Sem 2'!I4 -> 48 | K7: ='10A Sem 2'!J4 -> 51 | L7: ='10A Sem 2'!K4 -> 56 | M7: ='10A Sem 2'!L4 -> 55 | ... U7: ='10A Sem 2'!T4 -> 0
