Workbook

Sheet Roster 9A
A1: Maria Rubbato Catholic School 2016 E.C Roster Grade 9A Student's
A3: Home Room Teacher Grade 9A
A5: No | B5: Student Name | C5: Age | D5: Sex | E5: Semester | F5: Amharic | G5: English | H5: Maths | I5: physics | J5: chemistry | K5: Biology | L5: History | M5: Geography | N5: Citizenship | O5: ICT | P5: Economics | Q5: H.P.E | R5: Afan Oromo | S5: Total | T5: Average | U5: Rank | V5: Condc. | W5: Abse.
A6: 1 | C6: 15 | D6: M | E6: Semister 1 | F6: ='9A Sem 1'!E4 -> 77 | G6: ='9A Sem 1'!F4 -> 68 | H6: ='9A Sem 1'!G4 -> 74 | I6: ='9A Sem 1'!H4 -> 62 | J6: ='9A Sem 1'!I4 -> 75 | K6: ='9A Sem 1'!J4 -> 74 | L6: ='9A Sem 1'!K4 -> 84 | M6: ='9A Sem 1'!L4 -> 62 | ... W6: ='9A Sem 1'!V4 -> 0
C7: 15 | D7: M | E7: Semister 2 | F7: ='9A Sem 2'!E4 -> 82 | G7: ='9A Sem 2'!F4 -> 53 | H7: ='9A Sem 2'!G4 -> 71 | I7: ='9A Sem 2'!H4 -> 62 | J7: ='9A Sem 2'!I4 -> 60 | K7: ='9A Sem 2'!J4 -> 76 | L7: ='9A Sem 2'!K4 -> 67 | M7: ='9A Sem 2'!L4 -> 73 | ... W7: ='9A Sem 2'!V4 -> 0
C8: 15 | D8: M | E8: Average | F8: =AVERAGE(F6:F7) -> 79.5 | G8: =AVERAGE(G6:G7) -> 60.5 | H8: =AVERAGE(H6:H7) -> 72.5 | I8: =AVERAGE(I6:I7) -> 62 | J8: =AVERAGE(J6:J7) -> 67.5 | K8: =AVERAGE(K6:K7) -> 75 | L8: =AVERAGE(L6:L7) -> 75.5 | M8: =AVERAGE(M6:M7) -> 67.5 | ... T8: =AVERAGE(T6:T7) -> 74.192308 | U8: ='9A Sem avr'!$H$4 -> 32 | V8: =AVERAGE(V6:V7) -> 0 | W8: =AVERAGE(W6:W7) -> 0
A9: 2 | C9: 14 | D9: F | E9: Semister 1 | F9: ='9A Sem 1'!E5 -> 80 | G9: ='9A Sem 1'!F5 -> 83 | H9: ='9A Sem 1'!G5 -> 81 | I9: ='9A Sem 1'!H5 -> 67 | J9: ='9A Sem 1'!I5 -> 71 | K9: ='9A Sem 1'!J5 -> 70 | L9: ='9A Sem 1'!K5 -> 83 | M9: ='9A Sem 1'!L5 -> 65 | ... W9: ='9A Sem 1'!V5 -> 0
C10: 14 | D10: F | E10: Semister 2 | F10: ='9A Sem 2'!E5 -> 83 | G10: ='9A Sem 2'!F5 -> 79 | H10: ='9A Sem 2'!G5 -> 84 | I10: ='9A Sem 2'!H5 -> 70 | J10: ='9A Sem 2'!I5 -> 75 | K10: ='9A Sem 2'!J5 -> 87 | L10: ='9A Sem 2'!K5 -> 81 | M10: ='9A Sem 2'!L5 -> 89 | ... W10: ='9A Sem 2'!V5 -> 0
C11: 14 | D11: F | E11: Average | F11: =AVERAGE(F9:F10) -> 81.5 | G11: =AVERAGE(G9:G10) -> 81 | H11: =AVERAGE(H9:H10) -> 82.5 | I11: =AVERAGE(I9:I10) -> 68.5 | J11: =AVERAGE(J9:J10) -> 73 | K11: =AVERAGE(K9:K10) -> 78.5 | L11: =AVERAGE(L9:L10) -> 82 | M11: =AVERAGE(M9:M10) -> 77 | ... T11: =AVERAGE(T9:T10) -> 80.038462 | U11: ='9A Sem avr'!$H$5 -> 18 | V11: =AVERAGE(V9:V10) -> 0 | W11: =AVERAGE(W9:W10) -> 0
A12: 3 | C12: 15 | D12: M | E12: Semister 1 | F12: ='9A Sem 1'!E6 -> 89 | G12: ='9A Sem 1'!F6 -> 83 | H12: ='9A Sem 1'!G6 -> 80 | I12: ='9A Sem 1'!H6 -> 70 | J12: ='9A Sem 1'!I6 -> 71 | K12: ='9A Sem 1'!J6 -> 70 | L12: ='9A Sem 1'!K6 -> 77 | M12: ='9A Sem 1'!L6 -> 66 | ... W12: ='9A Sem 1'!V6 -> 0
C13: 15 | D13: M | E13: Semister 2 | F13: ='9A Sem 2'!E6 -> 85 | G13: ='9A Sem 2'!F6 -> 80 | H13: ='9A Sem 2'!G6 -> 72 | I13: ='9A Sem 2'!H6 -> 63 | J13: ='9A Sem 2'!I6 -> 72 | K13: ='9A Sem 2'!J6 -> 81 | L13: ='9A Sem 2'!K6 -> 72 | M13: ='9A Sem 2'!L6 -> 87 | ... W13: ='9A Sem 2'!V6 -> 0
C14: 15 | D14: M | E14: Average | F14: =AVERAGE(F12:F13) -> 87 | G14: =AVERAGE(G12:G13) -> 81.5 | H14: =AVERAGE(H12:H13) -> 76 | I14: =AVERAGE(I12:I13) -> 66.5 | J14: =AVERAGE(J12:J13) -> 71.5 | K14: =AVERAGE(K12:K13) -> 75.5 | L14: =AVERAGE(L12:L13) -> 74.5 | M14: =AVERAGE(M12:M13) -> 76.5 | ... T14: =AVERAGE(T12:T13) -> 79.230769 | U14: ='9A Sem avr'!$H$6 -> 19 | V14: =AVERAGE(V12:V13) -> 0 | W14: =AVERAGE(W12:W13) -> 0
A15: 4 | C15: 15 | D15: M | E15: Semister 1 | F15: ='9A Sem 1'!E7 -> 78 | G15: ='9A Sem 1'!F7 -> 72 | H15: ='9A Sem 1'!G7 -> 51 | I15: ='9A Sem 1'!H7 -> 50 | J15: ='9A Sem 1'!I7 -> 73 | K15: ='9A Sem 1'!J7 -> 53 | L15: ='9A Sem 1'!K7 -> 68 | M15: ='9A Sem 1'!L7 -> 64 | ... W15: ='9A Sem 1'!V7 -> 0
C16: 15 | D16: M | E16: Semister 2 | F16: ='9A Sem 2'!E7 -> 81 | G16: ='9A Sem 2'!F7 -> 70 | H16: ='9A Sem 2'!G7 -> 50 | I16: ='9A Sem 2'!H7 -> 42 | J16: ='9A Sem 2'!I7 -> 47 | K16: ='9A Sem 2'!J7 -> 68 | L16: ='9A Sem 2'!K7 -> 62 | M16: ='9A Sem 2'!L7 -> 73 | ... W16: ='9A Sem 2'!V7 -> 0
C17: 15 | D17: M | E17: Average | F17: =AVERAGE(F15:F16) -> 79.5 | G17: =AVERAGE(G15:G16) -> 71 | H17: =AVERAGE(H15:H16) -> 50.5 | I17: =AVERAGE(I15:I16) -> 46 | J17: =AVERAGE(J15:J16) -> 60 | K17: =AVERAGE(K15:K16) -> 60.5 | L17: =AVERAGE(L15:L16) -> 65 | M17: =AVERAGE(M15:M16) -> 68.5 | ... T17: =AVERAGE(T15:T16) -> 66.961538 | U17: ='9A Sem avr'!$H$7 -> 44 | V17: =AVERAGE(V15:V16) -> 0 | W17: =AVERAGE(W15:W16) -> 0
A18: 5 | C18: 15 | D18: F | E18: Semister 1 | F18: ='9A Sem 1'!E8 -> 72 | G18: ='9A Sem 1'!F8 -> 89 | H18: ='9A Sem 1'!G8 -> 65 | I18: ='9A Sem 1'!H8 -> 69 | J18: ='9A Sem 1'!I8 -> 73 | K18: ='9A Sem 1'!J8 -> 67 | L18: ='9A Sem 1'!K8 -> 80 | M18: ='9A Sem 1'!L8 -> 65 | ... W18: ='9A Sem 1'!V8 -> 0
C19: 15 | D19: F | E19: Semister 2 | F19: ='9A Sem 2'!E8 -> 79 | G19: ='9A Sem 2'!F8 -> 75 | H19: ='9A Sem 2'!G8 -> 77 | I19: ='9A Sem 2'!H8 -> 72 | J19: ='9A Sem 2'!I8 -> 78 | K19: ='9A Sem 2'!J8 -> 82 | L19: ='9A Sem 2'!K8 -> 71 | M19: ='9A Sem 2'!L8 -> 83 | ... W19: ='9A Sem 2'!V8 -> 0
C20: 15 | D20: F | E20: Average | F20: =AVERAGE(F18:F19) -> 75.5 | G20: =AVERAGE(G18:G19) -> 82 | H20: =AVERAGE(H18:H19) -> 71 | I20: =AVERAGE(I18:I19) -> 70.5 | J20: =AVERAGE(J18:J19) -> 75.5 | K20: =AVERAGE(K18:K19) -> 74.5 | L20: =AVERAGE(L18:L19) -> 75.5 | M20: =AVERAGE(M18:M19) -> 74 | ... T20: =AVERAGE(T18:T19) -> 77.384615 | U20: ='9A Sem avr'!$H$8 -> 22 | V20: =AVERAGE(V18:V19) -> 0 | W20: =AVERAGE(W18:W19) -> 0
A21: 6 | C21: 14 | D21: F | E21: Semister 1 | F21: ='9A Sem 1'!E9 -> 78 | G21: ='9A Sem 1'!F9 -> 71 | H21: ='9A Sem 1'!G9 -> 75 | I21: ='9A Sem 1'!H9 -> 77 | J21: ='9A Sem 1'!I9 -> 81 | K21: ='9A Sem 1'!J9 -> 75 | L21: ='9A Sem 1'!K9 -> 82 | M21: ='9A Sem 1'!L9 -> 79 | ... W21: ='9A Sem 1'!V9 -> 0
C22: 14 | D22: F | E22: Semister 2 | F22: ='9A Sem 2'!E9 -> 86 | G22: ='9A Sem 2'!F9 -> 65 | H22: ='9A Sem 2'!G9 -> 84 | I22: ='9A Sem 2'!H9 -> 76 | J22: ='9A Sem 2'!I9 -> 72 | K22: ='9A Sem 2'!J9 -> 83 | L22: ='9A Sem 2'!K9 -> 87 | M22: ='9A Sem 2'!L9 -> 81 | ... W22: ='9A Sem 2'!V9 -> 0
C23: 14 | D23: F | E23: Average | F23: =AVERAGE(F21:F22) -> 82 | G23: =AVERAGE(G21:G22) -> 68 | H23: =AVERAGE(H21:H22) -> 79.5 | I23: =AVERAGE(I21:I22) -> 76.5 | J23: =AVERAGE(J21:J22) -> 76.5 | K23: =AVERAGE(K21:K22) -> 79 | L23: =AVERAGE(L21:L22) -> 84.5 | M23: =AVERAGE(M21:M22) -> 80 | ... T23: =AVERAGE(T21:T22) -> 81.346154 | U23: ='9A Sem avr'!$H$9 -> 15 | V23: =AVERAGE(V21:V22) -> 0 | W23: =AVERAGE(W21:W22) -> 0
A24: 7 | C24: 14 | D24: F | E24: Semister 1 | F24: ='9A Sem 1'!E10 -> 65 | G24: ='9A Sem 1'!F10 -> 50 | H24: ='9A Sem 1'!G10 -> 56 | I24: ='9A Sem 1'!H10 -> 43 | J24: ='9A Sem 1'!I10 -> 48 | K24: ='9A Sem 1'!J10 -> 35 | L24: ='9A Sem 1'!K10 -> 66 | M24: ='9A Sem 1'!L10 -> 48 | ... W24: ='9A Sem 1'!V10 -> 0
C25: 14 | D25: F | E25: Semister 2 | F25: ='9A Sem 2'!E10 -> 65 | G25: ='9A Sem 2'!F10 -> 51 | H25: ='9A Sem 2'!G10 -> 51 | I25: ='9A Sem 2'!H10 -> 52 | J25: ='9A Sem 2'!I10 -> 62 | K25: ='9A Sem 2'!J10 -> 52 | L25: ='9A Sem 2'!K10 -> 40 | M25: ='9A Sem 2'!L10 -> 69 | ... W25: ='9A Sem 2'!V10 -> 0
C26: 14 | D26: F | E26: Average | F26: =AVERAGE(F24:F25) -> 65 | G26: =AVERAGE(G24:G25) -> 50.5 | H26: =AVERAGE(H24:H25) -> 53.5 | I26: =AVERAGE(I24:I25) -> 47.5 | J26: =AVERAGE(J24:J25) -> 55 | K26: =AVERAGE(K24:K25) -> 43.5 | L26: =AVERAGE(L24:L25) -> 53 | M26: =AVERAGE(M24:M25) -> 58.5 | ... T26: =AVERAGE(T24:T25) -> 57.615385 | U26: ='9A Sem avr'!$H$10 -> 52 | V26: =AVERAGE(V24:V25) -> 0 | W26: =AVERAGE(W24:W25) -> 0
A27: 8 | C27: 15 | D27: F | E27: Semister 1 | F27: ='9A Sem 1'!E11 -> 88 | G27: ='9A Sem 1'!F11 -> 86 | H27: ='9A Sem 1'!G11 -> 75 | I27: ='9A Sem 1'!H11 -> 70 | J27: ='9A Sem 1'!I11 -> 80 | K27: ='9A Sem 1'!J11 -> 78 | L27: ='9A Sem 1'!K11 -> 78 | M27: ='9A Sem 1'!L11 -> 70 | ... W27: ='9A Sem 1'!V11 -> 0
C28: 15 | D28: F | E28: Semister 2 | F28: ='9A Sem 2'!E11 -> 89 | G28: ='9A Sem 2'!F11 -> 88 | H28: ='9A Sem 2'!G11 -> 86 | I28: ='9A Sem 2'!H11 -> 68 | J28: ='9A Sem 2'!I11 -> 71 | K28: ='9A Sem 2'!J11 -> 84 | L28: ='9A Sem 2'!K11 -> 73 | M28: ='9A Sem 2'!L11 -> 88 | ... W28: ='9A Sem 2'!V11 -> 0
C29: 15 | D29: F | E29: Average | F29: =AVERAGE(F27:F28) -> 88.5 | G29: =AVERAGE(G27:G28) -> 87 | H29: =AVERAGE(H27:H28) -> 80.5 | I29: =AVERAGE(I27:I28) -> 69 | J29: =AVERAGE(J27:J28) -> 75.5 | K29: =AVERAGE(K27:K28) -> 81 | L29: =AVERAGE(L27:L28) -> 75.5 | M29: =AVERAGE(M27:M28) -> 79 | ... T29: =AVERAGE(T27:T28) -> 80.538462 | U29: ='9A Sem avr'!$H$11 -> 16 | V29: =AVERAGE(V27:V28) -> 0 | W29: =AVERAGE(W27:W28) -> 0
A30: 9 | C30: 15 | D30: M | E30: Semister 1 | F30: ='9A Sem 1'!E12 -> 76 | G30: ='9A Sem 1'!F12 -> 73 | H30: ='9A Sem 1'!G12 -> 59 | I30: ='9A Sem 1'!H12 -> 50 | J30: ='9A Sem 1'!I12 -> 63 | K30: ='9A Sem 1'!J12 -> 50 | L30: ='9A Sem 1'!K12 -> 43 | M30: ='9A Sem 1'!L12 -> 49 | ... W30: ='9A Sem 1'!V12 -> 0
C31: 15 | D31: M | E31: Semister 2 | F31: ='9A Sem 2'!E12 -> 73 | G31: ='9A Sem 2'!F12 -> 64 | H31: ='9A Sem 2'!G12 -> 45 | I31: ='9A Sem 2'!H12 -> 47 | J31: ='9A Sem 2'!I12 -> 57 | K31: ='9A Sem 2'!J12 -> 52 | L31: ='9A Sem 2'!K12 -> 43 | M31: ='9A Sem 2'!L12 -> 64 | ... W31: ='9A Sem 2'!V12 -> 0
C32: 15 | D32: M | E32: Average | F32: =AVERAGE(F30:F31) -> 74.5 | G32: =AVERAGE(G30:G31) -> 68.5 | H32: =AVERAGE(H30:H31) -> 52 | I32: =AVERAGE(I30:I31) -> 48.5 | J32: =AVERAGE(J30:J31) -> 60 | K32: =AVERAGE(K30:K31) -> 51 | L32: =AVERAGE(L30:L31) -> 43 | M32: =AVERAGE(M30:M31) -> 56.5 | ... T32: =AVERAGE(T30:T31) -> 62.384615 | U32: ='9A Sem avr'!$H$12 -> 49 | V32: =AVERAGE(V30:V31) -> 0 | W32: =AVERAGE(W30:W31) -> 0
A33: 10 | C33: 15 | D33: F | E33: Semister 1 | F33: ='9A Sem 1'!E13 -> 89 | G33: ='9A Sem 1'!F13 -> 66 | H33: ='9A Sem 1'!G13 -> 81 | I33: ='9A Sem 1'!H13 -> 56 | J33: ='9A Sem 1'!I13 -> 66 | K33: ='9A Sem 1'!J13 -> 50 | L33: ='9A Sem 1'!K13 -> 77 | M33: ='9A Sem 1'!L13 -> 61 | ... W33: ='9A Sem 1'!V13 -> 0
C34: 15 | D34: F | E34: Semister 2 | F34: ='9A Sem 2'!E13 -> 89 | G34: ='9A Sem 2'!F13 -> 69 | H34: ='9A Sem 2'!G13 -> 93 | I34: ='9A Sem 2'!H13 -> 63 | J34: ='9A Sem 2'!I13 -> 74 | K34: ='9A Sem 2'!J13 -> 58 | L34: ='9A Sem 2'!K13 -> 78 | M34: ='9A Sem 2'!L13 -> 73 | ... W34: ='9A Sem 2'!V13 -> 0
C35: 15 | D35: F | E35: Average | F35: =AVERAGE(F33:F34) -> 89 | G35: =AVERAGE(G33:G34) -> 67.5 | H35: =AVERAGE(H33:H34) -> 87 | I35: =AVERAGE(I33:I34) -> 59.5 | J35: =AVERAGE(J33:J34) -> 70 | K35: =AVERAGE(K33:K34) -> 54 | L35: =AVERAGE(L33:L34) -> 77.5 | M35: =AVERAGE(M33:M34) -> 67 | ... T35: =AVERAGE(T33:T34) -> 74.615385 | U35: ='9A Sem avr'!$H$13 -> 30 | V35: =AVERAGE(V33:V34) -> 0 | W35: =AVERAGE(W33:W34) -> 0
A36: 11 | C36: 15 | D36: M | E36: Semister 1 | F36: ='9A Sem 1'!E14 -> 78 | G36: ='9A Sem 1'!F14 -> 60 | H36: ='9A Sem 1'!G14 -> 65 | I36: ='9A Sem 1'!H14 -> 66 | J36: ='9A Sem 1'!I14 -> 56 | K36: ='9A Sem 1'!J14 -> 55 | L36: ='9A Sem 1'!K14 -> 77 | M36: ='9A Sem 1'!L14 -> 68 | ... W36: ='9A Sem 1'!V14 -> 0
C37: 15 | D37: M | E37: Semister 2 | F37: ='9A Sem 2'!E14 -> 84 | G37: ='9A Sem 2'!F14 -> 54 | H37: ='9A Sem 2'!G14 -> 69 | I37: ='9A Sem 2'!H14 -> 62 | J37: ='9A Sem 2'!I14 -> 71 | K37: ='9A Sem 2'!J14 -> 57 | L37: ='9A Sem 2'!K14 -> 71 | M37: ='9A Sem 2'!L14 -> 76 | ... W37: ='9A Sem 2'!V14 -> 0
C38: 15 | D38: M | E38: Average | F38: =AVERAGE(F36:F37) -> 81 | G38: =AVERAGE(G36:G37) -> 57 | H38: =AVERAGE(H36:H37) -> 67 | I38: =AVERAGE(I36:I37) -> 64 | J38: =AVERAGE(J36:J37) -> 63.5 | K38: =AVERAGE(K36:K37) -> 56 | L38: =AVERAGE(L36:L37) -> 74 | M38: =AVERAGE(M36:M37) -> 72 | ... T38: =AVERAGE(T36:T37) -> 70.923077 | U38: ='9A Sem avr'!$H$14 -> 40 | V38: =AVERAGE(V36:V37) -> 0 | W38: =AVERAGE(W36:W37) -> 0
A39: 12 | C39: 15 | D39: M | E39: Semister 1 | F39: ='9A Sem 1'!E15 -> 76 | G39: ='9A Sem 1'!F15 -> 61 | H39: ='9A Sem 1'!G15 -> 59 | I39: ='9A Sem 1'!H15 -> 50 | J39: ='9A Sem 1'!I15 -> 49 | K39: ='9A Sem 1'!J15 -> 40 | L39: ='9A Sem 1'!K15 -> 56 | M39: ='9A Sem 1'!L15 -> 43 | ... W39: ='9A Sem 1'!V15 -> 0
C40: 15 | D40: M | E40: Semister 2 | F40: ='9A Sem 2'!E15 -> 72 | G40: ='9A Sem 2'!F15 -> 55 | H40: ='9A Sem 2'!G15 -> 47 | I40: ='9A Sem 2'!H15 -> 37 | J40: ='9A Sem 2'!I15 -> 51 | K40: ='9A Sem 2'!J15 -> 62 | L40: ='9A Sem 2'!K15 -> 52 | M40: ='9A Sem 2'!L15 -> 70 | ... W40: ='9A Sem 2'!V15 -> 0
C41: 15 | D41: M | E41: Average | F41: =AVERAGE(F39:F40) -> 74 | G41: =AVERAGE(G39:G40) -> 58 | H41: =AVERAGE(H39:H40) -> 53 | I41: =AVERAGE(I39:I40) -> 43.5 | J41: =AVERAGE(J39:J40) -> 50 | K41: =AVERAGE(K39:K40) -> 51 | L41: =AVERAGE(L39:L40) -> 54 | M41: =AVERAGE(M39:M40) -> 56.5 | ... T41: =AVERAGE(T39:T40) -> 62.384615 | U41: ='9A Sem avr'!$H$15 -> 49 | V41: =AVERAGE(V39:V40) -> 0 | W41: =AVERAGE(W39:W40) -> 0
A42: 13 | C42: 14 | D42: F | E42: Semister 1 | F42: ='9A Sem 1'!E16 -> 81 | G42: ='9A Sem 1'!F16 -> 67 | H42: ='9A Sem 1'!G16 -> 65 | I42: ='9A Sem 1'!H16 -> 70 | J42: ='9A Sem 1'!I16 -> 71 | K42: ='9A Sem 1'!J16 -> 69 | L42: ='9A Sem 1'!K16 -> 84 | M42: ='9A Sem 1'!L16 -> 73 | ... W42: ='9A Sem 1'!V16 -> 0
...

Sheet 9A Sem 1
A1: Maria Rubbato Catholic School 2016 E.C Roster Grade 9A Student's
A2: Home Room Teacher Grade 9A
A3: No | B3: Student Name | C3: Age | D3: Sex | E3: Amharic | F3: English | G3: Maths | H3: physics | I3: chemistry | J3: Biology | K3: History | L3: Geography | M3: Citizenship | N3: ICT | O3: Economics | P3: H.P.E | Q3: Afan Oromo | R3: Total | S3: Average | T3: Rank | U3: Condc. | V3: Abse.
A4: 1 | C4: 15 | D4: M | E4: 77 | F4: 68 | G4: 74 | H4: 62 | I4: 75 | J4: 74 | K4: 84 | L4: 62 | M4: 78 | N4: 92 | O4: 74 | P4: 94 | Q4: 91 | R4: =SUM(E4:Q4) -> 1005 | S4: =AVERAGE(E4:Q4) -> 77.307692 | T4: =RANK(S4,$S$4:$S$58) -> 21
A5: 2 | C5: 14 | D5: F | E5: 80 | F5: 83 | G5: 81 | H5: 67 | I5: 71 | J5: 70 | K5: 83 | L5: 65 | M5: 85 | N5: 84 | O5: 80 | P5: 91 | Q5: 68 | R5: =SUM(E5:Q5) -> 1008 | S5: =AVERAGE(E5:Q5) -> 77.538462 | T5: =RANK(S5,$S$4:$S$58) -> 19
A6: 3 | C6: 15 | D6: M | E6: 89 | F6: 83 | G6: 80 | H6: 70 | I6: 71 | J6: 70 | K6: 77 | L6: 66 | M6: 91 | N6: 84 | O6: 80 | P6: 86 | Q6: 89 | R6: =SUM(E6:Q6) -> 1036 | S6: =AVERAGE(E6:Q6) -> 79.692308 | T6: =RANK(S6,$S$4:$S$58) -> 17
A7: 4 | C7: 15 | D7: M | E7: 78 | F7: 72 | G7: 51 | H7: 50 | I7: 73 | J7: 53 | K7: 68 | L7: 64 | M7: 76 | N7: 75 | O7: 63 | P7: 92 | Q7: 65 | R7: =SUM(E7:Q7) -> 880 | S7: =AVERAGE(E7:Q7) -> 67.692308 | T7: =RANK(S7,$S$4:$S$58) -> 44
A8: 5 | C8: 15 | D8: F | E8: 72 | F8: 89 | G8: 65 | H8: 69 | I8: 73 | J8: 67 | K8: 80 | L8: 65 | M8: 87 | N8: 79 | O8: 80 | P8: 98 | Q8: 71 | R8: =SUM(E8:Q8) -> 995 | S8: =AVERAGE(E8:Q8) -> 76.538462 | T8: =RANK(S8,$S$4:$S$58) -> 23
A9: 6 | C9: 14 | D9: F | E9: 78 | F9: 71 | G9: 75 | H9: 77 | I9: 81 | J9: 75 | K9: 82 | L9: 79 | M9: 80 | N9: 81 | O9: 82 | P9: 89 | Q9: 95 | R9: =SUM(E9:Q9) -> 1045 | S9: =AVERAGE(E9:Q9) -> 80.384615 | T9: =RANK(S9,$S$4:$S$58) -> 15
A10: 7 | C10: 14 | D10: F | E10: 65 | F10: 50 | G10: 56 | H10: 43 | I10: 48 | J10: 35 | K10: 66 | L10: 48 | M10: 57 | N10: 52 | O10: 56 | P10: 70 | Q10: 82 | R10: =SUM(E10:Q10) -> 728 | S10: =AVERAGE(E10:Q10) -> 56 | T10: =RANK(S10,$S$4:$S$58) -> 54
A11: 8 | C11: 15 | D11: F | E11: 88 | F11: 86 | G11: 75 | H11: 70 | I11: 80 | J11: 78 | K11: 78 | L11: 70 | M11: 87 | N11: 81 | O11: 82 | P11: 90 | Q11: 81 | R11: =SUM(E11:Q11) -> 1046 | S11: =AVERAGE(E11:Q11) -> 80.461538 | T11: =RANK(S11,$S$4:$S$58) -> 14
A12: 9 | C12: 15 | D12: M | E12: 76 | F12: 73 | G12: 59 | H12: 50 | I12: 63 | J12: 50 | K12: 43 | L12: 49 | M12: 74 | N12: 81 | O12: 67 | P12: 74 | Q12: 65 | R12: =SUM(E12:Q12) -> 824 | S12: =AVERAGE(E12:Q12) -> 63.384615 | T12: =RANK(S12,$S$4:$S$58) -> 47
A13: 10 | C13: 15 | D13: F | E13: 89 | F13: 66 | G13: 81 | H13: 56 | I13: 66 | J13: 50 | K13: 77 | L13: 61 | M13: 74 | N13: 76 | O13: 64 | P13: 82 | Q13: 93 | R13: =SUM(E13:Q13) -> 935 | S13: =AVERAGE(E13:Q13) -> 71.923077 | T13: =RANK(S13,$S$4:$S$58) -> 37
A14: 11 | C14: 15 | D14: M | E14: 78 | F14: 60 | G14: 65 | H14: 66 | I14: 56 | J14: 55 | K14: 77 | L14: 68 | M14: 71 | N14: 79 | O14: 72 | P14: 87 | Q14: 85 | R14: =SUM(E14:Q14) -> 919 | S14: =AVERAGE(E14:Q14) -> 70.692308 | T14: =RANK(S14,$S$4:$S$58) -> 41
A15: 12 | C15: 15 | D15: M | E15: 76 | F15: 61 | G15: 59 | H15: 50 | I15: 49 | J15: 40 | K15: 56 | L15: 43 | M15: 76 | N15: 82 | O15: 72 | P15: 79 | Q15: 67 | R15: =SUM(E15:Q15) -> 810 | S15: =AVERAGE(E15:Q15) -> 62.307692 | T15: =RANK(S15,$S$4:$S$58) -> 48
... A58: 55 | C58: 15 | D58: F | E58: 90 | F58: 93 | G58: 95 | H58: 97 | I58: 97 | J58: 97 | K58: 92 | L58: 95 | M58: 99 | N58: 88 | O58: 95 | P58: 98 | Q58: 93 | R58: =SUM(E58:Q58) -> 1229 | S58: =AVERAGE(E58:Q58) -> 94.538462 | T58: =RANK(S58,$S$4:$S$58) -> 1

Sheet 9A Sem 2
A1: Maria Rubbato Catholic School 2016 E.C Roster Grade 9A Student's
A2: Home Room Teacher Grade 9A
A3: No | B3: Student Name | C3: Age | D3: Sex | E3: Amharic | F3: English | G3: Maths | H3: physics | I3: chemistry | J3: Biology | K3: History | L3: Geography | M3: Citizenship | N3: ICT | O3: Economics | P3: H.P.E | Q3: Afan Oromo | R3: Total | S3: Average | T3: Rank | U3: Condc. | V3: Abse.
A4: 1 | C4: 15 | D4: M | E4: 82 | F4: 53 | G4: 71 | H4: 62 | I4: 60 | J4: 76 | K4: 67 | L4: 73 | M4: 71 | N4: 82 | O4: 80 | P4: 87 | Q4: 60 | R4: =SUM(E4:Q4) -> 924 | S4: =AVERAGE(E4:Q4) -> 71.076923 | T4: =RANK(S4,$S$4:$S$58) -> 40
A5: 2 | C5: 14 | D5: F | E5: 83 | F5: 79 | G5: 84 | H5: 70 | I5: 75 | J5: 87 | K5: 81 | L5: 89 | M5: 86 | N5: 94 | O5: 91 | P5: 90 | Q5: 64 | R5: =SUM(E5:Q5) -> 1073 | S5: =AVERAGE(E5:Q5) -> 82.538462 | T5: =RANK(S5,$S$4:$S$58) -> 11
A6: 3 | C6: 15 | D6: M | E6: 85 | F6: 80 | G6: 72 | H6: 63 | I6: 72 | J6: 81 | K6: 72 | L6: 87 | M6: 84 | N6: 92 | O6: 77 | P6: 91 | Q6: 68 | R6: =SUM(E6:Q6) -> 1024 | S6: =AVERAGE(E6:Q6) -> 78.769231 | T6: =RANK(S6,$S$4:$S$58) -> 22
A7: 4 | C7: 15 | D7: M | E7: 81 | F7: 70 | G7: 50 | H7: 42 | I7: 47 | J7: 68 | K7: 62 | L7: 73 | M7: 72 | N7: 76 | O7: 68 | P7: 85 | Q7: 67 | R7: =SUM(E7:Q7) -> 861 | S7: =AVERAGE(E7:Q7) -> 66.230769 | T7: =RANK(S7,$S$4:$S$58) -> 45
A8: 5 | C8: 15 | D8: F | E8: 79 | F8: 75 | G8: 77 | H8: 72 | I8: 78 | J8: 82 | K8: 71 | L8: 83 | M8: 76 | N8: 86 | O8: 75 | P8: 86 | Q8: 77 | R8: =SUM(E8:Q8) -> 1017 | S8: =AVERAGE(E8:Q8) -> 78.230769 | T8: =RANK(S8,$S$4:$S$58) -> 24
A9: 6 | C9: 14 | D9: F | E9: 86 | F9: 65 | G9: 84 | H9: 76 | I9: 72 | J9: 83 | K9: 87 | L9: 81 | M9: 83 | N9: 83 | O9: 81 | P9: 91 | Q9: 98 | R9: =SUM(E9:Q9) -> 1070 | S9: =AVERAGE(E9:Q9) -> 82.307692 | T9: =RANK(S9,$S$4:$S$58) -> 13
A10: 7 | C10: 14 | D10: F | E10: 65 | F10: 51 | G10: 51 | H10: 52 | I10: 62 | J10: 52 | K10: 40 | L10: 69 | M10: 62 | N10: 83 | O10: 43 | P10: 78 | Q10: 62 | R10: =SUM(E10:Q10) -> 770 | S10: =AVERAGE(E10:Q10) -> 59.230769 | T10: =RANK(S10,$S$4:$S$58) -> 51
A11: 8 | C11: 15 | D11: F | E11: 89 | F11: 88 | G11: 86 | H11: 68 | I11: 71 | J11: 84 | K11: 73 | L11: 88 | M11: 85 | N11: 87 | O11: 82 | P11: 83 | Q11: 64 | R11: =SUM(E11:Q11) -> 1048 | S11: =AVERAGE(E11:Q11) -> 80.615385 | T11: =RANK(S11,$S$4:$S$58) -> 18
A12: 9 | C12: 15 | D12: M | E12: 73 | F12: 64 | G12: 45 | H12: 47 | I12: 57 | J12: 52 | K12: 43 | L12: 64 | M12: 65 | N12: 80 | O12: 66 | P12: 82 | Q12: 60 | R12: =SUM(E12:Q12) -> 798 | S12: =AVERAGE(E12:Q12) -> 61.384615 | T12: =RANK(S12,$S$4:$S$58) -> 50
A13: 10 | C13: 15 | D13: F | E13: 89 | F13: 69 | G13: 93 | H13: 63 | I13: 74 | J13: 58 | K13: 78 | L13: 73 | M13: 78 | N13: 90 | O13: 70 | P13: 87 | Q13: 83 | R13: =SUM(E13:Q13) -> 1005 | S13: =AVERAGE(E13:Q13) -> 77.307692 | T13: =RANK(S13,$S$4:$S$58) -> 27
A14: 11 | C14: 15 | D14: M | E14: 84 | F14: 54 | G14: 69 | H14: 62 | I14: 71 | J14: 57 | K14: 71 | L14: 76 | M14: 71 | N14: 83 | O14: 67 | P14: 90 | Q14: 70 | R14: =SUM(E14:Q14) -> 925 | S14: =AVERAGE(E14:Q14) -> 71.153846 | T14: =RANK(S14,$S$4:$S$58) -> 39
A15: 12 | C15: 15 | D15: M | E15: 72 | F15: 55 | G15: 47 | H15: 37 | I15: 51 | J15: 62 | K15: 52 | L15: 70 | M15: 65 | N15: 82 | O15: 74 | P15: 83 | Q15: 62 | R15: =SUM(E15:Q15) -> 812 | S15: =AVERAGE(E15:Q15) -> 62.461538 | T15: =RANK(S15,$S$4:$S$58) -> 49
... A58: 55 | C58: 15 | D58: F | E58: 95 | F58: 92 | G58: 99 | H58: 100 | I58: 100 | J58: 100 | K58: 96 | L58: 99 | M58: 94 | N58: 94 | O58: 99 | P58: 89 | Q58: 89 | R58: =SUM(E58:Q58) -> 1246 | S58: =AVERAGE(E58:Q58) -> 95.846154 | T58: =RANK(S58,$S$4:$S$58) -> 1

Sheet 9A Sem avr
A1: Maria Rubbato Catholic School 2016E.C Roster Grade 9A Student's
A2: Home Room Teacher Grade 9A
A3: No | B3: Student Name | C3: Age | D3: Sex | E3: Semster 1 Average | F3: Semster 2 Average | G3: Average | H3: Rank
A4: 1 | C4: 15 | D4: M | E4: ='9A Sem 1'!S4 -> 77.307692 | F4: ='9A Sem 2'!S4 -> 71.076923 | G4: =AVERAGE(E4:F4) -> 74.192308 | H4: =RANK(G4,$G$4:$G$58) -> 32
A5: 2 | C5: 14 | D5: F | E5: ='9A Sem 1'!S5 -> 77.538462 | F5: ='9A Sem 2'!S5 -> 82.538462 | G5: =AVERAGE(E5:F5) -> 80.038462 | H5: =RANK(G5,$G$4:$G$58) -> 18
A6: 3 | C6: 15 | D6: M | E6: ='9A Sem 1'!S6 -> 79.692308 | F6: ='9A Sem 2'!S6 -> 78.769231 | G6: =AVERAGE(E6:F6) -> 79.230769 | H6: =RANK(G6,$G$4:$G$58) -> 19
A7: 4 | C7: 15 | D7: M | E7: ='9A Sem 1'!S7 -> 67.692308 | F7: ='9A Sem 2'!S7 -> 66.230769 | G7: =AVERAGE(E7:F7) -> 66.961538 | H7: =RANK(G7,$G$4:$G$58) -> 44
A8: 5 | C8: 15 | D8: F | E8: ='9A Sem 1'!S8 -> 76.538462 | F8: ='9A Sem 2'!S8 -> 78.230769 | G8: =AVERAGE(E8:F8) -> 77.384615 | H8: =RANK(G8,$G$4:$G$58) -> 22
A9: 6 | C9: 14 | D9: F | E9: ='9A Sem 1'!S9 -> 80.384615 | F9: ='9A Sem 2'!S9 -> 82.307692 | G9: =AVERAGE(E9:F9) -> 81.346154 | H9: =RANK(G9,$G$4:$G$58) -> 15
A10: 7 | C10: 14 | D10: F | E10: ='9A Sem 1'!S10 -> 56 | F10: ='9A Sem 2'!S10 -> 59.230769 | G10: =AVERAGE(E10:F10) -> 57.615385 | H10: =RANK(G10,$G$4:$G$58) -> 52
A11: 8 | C11: 15 | D11: F | E11: ='9A Sem 1'!S11 -> 80.461538 | F11: ='9A Sem 2'!S11 -> 80.615385 | G11: =AVERAGE(E11:F11) -> 80.538462 | H11: =RANK(G11,$G$4:$G$58) -> 16
A12: 9 | C12: 15 | D12: M | E12: ='9A Sem 1'!S12 -> 63.384615 | F12: ='9A Sem 2'!S12 -> 61.384615 | G12: =AVERAGE(E12:F12) -> 62.384615 | H12: =RANK(G12,$G$4:$G$58) -> 49
A13: 10 | C13: 15 | D13: F | E13: ='9A Sem 1'!S13 -> 71.923077 | F13: ='9A Sem 2'!S13 -> 77.307692 | G13: =AVERAGE(E13:F13) -> 74.615385 | H13: =RANK(G13,$G$4:$G$58) -> 30
A14: 11 | C14: 15 | D14: M | E14: ='9A Sem 1'!S14 -> 70.692308 | F14: ='9A Sem 2'!S14 -> 71.153846 | G14: =AVERAGE(E14:F14) -> 70.923077 | H14: =RANK(G14,$G$4:$G$58) -> 40
A15: 12 | C15: 15 | D15: M | E15: ='9A Sem 1'!S15 -> 62.307692 | F15: ='9A Sem 2'!S15 -> 62.461538 | G15: =AVERAGE(E15:F15) -> 62.384615 | H15: =RANK(G15,$G$4:$G$58) -> 49
... A58: 55 | C58: 15 | D58: F | E58: ='9A Sem 1'!S58 -> 94.538462 | F58: ='9A Sem 2'!S58 -> 95.846154 | G58: =AVERAGE(E58:F58) -> 95.192308 | H58: =RANK(G58,$G$4:$G$58) -> 1

Sheet Roster 9B
A1: Maria Rubbato Catholic School 2016 E.C Roster Grade 9B Student's
A3: Home Room Teacher Grade 9B
A5: No | B5: Student Name | C5: Age | D5: Sex | E5: Semester | F5: Amharic | G5: English | H5: Maths | I5: physics | J5: chemistry | K5: Biology | L5: History | M5: Geography | N5: Citizenship | O5: ICT | P5: Economics | Q5: H.P.E | R5: Afan Oromo | S5: Total | T5: Average | U5: Rank | V5: Condc. | W5: Abse.
A6: 1 | C6: 15 | D6: M | E6: Semister 1 | F6: ='9B Sem 1'!E4 -> 74 | G6: ='9B Sem 1'!F4 -> 67 | H6: ='9B Sem 1'!G4 -> 78 | I6: ='9B Sem 1'!H4 -> 71 | J6: ='9B Sem 1'!I4 -> 75 | K6: ='9B Sem 1'!J4 -> 64 | L6: ='9B Sem 1'!K4 -> 75 | M6: ='9B Sem 1'!L4 -> 64 | ... W6: ='9B Sem 1'!V4 -> 0
C7: 15 | D7: M | E7: Semister 2 | F7: ='9B Sem 2'!E4 -> 75 | G7: ='9B Sem 2'!F4 -> 74 | H7: ='9B Sem 2'!G4 -> 89 | I7: ='9B Sem 2'!H4 -> 77 | J7: ='9B Sem 2'!I4 -> 63 | K7: ='9B Sem 2'!J4 -> 77 | L7: ='9B Sem 2'!K4 -> 66 | M7: ='9B Sem 2'!L4 -> 81 | ... W7: ='9B Sem 2'!V4 -> 0
C8: 15 | D8: M | E8: Average | F8: =AVERAGE(F6:F7) -> 74.5 | G8: =AVERAGE(G6:G7) -> 70.5 | H8: =AVERAGE(H6:H7) -> 83.5 | I8: =AVERAGE(I6:I7) -> 74 | J8: =AVERAGE(J6:J7) -> 69 | K8: =AVERAGE(K6:K7) -> 70.5 | L8: =AVERAGE(L6:L7) -> 70.5 | M8: =AVERAGE(M6:M7) -> 72.5 | ... T8: =AVERAGE(T6:T7) -> 73.230769 | U8: ='9B Sem avr'!$H$4 -> 25 | V8: =AVERAGE(V6:V7) -> 0 | W8: =AVERAGE(W6:W7) -> 0
A9: 2 | C9: 14 | D9: M | E9: Semister 1 | F9: ='9B Sem 1'!E5 -> 63 | G9: ='9B Sem 1'!F5 -> 42 | H9: ='9B Sem 1'!G5 -> 47 | I9: ='9B Sem 1'!H5 -> 40 | J9: ='9B Sem 1'!I5 -> 50 | K9: ='9B Sem 1'!J5 -> 50 | L9: ='9B Sem 1'!K5 -> 42 | M9: ='9B Sem 1'!L5 -> 45 | ... W9: ='9B Sem 1'!V5 -> 0
C10: 14 | D10: M | E10: Semister 2 | F10: ='9B Sem 2'!E5 -> 58 | G10: ='9B Sem 2'!F5 -> 41 | H10: ='9B Sem 2'!G5 -> 39 | I10: ='9B Sem 2'!H5 -> 58 | J10: ='9B Sem 2'!I5 -> 52 | K10: ='9B Sem 2'!J5 -> 62 | L10: ='9B Sem 2'!K5 -> 60 | M10: ='9B Sem 2'!L5 -> 62 | ... W10: ='9B Sem 2'!V5 -> 0
C11: 14 | D11: M | E11: Average | F11: =AVERAGE(F9:F10) -> 60.5 | G11: =AVERAGE(G9:G10) -> 41.5 | H11: =AVERAGE(H9:H10) -> 43 | I11: =AVERAGE(I9:I10) -> 49 | J11: =AVERAGE(J9:J10) -> 51 | K11: =AVERAGE(K9:K10) -> 56 | L11: =AVERAGE(L9:L10) -> 51 | M11: =AVERAGE(M9:M10) -> 53.5 | ... T11: =AVERAGE(T9:T10) -> 54.461538 | U11: ='9B Sem avr'!$H$5 -> 50 | V11: =AVERAGE(V9:V10) -> 0 | W11: =AVERAGE(W9:W10) -> 0
A12: 3 | C12: 14 | D12: F | E12: Semister 1 | F12: ='9B Sem 1'!E6 -> 90 | G12: ='9B Sem 1'!F6 -> 93 | H12: ='9B Sem 1'!G6 -> 71 | I12: ='9B Sem 1'!H6 -> 76 | J12: ='9B Sem 1'!I6 -> 79 | K12: ='9B Sem 1'!J6 -> 87 | L12: ='9B Sem 1'!K6 -> 87 | M12: ='9B Sem 1'!L6 -> 71 | ... W12: ='9B Sem 1'!V6 -> 0
C13: 14 | D13: F | E13: Semister 2 | F13: ='9B Sem 2'!E6 -> 91 | G13: ='9B Sem 2'!F6 -> 90 | H13: ='9B Sem 2'!G6 -> 78 | I13: ='9B Sem 2'!H6 -> 85 | J13: ='9B Sem 2'!I6 -> 85 | K13: ='9B Sem 2'!J6 -> 95 | L13: ='9B Sem 2'!K6 -> 85 | M13: ='9B Sem 2'!L6 -> 92 | ... W13: ='9B Sem 2'!V6 -> 0
C14: 14 | D14: F | E14: Average | F14: =AVERAGE(F12:F13) -> 90.5 | G14: =AVERAGE(G12:G13) -> 91.5 | H14: =AVERAGE(H12:H13) -> 74.5 | I14: =AVERAGE(I12:I13) -> 80.5 | J14: =AVERAGE(J12:J13) -> 82 | K14: =AVERAGE(K12:K13) -> 91 | L14: =AVERAGE(L12:L13) -> 86 | M14: =AVERAGE(M12:M13) -> 81.5 | ... T14: =AVERAGE(T12:T13) -> 86.153846 | U14: ='9B Sem avr'!$H$6 -> 4 | V14: =AVERAGE(V12:V13) -> 0 | W14: =AVERAGE(W12:W13) -> 0
A15: 4 | C15: 15 | D15: F | E15: Semister 1 | F15: ='9B Sem 1'!E7 -> 87 | G15: ='9B Sem 1'!F7 -> 84 | H15: ='9B Sem 1'!G7 -> 61 | I15: ='9B Sem 1'!H7 -> 62 | J15: ='9B Sem 1'!I7 -> 72 | K15: ='9B Sem 1'!J7 -> 73 | L15: ='9B Sem 1'!K7 -> 80 | M15: ='9B Sem 1'!L7 -> 86 | ... W15: ='9B Sem 1'!V7 -> 0
C16: 15 | D16: F | E16: Semister 2 | F16: ='9B Sem 2'!E7 -> 91 | G16: ='9B Sem 2'!F7 -> 78 | H16: ='9B Sem 2'!G7 -> 77 | I16: ='9B Sem 2'!H7 -> 75 | J16: ='9B Sem 2'!I7 -> 77 | K16: ='9B Sem 2'!J7 -> 80 | L16: ='9B Sem 2'!K7 -> 72 | M16: ='9B Sem 2'!L7 -> 87 | ... W16: ='9B Sem 2'!V7 -> 0
C17: 15 | D17: F | E17: Average | F17: =AVERAGE(F15:F16) -> 89 | G17: =AVERAGE(G15:G16) -> 81 | H17: =AVERAGE(H15:H16) -> 69 | I17: =AVERAGE(I15:I16) -> 68.5 | J17: =AVERAGE(J15:J16) -> 74.5 | K17: =AVERAGE(K15:K16) -> 76.5 | L17: =AVERAGE(L15:L16) -> 76 | M17: =AVERAGE(M15:M16) -> 86.5 | ... T17: =AVERAGE(T15:T16) -> 80.961538 | U17: ='9B Sem avr'!$H$7 -> 11 | V17: =AVERAGE(V15:V16) -> 0 | W17: =AVERAGE(W15:W16) -> 0
A18: 5 | C18: 14 | D18: F | E18: Semister 1 | F18: ='9B Sem 1'!E8 -> 78 | G18: ='9B Sem 1'!F8 -> 80 | H18: ='9B Sem 1'!G8 -> 53 | I18: ='9B Sem 1'!H8 -> 51 | J18: ='9B Sem 1'!I8 -> 71 | K18: ='9B Sem 1'!J8 -> 66 | L18: ='9B Sem 1'!K8 -> 79 | M18: ='9B Sem 1'!L8 -> 72 | ... W18: ='9B Sem 1'!V8 -> 0
C19: 14 | D19: F | E19: Semister 2 | F19: ='9B Sem 2'!E8 -> 83 | G19: ='9B Sem 2'!F8 -> 66 | H19: ='9B Sem 2'!G8 -> 59 | I19: ='9B Sem 2'!H8 -> 61 | J19: ='9B Sem 2'!I8 -> 65 | K19: ='9B Sem 2'!J8 -> 74 | L19: ='9B Sem 2'!K8 -> 83 | M19: ='9B Sem 2'!L8 -> 61 | ... W19: ='9B Sem 2'!V8 -> 0
C20: 14 | D20: F | E20: Average | F20: =AVERAGE(F18:F19) -> 80.5 | G20: =AVERAGE(G18:G19) -> 73 | H20: =AVERAGE(H18:H19) -> 56 | I20: =AVERAGE(I18:I19) -> 56 | J20: =AVERAGE(J18:J19) -> 68 | K20: =AVERAGE(K18:K19) -> 70 | L20: =AVERAGE(L18:L19) -> 81 | M20: =AVERAGE(M18:M19) -> 66.5 | ... T20: =AVERAGE(T18:T19) -> 74.153846 | U20: ='9B Sem avr'!$H$8 -> 22 | V20: =AVERAGE(V18:V19) -> 0 | W20: =AVERAGE(W18:W19) -> 0
A21: 6 | C21: 15 | D21: M | E21: Semister 1 | F21: ='9B Sem 1'!E9 -> 75 | G21: ='9B Sem 1'!F9 -> 73 | H21: ='9B Sem 1'!G9 -> 43 | I21: ='9B Sem 1'!H9 -> 37 | J21: ='9B Sem 1'!I9 -> 44 | K21: ='9B Sem 1'!J9 -> 48 | L21: ='9B Sem 1'!K9 -> 55 | M21: ='9B Sem 1'!L9 -> 55 | ... W21: ='9B Sem 1'!V9 -> 0
C22: 15 | D22: M | E22: Semister 2 | F22: ='9B Sem 2'!E9 -> 82 | G22: ='9B Sem 2'!F9 -> 67 | H22: ='9B Sem 2'!G9 -> 44 | I22: ='9B Sem 2'!H9 -> 38 | J22: ='9B Sem 2'!I9 -> 38 | K22: ='9B Sem 2'!J9 -> 50 | L22: ='9B Sem 2'!K9 -> 46 | M22: ='9B Sem 2'!L9 -> 58 | ... W22: ='9B Sem 2'!V9 -> 0
C23: 15 | D23: M | E23: Average | F23: =AVERAGE(F21:F22) -> 78.5 | G23: =AVERAGE(G21:G22) -> 70 | H23: =AVERAGE(H21:H22) -> 43.5 | I23: =AVERAGE(I21:I22) -> 37.5 | J23: =AVERAGE(J21:J22) -> 41 | K23: =AVERAGE(K21:K22) -> 49 | L23: =AVERAGE(L21:L22) -> 50.5 | M23: =AVERAGE(M21:M22) -> 56.5 | ... T23: =AVERAGE(T21:T22) -> 58.884615 | U23: ='9B Sem avr'!$H$9 -> 43 | V23: =AVERAGE(V21:V22) -> 0 | W23: =AVERAGE(W21:W22) -> 0
A24: 7 | C24: 15 | D24: M | E24: Semister 1 | F24: ='9B Sem 1'!E10 -> 72 | G24: ='9B Sem 1'!F10 -> 59 | H24: ='9B Sem 1'!G10 -> 47 | I24: ='9B Sem 1'!H10 -> 46 | J24: ='9B Sem 1'!I10 -> 57 | K24: ='9B Sem 1'!J10 -> 53 | L24: ='9B Sem 1'!K10 -> 53 | M24: ='9B Sem 1'!L10 -> 61 | ... W24: ='9B Sem 1'!V10 -> 0
C25: 15 | D25: M | E25: Semister 2 | F25: ='9B Sem 2'!E10 -> 63 | G25: ='9B Sem 2'!F10 -> 58 | H25: ='9B Sem 2'!G10 -> 54 | I25: ='9B Sem 2'!H10 -> 52 | J25: ='9B Sem 2'!I10 -> 41 | K25: ='9B Sem 2'!J10 -> 52 | L25: ='9B Sem 2'!K10 -> 46 | M25: ='9B Sem 2'!L10 -> 50 | ... W25: ='9B Sem 2'!V10 -> 0
C26: 15 | D26: M | E26: Average | F26: =AVERAGE(F24:F25) -> 67.5 | G26: =AVERAGE(G24:G25) -> 58.5 | H26: =AVERAGE(H24:H25) -> 50.5 | I26: =AVERAGE(I24:I25) -> 49 | J26: =AVERAGE(J24:J25) -> 49 | K26: =AVERAGE(K24:K25) -> 52.5 | L26: =AVERAGE(L24:L25) -> 49.5 | M26: =AVERAGE(M24:M25) -> 55.5 | ... T26: =AVERAGE(T24:T25) -> 56.884615 | U26: ='9B Sem avr'!$H$10 -> 46 | V26: =AVERAGE(V24:V25) -> 0 | W26: =AVERAGE(W24:W25) -> 0
A27: 8 | C27: 14 | D27: M | E27: Semister 1 | F27: ='9B Sem 1'!E11 -> 64 | G27: ='9B Sem 1'!F11 -> 59 | H27: ='9B Sem 1'!G11 -> 54 | I27: ='9B Sem 1'!H11 -> 34 | J27: ='9B Sem 1'!I11 -> 37 | K27: ='9B Sem 1'!J11 -> 50 | L27: ='9B Sem 1'!K11 -> 49 | M27: ='9B Sem 1'!L11 -> 51 | ... W27: ='9B Sem 1'!V11 -> 0
C28: 14 | D28: M | E28: Semister 2 | F28: ='9B Sem 2'!E11 -> 58 | G28: ='9B Sem 2'!F11 -> 52 | H28: ='9B Sem 2'!G11 -> 45 | I28: ='9B Sem 2'!H11 -> 51 | J28: ='9B Sem 2'!I11 -> 32 | K28: ='9B Sem 2'!J11 -> 41 | L28: ='9B Sem 2'!K11 -> 45 | M28: ='9B Sem 2'!L11 -> 55 | ... W28: ='9B Sem 2'!V11 -> 0
C29: 14 | D29: M | E29: Average | F29: =AVERAGE(F27:F28) -> 61 | G29: =AVERAGE(G27:G28) -> 55.5 | H29: =AVERAGE(H27:H28) -> 49.5 | I29: =AVERAGE(I27:I28) -> 42.5 | J29: =AVERAGE(J27:J28) -> 34.5 | K29: =AVERAGE(K27:K28) -> 45.5 | L29: =AVERAGE(L27:L28) -> 47 | M29: =AVERAGE(M27:M28) -> 53 | ... T29: =AVERAGE(T27:T28) -> 53.5 | U29: ='9B Sem avr'!$H$11 -> 52 | V29: =AVERAGE(V27:V28) -> 0 | W29: =AVERAGE(W27:W28) -> 0
A30: 9 | C30: 14 | D30: M | E30: Semister 1 | F30: ='9B Sem 1'!E12 -> 73 | G30: ='9B Sem 1'!F12 -> 78 | H30: ='9B Sem 1'!G12 -> 70 | I30: ='9B Sem 1'!H12 -> 74 | J30: ='9B Sem 1'!I12 -> 69 | K30: ='9B Sem 1'!J12 -> 66 | L30: ='9B Sem 1'!K12 -> 79 | M30: ='9B Sem 1'!L12 -> 74 | ... W30: ='9B Sem 1'!V12 -> 0
C31: 14 | D31: M | E31: Semister 2 | F31: ='9B Sem 2'!E12 -> 76 | G31: ='9B Sem 2'!F12 -> 64 | H31: ='9B Sem 2'!G12 -> 82 | I31: ='9B Sem 2'!H12 -> 67 | J31: ='9B Sem 2'!I12 -> 70 | K31: ='9B Sem 2'!J12 -> 76 | L31: ='9B Sem 2'!K12 -> 87 | M31: ='9B Sem 2'!L12 -> 83 | ... W31: ='9B Sem 2'!V12 -> 0
C32: 14 | D32: M | E32: Average | F32: =AVERAGE(F30:F31) -> 74.5 | G32: =AVERAGE(G30:G31) -> 71 | H32: =AVERAGE(H30:H31) -> 76 | I32: =AVERAGE(I30:I31) -> 70.5 | J32: =AVERAGE(J30:J31) -> 69.5 | K32: =AVERAGE(K30:K31) -> 71 | L32: =AVERAGE(L30:L31) -> 83 | M32: =AVERAGE(M30:M31) -> 78.5 | ... T32: =AVERAGE(T30:T31) -> 76.115385 | U32: ='9B Sem avr'!$H$12 -> 21 | V32: =AVERAGE(V30:V31) -> 0 | W32: =AVERAGE(W30:W31) -> 0
A33: 10 | C33: 14 | D33: F | E33: Semister 1 | F33: ='9B Sem 1'!E13 -> 78 | G33: ='9B Sem 1'!F13 -> 87 | H33: ='9B Sem 1'!G13 -> 55 | I33: ='9B Sem 1'!H13 -> 54 | J33: ='9B Sem 1'!I13 -> 65 | K33: ='9B Sem 1'!J13 -> 55 | L33: ='9B Sem 1'!K13 -> 78 | M33: ='9B Sem 1'!L13 -> 58 | ... W33: ='9B Sem 1'!V13 -> 0
C34: 14 | D34: F | E34: Semister 2 | F34: ='9B Sem 2'!E13 -> 64 | G34: ='9B Sem 2'!F13 -> 82 | H34: ='9B Sem 2'!G13 -> 78 | I34: ='9B Sem 2'!H13 -> 53 | J34: ='9B Sem 2'!I13 -> 63 | K34: ='9B Sem 2'!J13 -> 71 | L34: ='9B Sem 2'!K13 -> 69 | M34: ='9B Sem 2'!L13 -> 76 | ... W34: ='9B Sem 2'!V13 -> 0
C35: 14 | D35: F | E35: Average | F35: =AVERAGE(F33:F34) -> 71 | G35: =AVERAGE(G33:G34) -> 84.5 | H35: =AVERAGE(H33:H34) -> 66.5 | I35: =AVERAGE(I33:I34) -> 53.5 | J35: =AVERAGE(J33:J34) -> 64 | K35: =AVERAGE(K33:K34) -> 63 | L35: =AVERAGE(L33:L34) -> 73.5 | M35: =AVERAGE(M33:M34) -> 67 | ... T35: =AVERAGE(T33:T34) -> 71.076923 | U35: ='9B Sem avr'!$H$13 -> 27 | V35: =AVERAGE(V33:V34) -> 0 | W35: =AVERAGE(W33:W34) -> 0
A36: 11 | C36: 15 | D36: F | E36: Semister 1 | F36: ='9B Sem 1'!E14 -> 83 | G36: ='9B Sem 1'!F14 -> 87 | H36: ='9B Sem 1'!G14 -> 81 | I36: ='9B Sem 1'!H14 -> 67 | J36: ='9B Sem 1'!I14 -> 72 | K36: ='9B Sem 1'!J14 -> 72 | L36: ='9B Sem 1'!K14 -> 79 | M36: ='9B Sem 1'!L14 -> 64 | ... W36: ='9B Sem 1'!V14 -> 0
C37: 15 | D37: F | E37: Semister 2 | F37: ='9B Sem 2'!E14 -> 78 | G37: ='9B Sem 2'!F14 -> 82 | H37: ='9B Sem 2'!G14 -> 81 | I37: ='9B Sem 2'!H14 -> 72 | J37: ='9B Sem 2'!I14 -> 81 | K37: ='9B Sem 2'!J14 -> 81 | L37: ='9B Sem 2'!K14 -> 71 | M37: ='9B Sem 2'!L14 -> 85 | ... W37: ='9B Sem 2'!V14 -> 0
C38: 15 | D38: F | E38: Average | F38: =AVERAGE(F36:F37) -> 80.5 | G38: =AVERAGE(G36:G37) -> 84.5 | H38: =AVERAGE(H36:H37) -> 81 | I38: =AVERAGE(I36:I37) -> 69.5 | J38: =AVERAGE(J36:J37) -> 76.5 | K38: =AVERAGE(K36:K37) -> 76.5 | L38: =AVERAGE(L36:L37) -> 75 | M38: =AVERAGE(M36:M37) -> 74.5 | ... T38: =AVERAGE(T36:T37) -> 79.115385 | U38: ='9B Sem avr'!$H$14 -> 15 | V38: =AVERAGE(V36:V37) -> 0 | W38: =AVERAGE(W36:W37) -> 0
A39: 12 | C39: 15 | D39: F | E39: Semister 1 | F39: ='9B Sem 1'!E15 -> 88 | G39: ='9B Sem 1'!F15 -> 82 | H39: ='9B Sem 1'!G15 -> 77 | I39: ='9B Sem 1'!H15 -> 73 | J39: ='9B Sem 1'!I15 -> 78 | K39: ='9B Sem 1'!J15 -> 87 | L39: ='9B Sem 1'!K15 -> 90 | M39: ='9B Sem 1'!L15 -> 82 | ... W39: ='9B Sem 1'!V15 -> 0
C40: 15 | D40: F | E40: Semister 2 | F40: ='9B Sem 2'!E15 -> 85 | G40: ='9B Sem 2'!F15 -> 76 | H40: ='9B Sem 2'!G15 -> 76 | I40: ='9B Sem 2'!H15 -> 72 | J40: ='9B Sem 2'!I15 -> 76 | K40: ='9B Sem 2'!J15 -> 84 | L40: ='9B Sem 2'!K15 -> 85 | M40: ='9B Sem 2'!L15 -> 91 | ... W40: ='9B Sem 2'!V15 -> 0
C41: 15 | D41: F | E41: Average | F41: =AVERAGE(F39:F40) -> 86.5 | G41: =AVERAGE(G39:G40) -> 79 | H41: =AVERAGE(H39:H40) -> 76.5 | I41: =AVERAGE(I39:I40) -> 72.5 | J41: =AVERAGE(J39:J40) -> 77 | K41: =AVERAGE(K39:K40) -> 85.5 | L41: =AVERAGE(L39:L40) -> 87.5 | M41: =AVERAGE(M39:M40) -> 86.5 | ... T41: =AVERAGE(T39:T40) -> 83.807692 | U41: ='9B Sem avr'!$H$15 -> 7 | V41: =AVERAGE(V39:V40) -> 0 | W41: =AVERAGE(W39:W40) -> 0
A42: 13 | C42: 14 | D42: F | E42: Semister 1 | F42: ='9B Sem 1'!E16 -> 89 | G42: ='9B Sem 1'!F16 -> 99 | H42: ='9B Sem 1'!G16 -> 99 | I42: ='9B Sem 1'!H16 -> 93 | J42: ='9B Sem 1'!I16 -> 100 | K42: ='9B Sem 1'!J16 -> 97 | L42: ='9B Sem 1'!K16 -> 96 | M42: ='9B Sem 1'!L16 -> 99 | ... W42: ='9B Sem 1'!V16 -> 0
...

Sheet 9B Sem 1
A1: Maria Rubbato Catholic School 2016 E.C Roster Grade 9B Student's
A2: Home Room Teacher Grade 9B
A3: No | B3: Student Name | C3: Age | D3: Sex | E3: Amharic | F3: English | G3: Maths | H3: physics | I3: chemistry | J3: Biology | K3: History | L3: Geography | M3: Citizenship | N3: ICT | O3: Economics | P3: H.P.E | Q3: Afan Oromo | R3: Total | S3: Average | T3: Rank | U3: Condc. | V3: Abse.
A4: 1 | C4: 15 | D4: M | E4: 74 | F4: 67 | G4: 78 | H4: 71 | I4: 75 | J4: 64 | K4: 75 | L4: 64 | M4: 72 | N4: 89 | O4: 70 | P4: 81 | Q4: 54 | R4: =SUM(E4:Q4) -> 934 | S4: =AVERAGE(E4:Q4) -> 71.846154 | T4: =RANK(S4,$S$4:$S$59) -> 25
A5: 2 | C5: 14 | D5: M | E5: 63 | F5: 42 | G5: 47 | H5: 40 | I5: 50 | J5: 50 | K5: 42 | L5: 45 | M5: 54 | N5: 52 | O5: 51 | P5: 70 | Q5: 61 | R5: =SUM(E5:Q5) -> 667 | S5: =AVERAGE(E5:Q5) -> 51.307692 | T5: =RANK(S5,$S$4:$S$59) -> 54
A6: 3 | C6: 14 | D6: F | E6: 90 | F6: 93 | G6: 71 | H6: 76 | I6: 79 | J6: 87 | K6: 87 | L6: 71 | M6: 95 | N6: 89 | O6: 84 | P6: 96 | Q6: 78 | R6: =SUM(E6:Q6) -> 1096 | S6: =AVERAGE(E6:Q6) -> 84.307692 | T6: =RANK(S6,$S$4:$S$59) -> 7
A7: 4 | C7: 15 | D7: F | E7: 87 | F7: 84 | G7: 61 | H7: 62 | I7: 72 | J7: 73 | K7: 80 | L7: 86 | M7: 87 | N7: 87 | O7: 82 | P7: 96 | Q7: 93 | R7: =SUM(E7:Q7) -> 1050 | S7: =AVERAGE(E7:Q7) -> 80.769231 | T7: =RANK(S7,$S$4:$S$59) -> 12
A8: 5 | C8: 14 | D8: F | E8: 78 | F8: 80 | G8: 53 | H8: 51 | I8: 71 | J8: 66 | K8: 79 | L8: 72 | M8: 86 | N8: 77 | O8: 75 | P8: 92 | Q8: 90 | R8: =SUM(E8:Q8) -> 970 | S8: =AVERAGE(E8:Q8) -> 74.615385 | T8: =RANK(S8,$S$4:$S$59) -> 22
A9: 6 | C9: 15 | D9: M | E9: 75 | F9: 73 | G9: 43 | H9: 37 | I9: 44 | J9: 48 | K9: 55 | L9: 55 | M9: 70 | N9: 77 | O9: 65 | P9: 80 | Q9: 55 | R9: =SUM(E9:Q9) -> 777 | S9: =AVERAGE(E9:Q9) -> 59.769231 | T9: =RANK(S9,$S$4:$S$59) -> 44
A10: 7 | C10: 15 | D10: M | E10: 72 | F10: 59 | G10: 47 | H10: 46 | I10: 57 | J10: 53 | K10: 53 | L10: 61 | M10: 56 | N10: 56 | O10: 55 | P10: 85 | Q10: 50 | R10: =SUM(E10:Q10) -> 750 | S10: =AVERAGE(E10:Q10) -> 57.692308 | T10: =RANK(S10,$S$4:$S$59) -> 48
A11: 8 | C11: 14 | D11: M | E11: 64 | F11: 59 | G11: 54 | H11: 34 | I11: 37 | J11: 50 | K11: 49 | L11: 51 | M11: 60 | N11: 49 | O11: 44 | P11: 80 | Q11: 51 | R11: =SUM(E11:Q11) -> 682 | S11: =AVERAGE(E11:Q11) -> 52.461538 | T11: =RANK(S11,$S$4:$S$59) -> 53
A12: 9 | C12: 14 | D12: M | E12: 73 | F12: 78 | G12: 70 | H12: 74 | I12: 69 | J12: 66 | K12: 79 | L12: 74 | M12: 79 | N12: 76 | O12: 77 | P12: 90 | Q12: 72 | R12: =SUM(E12:Q12) -> 977 | S12: =AVERAGE(E12:Q12) -> 75.153846 | T12: =RANK(S12,$S$4:$S$59) -> 20
A13: 10 | C13: 14 | D13: F | E13: 78 | F13: 87 | G13: 55 | H13: 54 | I13: 65 | J13: 55 | K13: 78 | L13: 58 | M13: 80 | N13: 66 | O13: 77 | P13: 84 | Q13: 66 | R13: =SUM(E13:Q13) -> 903 | S13: =AVERAGE(E13:Q13) -> 69.461538 | T13: =RANK(S13,$S$4:$S$59) -> 28
A14: 11 | C14: 15 | D14: F | E14: 83 | F14: 87 | G14: 81 | H14: 67 | I14: 72 | J14: 72 | K14: 79 | L14: 64 | M14: 90 | N14: 81 | O14: 79 | P14: 84 | Q14: 69 | R14: =SUM(E14:Q14) -> 1008 | S14: =AVERAGE(E14:Q14) -> 77.538462 | T14: =RANK(S14,$S$4:$S$59) -> 18
A15: 12 | C15: 15 | D15: F | E15: 88 | F15: 82 | G15: 77 | H15: 73 | I15: 78 | J15: 87 | K15: 90 | L15: 82 | M15: 95 | N15: 88 | O15: 80 | P15: 96 | Q15: 91 | R15: =SUM(E15:Q15) -> 1107 | S15: =AVERAGE(E15:Q15) -> 85.153846 | T15: =RANK(S15,$S$4:$S$59) -> 6
... A57: 54 | C57: 15 | D57: M | E57: 81 | F57: 79 | G57: 81 | H57: 87 | I57: 84 | J57: 88 | K57: 87 | L57: 84 | M57: 91 | N57: 86 | O57: 84 | P57: 100 | Q57: 81 | R57: =SUM(E57:Q57) -> 1113 | S57: =AVERAGE(E57:Q57) -> 85.615385 | T57: =RANK(S57,$S$4:$S$59) -> 4
A58: 55 | C58: 15 | D58: M | R58: =SUM(E58:Q58) -> 0 | S58: 0 | T58: =RANK(S58,$S$4:$S$59) -> 56
A59: 56 | C59: 15 | D59: F | E59: 75 | F59: 57 | G59: 57 | H59: 44 | I59: 54 | J59: 48 | K59: 67 | L59: 53 | M59: 64 | N59: 70 | O59: 63 | P59: 82 | Q59: 62 | R59: =SUM(E59:Q59) -> 796 | S59: =AVERAGE(E59:Q59) -> 61.230769 | T59: =RANK(S59,$S$4:$S$59) -> 39

Sheet 9B Sem avr
A1: Maria Rubbato Catholic School 2016 E.C Roster Grade 9A Student's
A2: Home Room Teacher Grade 9B
A3: No | B3: Student Name | C3: Age | D3: Sex | E3: Semster 1 Average | F3: Semster 2 Average | G3: Average | H3: Rank
A4: 1 | C4: 15 | D4: M | E4: ='9B Sem 1'!S4 -> 71.846154 | F4: ='9B Sem 2'!S4 -> 74.615385 | G4: =AVERAGE(E4:F4) -> 73.230769 | H4: =RANK(G4,$G$4:$G$57) -> 25
A5: 2 | C5: 14 | D5: M | E5: ='9B Sem 1'!S5 -> 51.307692 | F5: ='9B Sem 2'!S5 -> 57.615385 | G5: =AVERAGE(E5:F5) -> 54.461538 | H5: =RANK(G5,$G$4:$G$57) -> 50
A6: 3 | C6: 14 | D6: F | E6: ='9B Sem 1'!S6 -> 84.307692 | F6: ='9B Sem 2'!S6 -> 88 | G6: =AVERAGE(E6:F6) -> 86.153846 | H6: =RANK(G6,$G$4:$G$57) -> 4
A7: 4 | C7: 15 | D7: F | E7: ='9B Sem 1'!S7 -> 80.769231 | F7: ='9B Sem 2'!S7 -> 81.153846 | G7: =AVERAGE(E7:F7) -> 80.961538 | H7: =RANK(G7,$G$4:$G$57) -> 11
A8: 5 | C8: 14 | D8: F | E8: ='9B Sem 1'!S8 -> 74.615385 | F8: ='9B Sem 2'!S8 -> 73.692308 | G8: =AVERAGE(E8:F8) -> 74.153846 | H8: =RANK(G8,$G$4:$G$57) -> 22
A9: 6 | C9: 15 | D9: M | E9: ='9B Sem 1'!S9 -> 59.769231 | F9: ='9B Sem 2'!S9 -> 58 | G9: =AVERAGE(E9:F9) -> 58.884615 | H9: =RANK(G9,$G$4:$G$57) -> 43
A10: 7 | C10: 15 | D10: M | E10: ='9B Sem 1'!S10 -> 57.692308 | F10: ='9B Sem 2'!S10 -> 56.076923 | G10: =AVERAGE(E10:F10) -> 56.884615 | H10: =RANK(G10,$G$4:$G$57) -> 46
A11: 8 | C11: 14 | D11: M | E11: ='9B Sem 1'!S11 -> 52.461538 | F11: ='9B Sem 2'!S11 -> 54.538462 | G11: =AVERAGE(E11:F11) -> 53.5 | H11: =RANK(G11,$G$4:$G$57) -> 52
A12: 9 | C12: 14 | D12: M | E12: ='9B Sem 1'!S12 -> 75.153846 | F12: ='9B Sem 2'!S12 -> 77.076923 | G12: =AVERAGE(E12:F12) -> 76.115385 | H12: =RANK(G12,$G$4:$G$57) -> 21
A13: 10 | C13: 14 | D13: F | E13: ='9B Sem 1'!S13 -> 69.461538 | F13: ='9B Sem 2'!S13 -> 72.692308 | G13: =AVERAGE(E13:F13) -> 71.076923 | H13: =RANK(G13,$G$4:$G$57) -> 27
A14: 11 | C14: 15 | D14: F | E14: ='9B Sem 1'!S14 -> 77.538462 | F14: ='9B Sem 2'!S14 -> 80.692308 | G14: =AVERAGE(E14:F14) -> 79.115385 | H14: =RANK(G14,$G$4:$G$57) -> 15
A15: 12 | C15: 15 | D15: F | E15: ='9B Sem 1'!S15 -> 85.153846 | F15: ='9B Sem 2'!S15 -> 82.461538 | G15: =AVERAGE(E15:F15) -> 83.807692 | H15: =RANK(G15,$G$4:$G$57) -> 7
... A57: 54 | C57: 15 | D57: M | E57: ='9B Sem 1'!S57 -> 85.615385 | F57: ='9B Sem 2'!S57 -> 85.538462 | G57: =AVERAGE(E57:F57) -> 85.576923 | H57: =RANK(G57,$G$4:$G$57) -> 5
A58: 55 | C58: 15 | D58: M | E58: ='9B Sem 1'!S58 -> 0 | F58: ='9B Sem 2'!S58 -> 0 | G58: =AVERAGE(E58:F58) -> 0
A59: 56 | C59: 15 | D59: F

Sheet 9B Sem 2
A1: Maria Rubbato Catholic School 2016 E.C Roster Grade 9B Student's
A2: Home Room Teacher Grade 9B
A3: No | B3: Student Name | C3: Age | D3: Sex | E3: Amharic | F3: English | G3: Maths | H3: physics | I3: chemistry | J3: Biology | K3: History | L3: Geography | M3: Citizenship | N3: ICT | O3: Economics | P3: H.P.E | Q3: Afan Oromo | R3: Total | S3: Average | T3: Rank | U3: Condc. | V3: Abse.
A4: 1 | C4: 15 | D4: M | E4: 75 | F4: 74 | G4: 89 | H4: 77 | I4: 63 | J4: 77 | K4: 66 | L4: 81 | M4: 66 | N4: 84 | O4: 64 | P4: 91 | Q4: 63 | R4: =SUM(E4:Q4) -> 970 | S4: =AVERAGE(E4:Q4) -> 74.615385 | T4: =RANK(S4,$S$4:$S$59) -> 24
A5: 2 | C5: 14 | D5: M | E5: 58 | F5: 41 | G5: 39 | H5: 58 | I5: 52 | J5: 62 | K5: 60 | L5: 62 | M5: 58 | N5: 72 | O5: 48 | P5: 76 | Q5: 63 | R5: =SUM(E5:Q5) -> 749 | S5: =AVERAGE(E5:Q5) -> 57.615385 | T5: =RANK(S5,$S$4:$S$59) -> 46
A6: 3 | C6: 14 | D6: F | E6: 91 | F6: 90 | G6: 78 | H6: 85 | I6: 85 | J6: 95 | K6: 85 | L6: 92 | M6: 93 | N6: 96 | O6: 97 | P6: 94 | Q6: 63 | R6: =SUM(E6:Q6) -> 1144 | S6: =AVERAGE(E6:Q6) -> 88 | T6: =RANK(S6,$S$4:$S$59) -> 3
A7: 4 | C7: 15 | D7: F | E7: 91 | F7: 78 | G7: 77 | H7: 75 | I7: 77 | J7: 80 | K7: 72 | L7: 87 | M7: 87 | N7: 85 | O7: 89 | P7: 93 | Q7: 64 | R7: =SUM(E7:Q7) -> 1055 | S7: =AVERAGE(E7:Q7) -> 81.153846 | T7: =RANK(S7,$S$4:$S$59) -> 12
A8: 5 | C8: 14 | D8: F | E8: 83 | F8: 66 | G8: 59 | H8: 61 | I8: 65 | J8: 74 | K8: 83 | L8: 61 | M8: 85 | N8: 85 | O8: 78 | P8: 94 | Q8: 64 | R8: =SUM(E8:Q8) -> 958 | S8: =AVERAGE(E8:Q8) -> 73.692308 | T8: =RANK(S8,$S$4:$S$59) -> 25
A9: 6 | C9: 15 | D9: M | E9: 82 | F9: 67 | G9: 44 | H9: 38 | I9: 38 | J9: 50 | K9: 46 | L9: 58 | M9: 68 | N9: 70 | O9: 54 | P9: 73 | Q9: 66 | R9: =SUM(E9:Q9) -> 754 | S9: =AVERAGE(E9:Q9) -> 58 | T9: =RANK(S9,$S$4:$S$59) -> 45
A10: 7 | C10: 15 | D10: M | E10: 63 | F10: 58 | G10: 54 | H10: 52 | I10: 41 | J10: 52 | K10: 46 | L10: 50 | M10: 54 | N10: 66 | O10: 48 | P10: 76 | Q10: 69 | R10: =SUM(E10:Q10) -> 729 | S10: =AVERAGE(E10:Q10) -> 56.076923 | T10: =RANK(S10,$S$4:$S$59) -> 48
A11: 8 | C11: 14 | D11: M | E11: 58 | F11: 52 | G11: 45 | H11: 51 | I11: 32 | J11: 41 | K11: 45 | L11: 55 | M11: 57 | N11: 63 | O11: 68 | P11: 73 | Q11: 69 | R11: =SUM(E11:Q11) -> 709 | S11: =AVERAGE(E11:Q11) -> 54.538462 | T11: =RANK(S11,$S$4:$S$59) -> 49
A12: 9 | C12: 14 | D12: M | E12: 76 | F12: 64 | G12: 82 | H12: 67 | I12: 70 | J12: 76 | K12: 87 | L12: 83 | M12: 73 | N12: 84 | O12: 76 | P12: 94 | Q12: 70 | R12: =SUM(E12:Q12) -> 1002 | S12: =AVERAGE(E12:Q12) -> 77.076923 | T12: =RANK(S12,$S$4:$S$59) -> 20
A13: 10 | C13: 14 | D13: F | E13: 64 | F13: 82 | G13: 78 | H13: 53 | I13: 63 | J13: 71 | K13: 69 | L13: 76 | M13: 76 | N13: 77 | O13: 85 | P13: 90 | Q13: 61 | R13: =SUM(E13:Q13) -> 945 | S13: =AVERAGE(E13:Q13) -> 72.692308 | T13: =RANK(S13,$S$4:$S$59) -> 28
A14: 11 | C14: 15 | D14: F | E14: 78 | F14: 82 | G14: 81 | H14: 72 | I14: 81 | J14: 81 | K14: 71 | L14: 85 | M14: 84 | N14: 91 | O14: 81 | P14: 87 | Q14: 75 | R14: =SUM(E14:Q14) -> 1049 | S14: =AVERAGE(E14:Q14) -> 80.692308 | T14: =RANK(S14,$S$4:$S$59) -> 14
A15: 12 | C15: 15 | D15: F | E15: 85 | F15: 76 | G15: 76 | H15: 72 | I15: 76 | J15: 84 | K15: 85 | L15: 91 | M15: 85 | N15: 94 | O15: 87 | P15: 90 | Q15: 71 | R15: =SUM(E15:Q15) -> 1072 | S15: =AVERAGE(E15:Q15) -> 82.461538 | T15: =RANK(S15,$S$4:$S$59) -> 9
... A59: 56 | C59: 15 | D59: F | E59: 81 | F59: 44 | G59: 52 | H59: 53 | I59: 55 | J59: 64 | K59: 63 | L59: 67 | M59: 62 | N59: 77 | O59: 73 | P59: 87 | Q59: 85 | R59: =SUM(E59:Q59) -> 863 | S59: =AVERAGE(E59:Q59) -> 66.384615 | T59: =RANK(S59,$S$4:$S$59) -> 35

Sheet Roster 10A
A1: Maria Rubbato Catholic School 2016 E.C Roster Grade 10A Student's
A3: Home Room Teacher Grade 10A
A5: No | B5: Student Name | C5: Age | D5: Sex | E5: Semester | F5: Amharic | G5: English | H5: Maths | I5: physics | J5: chemistry | K5: Biology | L5: History | M5: Geography | N5: Civics | O5: ICT | P5: Economics | Q5: H.P.E | R5: Afan Oromo | S5: Total | T5: Average | U5: Rank | V5: Condc. | W5: Abse.
A6: 1 | C6: 15 | D6: F | E6: Semister 1 | F6: ='10A Sem 1'!E4 -> 79 | G6: ='10A Sem 1'!F4 -> 78 | H6: ='10A Sem 1'!G4 -> 64 | I6: ='10A Sem 1'!H4 -> 64 | J6: ='10A Sem 1'!I4 -> 56 | K6: ='10A Sem 1'!J4 -> 68 | L6: ='10A Sem 1'!K4 -> 64 | M6: ='10A Sem 1'!L4 -> 66 | ... W6: ='10A Sem 1'!V4 -> 0
C7: 15 | D7: F | E7: Semister 2 | F7: ='10A Sem 2'!E4 -> 67 | G7: ='10A Sem 2'!F4 -> 74 | H7: ='10A Sem 2'!G4 -> 48 | I7: ='10A Sem 2'!H4 -> 61 | J7: ='10A Sem 2'!I4 -> 55 | K7: ='10A Sem 2'!J4 -> 69 | L7: ='10A Sem 2'!K4 -> 69 | M7: ='10A Sem 2'!L4 -> 69 | ... W7: ='10A Sem 2'!V4 -> 0
C8: 15 | D8: F | E8: Average | F8: =AVERAGE(F6:F7) -> 73 | G8: =AVERAGE(G6:G7) -> 76 | H8: =AVERAGE(H6:H7) -> 56 | I8: =AVERAGE(I6:I7) -> 62.5 | J8: =AVERAGE(J6:J7) -> 55.5 | K8: =AVERAGE(K6:K7) -> 68.5 | L8: =AVERAGE(L6:L7) -> 66.5 | M8: =AVERAGE(M6:M7) -> 67.5 | ... T8: =AVERAGE(T6:T7) -> 71 | U8: ='10A Sem avr'!$H$4 -> 29 | V8: =AVERAGE(V6:V7) -> 0 | W8: =AVERAGE(W6:W7) -> 0
A9: 2 | C9: 15 | D9: F | E9: Semister 1 | F9: ='10A Sem 1'!E5 -> 71 | G9: ='10A Sem 1'!F5 -> 52 | H9: ='10A Sem 1'!G5 -> 70 | I9: ='10A Sem 1'!H5 -> 55 | J9: ='10A Sem 1'!I5 -> 48 | K9: ='10A Sem 1'!J5 -> 58 | L9: ='10A Sem 1'!K5 -> 56 | M9: ='10A Sem 1'!L5 -> 58 | ... W9: ='10A Sem 1'!V5 -> 0
C10: 15 | D10: F | E10: Semister 2 | F10: ='10A Sem 2'!E5 -> 70 | G10: ='10A Sem 2'!F5 -> 64 | H10: ='10A Sem 2'!G5 -> 54 | I10: ='10A Sem 2'!H5 -> 61 | J10: ='10A Sem 2'!I5 -> 42 | K10: ='10A Sem 2'!J5 -> 48 | L10: ='10A Sem 2'!K5 -> 48 | M10: ='10A Sem 2'!L5 -> 76 | ... W10: ='10A Sem 2'!V5 -> 0
C11: 15 | D11: F | E11: Average | F11: =AVERAGE(F9:F10) -> 70.5 | G11: =AVERAGE(G9:G10) -> 58 | H11: =AVERAGE(H9:H10) -> 62 | I11: =AVERAGE(I9:I10) -> 58 | J11: =AVERAGE(J9:J10) -> 45 | K11: =AVERAGE(K9:K10) -> 53 | L11: =AVERAGE(L9:L10) -> 52 | M11: =AVERAGE(M9:M10) -> 67 | ... T11: =AVERAGE(T9:T10) -> 62.961538 | U11: ='10A Sem avr'!$H$5 -> 40 | V11: =AVERAGE(V9:V10) -> 0 | W11: =AVERAGE(W9:W10) -> 0
A12: 3 | C12: 17 | D12: M | E12: Semister 1 | F12: ='10A Sem 1'!E6 -> 96 | G12: ='10A Sem 1'!F6 -> 94 | H12: ='10A Sem 1'!G6 -> 100 | I12: ='10A Sem 1'!H6 -> 100 | J12: ='10A Sem 1'!I6 -> 96 | K12: ='10A Sem 1'!J6 -> 97 | L12: ='10A Sem 1'!K6 -> 90 | M12: ='10A Sem 1'!L6 -> 96 | ... W12: ='10A Sem 1'!V6 -> 0
C13: 17 | D13: M | E13: Semister 2 | F13: ='10A Sem 2'!E6 -> 91 | G13: ='10A Sem 2'!F6 -> 91 | H13: ='10A Sem 2'!G6 -> 95 | I13: ='10A Sem 2'!H6 -> 100 | J13: ='10A Sem 2'!I6 -> 96 | K13: ='10A Sem 2'!J6 -> 98 | L13: ='10A Sem 2'!K6 -> 88 | M13: ='10A Sem 2'!L6 -> 97 | ... W13: ='10A Sem 2'!V6 -> 0
C14: 17 | D14: M | E14: Average | F14: =AVERAGE(F12:F13) -> 93.5 | G14: =AVERAGE(G12:G13) -> 92.5 | H14: =AVERAGE(H12:H13) -> 97.5 | I14: =AVERAGE(I12:I13) -> 100 | J14: =AVERAGE(J12:J13) -> 96 | K14: =AVERAGE(K12:K13) -> 97.5 | L14: =AVERAGE(L12:L13) -> 89 | M14: =AVERAGE(M12:M13) -> 96.5 | ... T14: =AVERAGE(T12:T13) -> 95.076923 | U14: ='10A Sem avr'!$H$6 -> 1 | V14: =AVERAGE(V12:V13) -> 0 | W14: =AVERAGE(W12:W13) -> 0
A15: 4 | C15: 15 | D15: F | E15: Semister 1 | F15: ='10A Sem 1'!E7 -> 81 | G15: ='10A Sem 1'!F7 -> 90 | H15: ='10A Sem 1'!G7 -> 98 | I15: ='10A Sem 1'!H7 -> 98 | J15: ='10A Sem 1'!I7 -> 85 | K15: ='10A Sem 1'!J7 -> 95 | L15: ='10A Sem 1'!K7 -> 95 | M15: ='10A Sem 1'!L7 -> 99 | ... W15: ='10A Sem 1'!V7 -> 0
C16: 15 | D16: F | E16: Semister 2 | F16: ='10A Sem 2'!E7 -> 85 | G16: ='10A Sem 2'!F7 -> 94 | H16: ='10A Sem 2'!G7 -> 90 | I16: ='10A Sem 2'!H7 -> 93 | J16: ='10A Sem 2'!I7 -> 92 | K16: ='10A Sem 2'!J7 -> 92 | L16: ='10A Sem 2'!K7 -> 91 | M16: ='10A Sem 2'!L7 -> 97 | ... W16: ='10A Sem 2'!V7 -> 0
C17: 15 | D17: F | E17: Average | F17: =AVERAGE(F15:F16) -> 83 | G17: =AVERAGE(G15:G16) -> 92 | H17: =AVERAGE(H15:H16) -> 94 | I17: =AVERAGE(I15:I16) -> 95.5 | J17: =AVERAGE(J15:J16) -> 88.5 | K17: =AVERAGE(K15:K16) -> 93.5 | L17: =AVERAGE(L15:L16) -> 93 | M17: =AVERAGE(M15:M16) -> 98 | ... T17: =AVERAGE(T15:T16) -> 93.346154 | U17: ='10A Sem avr'!$H$7 -> 2 | V17: =AVERAGE(V15:V16) -> 0 | W17: =AVERAGE(W15:W16) -> 0
A18: 5 | C18: 14 | D18: M | E18: Semister 1 | F18: ='10A Sem 1'!E8 -> 80 | G18: ='10A Sem 1'!F8 -> 80 | H18: ='10A Sem 1'!G8 -> 88 | I18: ='10A Sem 1'!H8 -> 67 | J18: ='10A Sem 1'!I8 -> 76 | K18: ='10A Sem 1'!J8 -> 78 | L18: ='10A Sem 1'!K8 -> 78 | M18: ='10A Sem 1'!L8 -> 68 | ... W18: ='10A Sem 1'!V8 -> 0
C19: 14 | D19: M | E19: Semister 2 | F19: ='10A Sem 2'!E8 -> 80 | G19: ='10A Sem 2'!F8 -> 80 | H19: ='10A Sem 2'!G8 -> 88 | I19: ='10A Sem 2'!H8 -> 75 | J19: ='10A Sem 2'!I8 -> 79 | K19: ='10A Sem 2'!J8 -> 83 | L19: ='10A Sem 2'!K8 -> 63 | M19: ='10A Sem 2'!L8 -> 85 | ... W19: ='10A Sem 2'!V8 -> 0
C20: 14 | D20: M | E20: Average | F20: =AVERAGE(F18:F19) -> 80 | G20: =AVERAGE(G18:G19) -> 80 | H20: =AVERAGE(H18:H19) -> 88 | I20: =AVERAGE(I18:I19) -> 71 | J20: =AVERAGE(J18:J19) -> 77.5 | K20: =AVERAGE(K18:K19) -> 80.5 | L20: =AVERAGE(L18:L19) -> 70.5 | M20: =AVERAGE(M18:M19) -> 76.5 | ... T20: =AVERAGE(T18:T19) -> 78 | U20: ='10A Sem avr'!$H$8 -> 17 | V20: =AVERAGE(V18:V19) -> 0 | W20: =AVERAGE(W18:W19) -> 0
A21: 6 | C21: 16 | D21: M | E21: Semister 1 | F21: ='10A Sem 1'!E9 -> 85 | G21: ='10A Sem 1'!F9 -> 73 | H21: ='10A Sem 1'!G9 -> 66 | I21: ='10A Sem 1'!H9 -> 63 | J21: ='10A Sem 1'!I9 -> 67 | K21: ='10A Sem 1'!J9 -> 79 | L21: ='10A Sem 1'!K9 -> 76 | M21: ='10A Sem 1'!L9 -> 80 | ... W21: ='10A Sem 1'!V9 -> 0
C22: 16 | D22: M | E22: Semister 2 | F22: ='10A Sem 2'!E9 -> 81 | G22: ='10A Sem 2'!F9 -> 72 | H22: ='10A Sem 2'!G9 -> 61 | I22: ='10A Sem 2'!H9 -> 64 | J22: ='10A Sem 2'!I9 -> 69 | K22: ='10A Sem 2'!J9 -> 73 | L22: ='10A Sem 2'!K9 -> 79 | M22: ='10A Sem 2'!L9 -> 97 | ... W22: ='10A Sem 2'!V9 -> 0
C23: 16 | D23: M | E23: Average | F23: =AVERAGE(F21:F22) -> 83 | G23: =AVERAGE(G21:G22) -> 72.5 | H23: =AVERAGE(H21:H22) -> 63.5 | I23: =AVERAGE(I21:I22) -> 63.5 | J23: =AVERAGE(J21:J22) -> 68 | K23: =AVERAGE(K21:K22) -> 76 | L23: =AVERAGE(L21:L22) -> 77.5 | M23: =AVERAGE(M21:M22) -> 88.5 | ... T23: =AVERAGE(T21:T22) -> 77.5 | U23: ='10A Sem avr'!$H$9 -> 18 | V23: =AVERAGE(V21:V22) -> 0 | W23: =AVERAGE(W21:W22) -> 0
A24: 7 | C24: 15 | D24: F | E24: Semister 1 | F24: ='10A Sem 1'!E10 -> 88 | G24: ='10A Sem 1'!F10 -> 95 | H24: ='10A Sem 1'!G10 -> 97 | I24: ='10A Sem 1'!H10 -> 95 | J24: ='10A Sem 1'!I10 -> 79 | K24: ='10A Sem 1'!J10 -> 93 | L24: ='10A Sem 1'!K10 -> 93 | M24: ='10A Sem 1'!L10 -> 82 | ... W24: ='10A Sem 1'!V10 -> 0
C25: 15 | D25: F | E25: Semister 2 | F25: ='10A Sem 2'!E10 -> 89 | G25: ='10A Sem 2'!F10 -> 91 | H25: ='10A Sem 2'!G10 -> 92 | I25: ='10A Sem 2'!H10 -> 88 | J25: ='10A Sem 2'!I10 -> 91 | K25: ='10A Sem 2'!J10 -> 96 | L25: ='10A Sem 2'!K10 -> 91 | M25: ='10A Sem 2'!L10 -> 98 | ... W25: ='10A Sem 2'!V10 -> 0
C26: 15 | D26: F | E26: Average | F26: =AVERAGE(F24:F25) -> 88.5 | G26: =AVERAGE(G24:G25) -> 93 | H26: =AVERAGE(H24:H25) -> 94.5 | I26: =AVERAGE(I24:I25) -> 91.5 | J26: =AVERAGE(J24:J25) -> 85 | K26: =AVERAGE(K24:K25) -> 94.5 | L26: =AVERAGE(L24:L25) -> 92 | M26: =AVERAGE(M24:M25) -> 90 | ... T26: =AVERAGE(T24:T25) -> 92.423077 | U26: ='10A Sem avr'!$H$10 -> 3 | V26: =AVERAGE(V24:V25) -> 0 | W26: =AVERAGE(W24:W25) -> 0
A27: 8 | C27: 15 | D27: F | E27: Semister 1 | F27: ='10A Sem 1'!E11 -> 73 | G27: ='10A Sem 1'!F11 -> 76 | H27: ='10A Sem 1'!G11 -> 61 | I27: ='10A Sem 1'!H11 -> 43 | J27: ='10A Sem 1'!I11 -> 50 | K27: ='10A Sem 1'!J11 -> 69 | L27: ='10A Sem 1'!K11 -> 52 | M27: ='10A Sem 1'!L11 -> 65 | ... W27: ='10A Sem 1'!V11 -> 0
C28: 15 | D28: F | E28: Semister 2 | F28: ='10A Sem 2'!E11 -> 73 | G28: ='10A Sem 2'!F11 -> 77 | H28: ='10A Sem 2'!G11 -> 48 | I28: ='10A Sem 2'!H11 -> 52 | J28: ='10A Sem 2'!I11 -> 54 | K28: ='10A Sem 2'!J11 -> 75 | L28: ='10A Sem 2'!K11 -> 58 | M28: ='10A Sem 2'!L11 -> 82 | ... W28: ='10A Sem 2'!V11 -> 0
C29: 15 | D29: F | E29: Average | F29: =AVERAGE(F27:F28) -> 73 | G29: =AVERAGE(G27:G28) -> 76.5 | H29: =AVERAGE(H27:H28) -> 54.5 | I29: =AVERAGE(I27:I28) -> 47.5 | J29: =AVERAGE(J27:J28) -> 52 | K29: =AVERAGE(K27:K28) -> 72 | L29: =AVERAGE(L27:L28) -> 55 | M29: =AVERAGE(M27:M28) -> 73.5 | ... T29: =AVERAGE(T27:T28) -> 69.5 | U29: ='10A Sem avr'!$H$11 -> 32 | V29: =AVERAGE(V27:V28) -> 0 | W29: =AVERAGE(W27:W28) -> 0
A30: 9 | C30: 16 | D30: F | E30: Semister 1 | F30: ='10A Sem 1'!E11 -> 73 | G30: ='10A Sem 1'!F11 -> 76 | H30: ='10A Sem 1'!G11 -> 61 | I30: ='10A Sem 1'!H11 -> 43 | J30: ='10A Sem 1'!I11 -> 50 | K30: ='10A Sem 1'!J11 -> 69 | L30: ='10A Sem 1'!K11 -> 52 | M30: ='10A Sem 1'!L11 -> 65 | ... W30: ='10A Sem 1'!V11 -> 0
C31: 16 | D31: F | E31: Semister 2 | F31: ='10A Sem 2'!E12 -> 66 | G31: ='10A Sem 2'!F12 -> 71 | H31: ='10A Sem 2'!G12 -> 61 | I31: ='10A Sem 2'!H12 -> 57 | J31: ='10A Sem 2'!I12 -> 59 | K31: ='10A Sem 2'!J12 -> 71 | L31: ='10A Sem 2'!K12 -> 73 | M31: ='10A Sem 2'!L12 -> 86 | ... W31: ='10A Sem 2'!V12 -> 0
C32: 16 | D32: F | E32: Average | F32: =AVERAGE(F30:F31) -> 69.5 | G32: =AVERAGE(G30:G31) -> 73.5 | H32: =AVERAGE(H30:H31) -> 61 | I32: =AVERAGE(I30:I31) -> 50 | J32: =AVERAGE(J30:J31) -> 54.5 | K32: =AVERAGE(K30:K31) -> 70 | L32: =AVERAGE(L30:L31) -> 62.5 | M32: =AVERAGE(M30:M31) -> 75.5 | ... T32: =AVERAGE(T30:T31) -> 68.192308 | U32: ='10A Sem avr'!$H$12 -> 36 | V32: =AVERAGE(V30:V31) -> 0 | W32: =AVERAGE(W30:W31) -> 0
A33: 10 | C33: 16 | D33: M | E33: Semister 1 | F33: ='10A Sem 1'!E13 -> 63 | G33: ='10A Sem 1'!F13 -> 45 | H33: ='10A Sem 1'!G13 -> 61 | I33: ='10A Sem 1'!H13 -> 53 | J33: ='10A Sem 1'!I13 -> 47 | K33: ='10A Sem 1'!J13 -> 58 | L33: ='10A Sem 1'!K13 -> 56 | M33: ='10A Sem 1'!L13 -> 52 | ... W33: ='10A Sem 1'!V13 -> 0
C34: 16 | D34: M | E34: Semister 2 | F34: ='10A Sem 2'!E13 -> 61 | G34: ='10A Sem 2'!F13 -> 61 | H34: ='10A Sem 2'!G13 -> 39 | I34: ='10A Sem 2'!H13 -> 51 | J34: ='10A Sem 2'!I13 -> 48 | K34: ='10A Sem 2'!J13 -> 58 | L34: ='10A Sem 2'!K13 -> 51 | M34: ='10A Sem 2'!L13 -> 63 | ... W34: ='10A Sem 2'!V13 -> 0
C35: 16 | D35: M | E35: Average | F35: =AVERAGE(F33:F34) -> 62 | G35: =AVERAGE(G33:G34) -> 53 | H35: =AVERAGE(H33:H34) -> 50 | I35: =AVERAGE(I33:I34) -> 52 | J35: =AVERAGE(J33:J34) -> 47.5 | K35: =AVERAGE(K33:K34) -> 58 | L35: =AVERAGE(L33:L34) -> 53.5 | M35: =AVERAGE(M33:M34) -> 57.5 | ... T35: =AVERAGE(T33:T34) -> 58.384615 | U35: ='10A Sem avr'!$H$13 -> 50 | V35: =AVERAGE(V33:V34) -> 0 | W35: =AVERAGE(W33:W34) -> 0
A36: 11 | C36: 15 | D36: F | E36: Semister 1 | F36: ='10A Sem 1'!E14 -> 77 | G36: ='10A Sem 1'!F14 -> 81 | H36: ='10A Sem 1'!G14 -> 60 | I36: ='10A Sem 1'!H14 -> 61 | J36: ='10A Sem 1'!I14 -> 62 | K36: ='10A Sem 1'!J14 -> 80 | L36: ='10A Sem 1'!K14 -> 82 | M36: ='10A Sem 1'!L14 -> 71 | ... W36: ='10A Sem 1'!V14 -> 0
C37: 15 | D37: F | E37: Semister 2 | F37: ='10A Sem 2'!E14 -> 80 | G37: ='10A Sem 2'!F14 -> 80 | H37: ='10A Sem 2'!G14 -> 63 | I37: ='10A Sem 2'!H14 -> 64 | J37: ='10A Sem 2'!I14 -> 62 | K37: ='10A Sem 2'!J14 -> 77 | L37: ='10A Sem 2'!K14 -> 78 | M37: ='10A Sem 2'!L14 -> 86 | ... W37: ='10A Sem 2'!V14 -> 0
C38: 15 | D38: F | E38: Average | F38: =AVERAGE(F36:F37) -> 78.5 | G38: =AVERAGE(G36:G37) -> 80.5 | H38: =AVERAGE(H36:H37) -> 61.5 | I38: =AVERAGE(I36:I37) -> 62.5 | J38: =AVERAGE(J36:J37) -> 62 | K38: =AVERAGE(K36:K37) -> 78.5 | L38: =AVERAGE(L36:L37) -> 80 | M38: =AVERAGE(M36:M37) -> 78.5 | ... T38: =AVERAGE(T36:T37) -> 77.115385 | U38: ='10A Sem avr'!$H$14 -> 19 | V38: =AVERAGE(V36:V37) -> 0 | W38: =AVERAGE(W36:W37) -> 0
A39: 12 | C39: 15 | D39: M | E39: Semister 1 | F39: ='10A Sem 1'!E15 -> 66 | G39: ='10A Sem 1'!F15 -> 53 | H39: ='10A Sem 1'!G15 -> 63 | I39: ='10A Sem 1'!H15 -> 45 | J39: ='10A Sem 1'!I15 -> 40 | K39: ='10A Sem 1'!J15 -> 55 | L39: ='10A Sem 1'!K15 -> 54 | M39: ='10A Sem 1'!L15 -> 52 | ... W39: ='10A Sem 1'!V15 -> 0
C40: 15 | D40: M | E40: Semister 2 | F40: ='10A Sem 2'!E15 -> 64 | G40: ='10A Sem 2'!F15 -> 62 | H40: ='10A Sem 2'!G15 -> 50 | I40: ='10A Sem 2'!H15 -> 55 | J40: ='10A Sem 2'!I15 -> 43 | K40: ='10A Sem 2'!J15 -> 57 | L40: ='10A Sem 2'!K15 -> 57 | M40: ='10A Sem 2'!L15 -> 72 | ... W40: ='10A Sem 2'!V15 -> 0
C41: 15 | D41: M | E41: Average | F41: =AVERAGE(F39:F40) -> 65 | G41: =AVERAGE(G39:G40) -> 57.5 | H41: =AVERAGE(H39:H40) -> 56.5 | I41: =AVERAGE(I39:I40) -> 50 | J41: =AVERAGE(J39:J40) -> 41.5 | K41: =AVERAGE(K39:K40) -> 56 | L41: =AVERAGE(L39:L40) -> 55.5 | M41: =AVERAGE(M39:M40) -> 62 | ... T41: =AVERAGE(T39:T40) -> 60.615385 | U41: ='10A Sem avr'!$H$15 -> 44 | V41: =AVERAGE(V39:V40) -> 0 | W41: =AVERAGE(W39:W40) -> 0
A42: 13 | C42: 16 | D42: F | E42: Semister 1 | F42: ='10A Sem 1'!E16 -> 84 | G42: ='10A Sem 1'!F16 -> 62 | H42: ='10A Sem 1'!G16 -> 65 | I42: ='10A Sem 1'!H16 -> 62 | J42: ='10A Sem 1'!I16 -> 54 | K42: ='10A Sem 1'!J16 -> 67 | L42: ='10A Sem 1'!K16 -> 64 | M42: ='10A Sem 1'!L16 -> 66 | ... W42: ='10A Sem 1'!V16 -> 0
...

Sheet 10A Sem 1
A1: Maria Rubbato Catholic School 2016 E.C Roster Grade 10A Student's
A2: Home Room Teacher Grade 10A
A3: No | B3: Student Name | C3: Age | D3: Sex | E3: Amharic | F3: English | G3: Maths | H3: physics | I3: chemistry | J3: Biology | K3: History | L3: Geography | M3: Citizenship | N3: ICT | O3: Economics | P3: H.P.E | Q3: Afan Oromo | R3: Total | S3: Average | T3: Rank | U3: Condc. | V3: Abse.
A4: 1 | C4: 15 | D4: F | E4: 79 | F4: 78 | G4: 64 | H4: 64 | I4: 56 | J4: 68 | K4: 64 | L4: 66 | M4: 73 | N4: 87 | O4: 68 | P4: 93 | Q4: 87 | R4: =SUM(E4:Q4) -> 947 | S4: =AVERAGE(E4:Q4) -> 72.846154 | T4: =RANK(S4,$S$4:$S$54) -> 28
A5: 2 | C5: 15 | D5: F | E5: 71 | F5: 52 | G5: 70 | H5: 55 | I5: 48 | J5: 58 | K5: 56 | L5: 58 | M5: 63 | N5: 88 | O5: 56 | P5: 80 | Q5: 72 | R5: =SUM(E5:Q5) -> 827 | S5: =AVERAGE(E5:Q5) -> 63.615385 | T5: =RANK(S5,$S$4:$S$54) -> 42
A6: 3 | C6: 17 | D6: M | E6: 96 | F6: 94 | G6: 100 | H6: 100 | I6: 96 | J6: 97 | K6: 90 | L6: 96 | M6: 93 | N6: 100 | O6: 98 | P6: 96 | Q6: 98 | R6: =SUM(E6:Q6) -> 1254 | S6: =AVERAGE(E6:Q6) -> 96.461538 | T6: =RANK(S6,$S$4:$S$54) -> 1
